Workbook

Sheet Sayfa1
A1: STOK KODU | B1: AÇIKLAMA | C1: 17 EYLÜL HOROZ | D1: 28 EYLÜL STUDIOLINE HOROZ | E1: 28 EYLÜL YILDIZ DEPO | F1: CAM OFİS KAPALI KUTU | G1: CAM OFİS TEŞHİR | H1: STUDIO LINE CEPA | I1: ANKAMALL | J1: CEPA | K1: OPTIMUM | L1: ONE TOWER | M1: PANORA | N1: TOPLAM STOK | O1: 24 EYLÜL BEKLEYEN | P1: PRİM HARİÇ ÜRÜN | Q1: EYLÜL TOPTAN | R1: HAVALE FİYATI | S1: TEK ÇEKİM FİYATI | T1: TAKSİTLİ FİYATI 3/6 TAKSİT | U1: EYLÜL BİP | V1: 30.09.2026 montaj zorunlu PHASE OUT | W1: Hakedişler LİSTE FİYATINDAN SATILIRSA geçerli olacak | X1: ONLINE FİYATI | Y1: ÜRÜN NOTLARI
A2: KA93NVL30N | B2: =IFERROR(HYPERLINK(VLOOKUP(A2,ÜRÜNLER!A:C,3,FALSE),VLOOKUP(A2,ÜRÜNLER!A:B,2,FALSE)),"") -> iQ300 Gardırop Tipi Buzdolabı, 90.8cm, Inox | J2: 1 | L2: 1 | N2: =M2+K2+L2+J2+I2+H2+G2+F2+E2+D2+C2 -> 2 | Q2: devamı yok | R2: 80000 | S2: 83200 | T2: 86400 | W2: 1000
A3: KF96RSBEA | B3: =IFERROR(HYPERLINK(VLOOKUP(A3,ÜRÜNLER!A:C,3,FALSE),VLOOKUP(A3,ÜRÜNLER!A:B,2,FALSE)),"") -> iQ700 Gardırop Tipi Buzdolabı, Cam Kapı, Alkol Çekmeceli, 90.5cm, Siyah | C3: 4 | F3: 1 | I3: 1 | J3: 1 | M3: 1 | N3: =M3+K3+L3+J3+I3+H3+G3+F3+E3+D3+C3 -> 8 | O3: 11 | Q3: 215784.17 | R3: 204994.96 | S3: 213194.76 | T3: 221394.56 | U3: 6594.3524
A4: KF96NAXEA | B4: =IFERROR(HYPERLINK(VLOOKUP(A4,ÜRÜNLER!A:C,3,FALSE),VLOOKUP(A4,ÜRÜNLER!A:B,2,FALSE)),"") -> iQ300 Gardırop Tipi Buzdolabı, 90.5cm, BlackSteel | I4: 1 | J4: 1 | K4: 1 | L4: 2 | M4: 1 | N4: =M4+K4+L4+J4+I4+H4+G4+F4+E4+D4+C4 -> 6 | O4: 11 | Q4: 134806.51 | R4: 128066.18 | S4: 133188.83 | T4: 138311.48 | U4: 41230.118
A5: KF96NVPEA | B5: =IFERROR(HYPERLINK(VLOOKUP(A5,ÜRÜNLER!A:C,3,FALSE),VLOOKUP(A5,ÜRÜNLER!A:B,2,FALSE)),"") -> iQ300 Gardırop Tipi Buzdolabı, 90.5cm, Inox | C5: 12 | F5: 1 | I5: 1 | L5: 2 | N5: =M5+K5+L5+J5+I5+H5+G5+F5+E5+D5+C5 -> 16 | O5: 1 | Q5: 118087.27 | R5: 112182.91 | S5: 116670.22 | T5: 121157.54 | U5: 26517.502 | W5: 250 | X5: =R5-U5 -> 85665.404
A6: KD43NNWE0N | B6: =IFERROR(HYPERLINK(VLOOKUP(A6,ÜRÜNLER!A:C,3,FALSE),VLOOKUP(A6,ÜRÜNLER!A:B,2,FALSE)),"") -> iQ100 Üstten Donduruculu Kulpsuz Buzdolabı, 70cm, Beyaz | C6: 1 | N6: =M6+K6+L6+J6+I6+H6+G6+F6+E6+D6+C6 -> 1 | P6: PRİM HARİÇ | Q6: 33700.892 | R6: 34037.901 | S6: 35399.417 | T6: 36760.933
A7: KD55NNWE0N | B7: =IFERROR(HYPERLINK(VLOOKUP(A7,ÜRÜNLER!A:C,3,FALSE),VLOOKUP(A7,ÜRÜNLER!A:B,2,FALSE)),"") -> iQ300 Üstten Donduruculu Kulpsuz Buzdolabı, 70cm, Beyaz | F7: 1 | N7: =M7+K7+L7+J7+I7+H7+G7+F7+E7+D7+C7 -> 1 | P7: PRİM HARİÇ | Q7: 36619.942 | R7: 36986.142 | S7: 38465.587 | T7: 39945.033 | U7: 968.77953
A8: KD55NNLE0N | B8: =IFERROR(HYPERLINK(VLOOKUP(A8,ÜRÜNLER!A:C,3,FALSE),VLOOKUP(A8,ÜRÜNLER!A:B,2,FALSE)),"") -> iQ300 Üstten Donduruculu Kulpsuz Buzdolabı, 70cm, Inox Görünümlü | C8: 4 | N8: =M8+K8+L8+J8+I8+H8+G8+F8+E8+D8+C8 -> 4 | P8: PRİM HARİÇ | Q8: 43007.56 | R8: 43670 | S8: 45416.8 | T8: 47163.6 | U8: 4670.351
A9: KD56NXWF1N | B9: =IFERROR(HYPERLINK(VLOOKUP(A9,ÜRÜNLER!A:C,3,FALSE),VLOOKUP(A9,ÜRÜNLER!A:B,2,FALSE)),"") -> iQ300 Üstten Donduruculu Kulpsuz Buzdolabı, 70cm, Beyaz | L9: 1 | N9: =M9+K9+L9+J9+I9+H9+G9+F9+E9+D9+C9 -> 1 | Q9: devamı yok | R9: 40000 | S9: 41600 | T9: 43200 | W9: 500
A10: KD76NAIE1N | B10: =IFERROR(HYPERLINK(VLOOKUP(A10,ÜRÜNLER!A:C,3,FALSE),VLOOKUP(A10,ÜRÜNLER!A:B,2,FALSE)),"") -> iQ500 Üstten Donduruculu Kulplu Buzdolabı, 75cm, Inox | C10: 11 | N10: =M10+K10+L10+J10+I10+H10+G10+F10+E10+D10+C10 -> 11 | Q10: 84535.625 | R10: 80308.843 | S10: 83521.197 | T10: 86733.551 | U10: 15186.788
A11: KD76NAWE1N | B11: =IFERROR(HYPERLINK(VLOOKUP(A11,ÜRÜNLER!A:C,3,FALSE),VLOOKUP(A11,ÜRÜNLER!A:B,2,FALSE)),"") -> iQ500 Üstten Donduruculu Kulplu Buzdolabı, 75cm, Beyaz | C11: 5 | N11: =M11+K11+L11+J11+I11+H11+G11+F11+E11+D11+C11 -> 5 | O11: 5 | Q11: 62949.551 | R11: 59802.074 | S11: 62194.157 | T11: 64586.24 | U11: 3123.9701
A12: KD76NXIE1N | B12: =IFERROR(HYPERLINK(VLOOKUP(A12,ÜRÜNLER!A:C,3,FALSE),VLOOKUP(A12,ÜRÜNLER!A:B,2,FALSE)),"") -> iQ500 Üstten Donduruculu Kulpsuz Buzdolabı, 75cm, Inox | C12: 11 | N12: =M12+K12+L12+J12+I12+H12+G12+F12+E12+D12+C12 -> 11 | Q12: 70136.481 | R12: 66629.657 | S12: 69294.843 | T12: 71960.029 | U12: 7950.4345
A13: KD76NXWE1N | B13: =IFERROR(HYPERLINK(VLOOKUP(A13,ÜRÜNLER!A:C,3,FALSE),VLOOKUP(A13,ÜRÜNLER!A:B,2,FALSE)),"") -> iQ300 Üstten Donduruculu, Kulpsuz Buzdolabı, 75cm, Beyaz | I13: 1 | J13: 1 | M13: 1 | N13: =M13+K13+L13+J13+I13+H13+G13+F13+E13+D13+C13 -> 3 | O13: 11 | Q13: 64328.533 | R13: 61112.107 | S13: 63556.591 | T13: 66001.075 | U13: 13537.836
A14: KD76NXWE0N | B14: =IFERROR(HYPERLINK(VLOOKUP(A14,ÜRÜNLER!A:C,3,FALSE),VLOOKUP(A14,ÜRÜNLER!A:B,2,FALSE)),"") -> iQ300 Üstten Donduruculu Kulpsuz Buzdolabı, 75cm, Beyaz | L14: 1 | N14: =M14+K14+L14+J14+I14+H14+G14+F14+E14+D14+C14 -> 1 | Q14: devamı yok | R14: 55000 | S14: 57200 | T14: 59400 | W14: 500
A15: KD76NNWE0N | B15: =IFERROR(HYPERLINK(VLOOKUP(A15,ÜRÜNLER!A:C,3,FALSE),VLOOKUP(A15,ÜRÜNLER!A:B,2,FALSE)),"") -> iQ300 Üstten Donduruculu Kulpsuz Buzdolabı, 75cm, Beyaz | C15: 1 | N15: =M15+K15+L15+J15+I15+H15+G15+F15+E15+D15+C15 -> 1 | Q15: 56792.905 | R15: 56793 | S15: 59064.72 | T15: 61336.44 | U15: 8118.4866
A16: KD86NAID1N | B16: =IFERROR(HYPERLINK(VLOOKUP(A16,ÜRÜNLER!A:C,3,FALSE),VLOOKUP(A16,ÜRÜNLER!A:B,2,FALSE)),"") -> iQ500 Üstten Donduruculu Kulplu Buzdolabı, 86cm, Inox | C16: 10 | E16: 1 | I16: 1 | J16: 1 | K16: 1 | N16: =M16+K16+L16+J16+I16+H16+G16+F16+E16+D16+C16 -> 14 | Q16: 98053.757 | R16: 93151.069 | S16: 96877.112 | T16: 100603.16 | U16: 23170.036
A17: KD86NAWE1N | B17: =IFERROR(HYPERLINK(VLOOKUP(A17,ÜRÜNLER!A:C,3,FALSE),VLOOKUP(A17,ÜRÜNLER!A:B,2,FALSE)),"") -> iQ500 Üstten Donduruculu Kulplu Buzdolabı, 86cm, Beyaz | C17: 1 | N17: =M17+K17+L17+J17+I17+H17+G17+F17+E17+D17+C17 -> 1 | O17: 10 | Q17: 85320.531 | R17: 81054.504 | S17: 84296.684 | T17: 87538.864 | U17: 15971.693
A18: KD86NHID1N | B18: =IFERROR(HYPERLINK(VLOOKUP(A18,ÜRÜNLER!A:C,3,FALSE),VLOOKUP(A18,ÜRÜNLER!A:B,2,FALSE)),"") -> iQ500 Üstten Donduruculu Kulplu Buzdolabı, 86cm, Inox | L18: 1 | N18: =M18+K18+L18+J18+I18+H18+G18+F18+E18+D18+C18 -> 1 | Q18: devamı yok | R18: 55000 | S18: 57200 | T18: 59400 | W18: 500
A19: KG36NNLE0N | B19: =IFERROR(HYPERLINK(VLOOKUP(A19,ÜRÜNLER!A:C,3,FALSE),VLOOKUP(A19,ÜRÜNLER!A:B,2,FALSE)),"") -> iQ100 Alttan Donduruculu Kulpsuz Buzdolabı, 60cm, Inox | N19: =M19+K19+L19+J19+I19+H19+G19+F19+E19+D19+C19 -> 0 | Q19: devamı yok | R19: 40000 | S19: 41600 | T19: 43200 | W19: 500
A20: KG55NCIE0N | B20: =IFERROR(HYPERLINK(VLOOKUP(A20,ÜRÜNLER!A:C,3,FALSE),VLOOKUP(A20,ÜRÜNLER!A:B,2,FALSE)),"") -> iQ300 Alttan Donduruculu Kulpsuz Buzdolabı, 70cm, Inox | C20: 59 | E20: 4 | I20: 1 | J20: 1 | L20: 1 | M20: 1 | N20: =M20+K20+L20+J20+I20+H20+G20+F20+E20+D20+C20 -> 67 | Q20: 65373.711 | R20: 58836.34 | S20: 61189.793 | T20: 63543.247 | U20: 14664.409
A21: KG55NCWE0N | B21: =IFERROR(HYPERLINK(VLOOKUP(A21,ÜRÜNLER!A:C,3,FALSE),VLOOKUP(A21,ÜRÜNLER!A:B,2,FALSE)),"") -> iQ300 Alttan Donduruculu Kulpsuz Buzdolabı, 70cm, Beyaz | C21: 77 | I21: 1 | K21: 1 | L21: 2 | N21: =M21+K21+L21+J21+I21+H21+G21+F21+E21+D21+C21 -> 81 | Q21: 60461.405 | R21: 54415.264 | S21: 56591.875 | T21: 58768.486 | U21: 11705.591
A22: KG55NVIE0N | B22: =IFERROR(HYPERLINK(VLOOKUP(A22,ÜRÜNLER!A:C,3,FALSE),VLOOKUP(A22,ÜRÜNLER!A:B,2,FALSE)),"") -> iQ300 Alttan Donduruculu Kulpsuz Buzdolabı, 70cm, Inox | E22: 1 | L22: 1 | N22: =M22+K22+L22+J22+I22+H22+G22+F22+E22+D22+C22 -> 2 | Q22: devamı yok | R22: 55000 | S22: 57200 | T22: 59400 | U22: 8118.2663
A23: KG55NVWE0N | B23: =IFERROR(HYPERLINK(VLOOKUP(A23,ÜRÜNLER!A:C,3,FALSE),VLOOKUP(A23,ÜRÜNLER!A:B,2,FALSE)),"") -> iQ300 Alttan Donduruculu Kulpsuz Buzdolabı, 70cm, Beyaz | E23: 1 | L23: 1 | N23: =M23+K23+L23+J23+I23+H23+G23+F23+E23+D23+C23 -> 2 | Q23: devamı yok | R23: 44500 | S23: 46280 | T23: 48060 | U23: 4531.8972 | W23: 500
A24: KG56NCID0N | B24: =IFERROR(HYPERLINK(VLOOKUP(A24,ÜRÜNLER!A:C,3,FALSE),VLOOKUP(A24,ÜRÜNLER!A:B,2,FALSE)),"") -> iQ300 Alttan Donduruculu Kulpsuz Buzdolabı, 70cm, Inox (Wi-Fi) | C24: 3 | N24: =M24+K24+L24+J24+I24+H24+G24+F24+E24+D24+C24 -> 3 | Q24: 60254.001 | R24: 57241.301 | S24: 59530.953 | T24: 61820.605 | U24: 5800.5128
A25: KG56NCWD0N | B25: =IFERROR(HYPERLINK(VLOOKUP(A25,ÜRÜNLER!A:C,3,FALSE),VLOOKUP(A25,ÜRÜNLER!A:B,2,FALSE)),"") -> iQ300 Alttan Donduruculu Kulpsuz Buzdolabı, 70cm, Beyaz (Wi-Fi) | C25: 3 | N25: =M25+K25+L25+J25+I25+H25+G25+F25+E25+D25+C25 -> 3 | Q25: 55360.41 | R25: 52592.39 | S25: 54696.085 | T25: 56799.781 | U25: 2941.8055
A26: KG56NCXD0N | B26: =IFERROR(HYPERLINK(VLOOKUP(A26,ÜRÜNLER!A:C,3,FALSE),VLOOKUP(A26,ÜRÜNLER!A:B,2,FALSE)),"") -> iQ300 Alttan Donduruculu Kulpsuz Buzdolabı, 70cm, Black Inox (Wi-Fi) | C26: 5 | N26: =M26+K26+L26+J26+I26+H26+G26+F26+E26+D26+C26 -> 5 | Q26: 63899.365 | R26: 60704.397 | S26: 63132.573 | T26: 65560.749 | U26: 6597.0399
A27: KG56NLBE0N | B27: =IFERROR(HYPERLINK(VLOOKUP(A27,ÜRÜNLER!A:C,3,FALSE),VLOOKUP(A27,ÜRÜNLER!A:B,2,FALSE)),"") -> iQ500 Alttan Donduruculu Kulpsuz Buzdolabı, 70cm, Parlak Siyah | C27: 4 | I27: 2 | J27: 1 | K27: 1 | M27: 2 | N27: =M27+K27+L27+J27+I27+H27+G27+F27+E27+D27+C27 -> 10 | Q27: 62632.699 | R27: 59501.064 | S27: 61881.107 | T27: 64261.149
A28: KG56NNWD0N | B28: =IFERROR(HYPERLINK(VLOOKUP(A28,ÜRÜNLER!A:C,3,FALSE),VLOOKUP(A28,ÜRÜNLER!A:B,2,FALSE)),"") -> iQ100 Alttan Donduruculu Kulpsuz Buzdolabı, 70cm, Beyaz (Wi-Fi) | C28: 42 | N28: =M28+K28+L28+J28+I28+H28+G28+F28+E28+D28+C28 -> 42 | Q28: 44190.123 | R28: 41980.617 | S28: 43659.842 | T28: 45339.066
A29: KG56NQWF0N | B29: =IFERROR(HYPERLINK(VLOOKUP(A29,ÜRÜNLER!A:C,3,FALSE),VLOOKUP(A29,ÜRÜNLER!A:B,2,FALSE)),"") -> iQ500 Alttan Donduruculu Kulpsuz Buzdolabı, 70cm, Seramik Desen | J29: 1 | N29: =M29+K29+L29+J29+I29+H29+G29+F29+E29+D29+C29 -> 1 | Q29: devamı yok | R29: 48000 | S29: 49920 | T29: 51840 | W29: 500
A30: KG56NTEE0N | B30: =IFERROR(HYPERLINK(VLOOKUP(A30,ÜRÜNLER!A:C,3,FALSE),VLOOKUP(A30,ÜRÜNLER!A:B,2,FALSE)),"") -> iQ500 Alttan Donduruculu Kulpsuz Buzdolabı, 70cm, Mat Siyah | G30: 1 | N30: =M30+K30+L30+J30+I30+H30+G30+F30+E30+D30+C30 -> 1 | Q30: devamı yok | R30: 48000 | S30: 49920 | T30: 51840 | W30: 500
A31: KG56NTWE0N | B31: =IFERROR(HYPERLINK(VLOOKUP(A31,ÜRÜNLER!A:C,3,FALSE),VLOOKUP(A31,ÜRÜNLER!A:B,2,FALSE)),"") -> iQ500 Alttan Donduruculu Kulpsuz Buzdolabı, 70cm, Seramik Desen | L31: 1 | N31: =M31+K31+L31+J31+I31+H31+G31+F31+E31+D31+C31 -> 1 | Q31: devamı yok | R31: 48000 | S31: 49920 | T31: 51840 | W31: 500
A32: KG56NVPD0N | B32: =IFERROR(HYPERLINK(VLOOKUP(A32,ÜRÜNLER!A:C,3,FALSE),VLOOKUP(A32,ÜRÜNLER!A:B,2,FALSE)),"") -> iQ300 Alttan Donduruculu Kulpsuz Buzdolabı, 70cm, Inox (Wi-Fi) | C32: 28 | I32: 1 | N32: =M32+K32+L32+J32+I32+H32+G32+F32+E32+D32+C32 -> 29 | O32: 20 | Q32: 50627.907 | R32: 48096.512 | S32: 50020.372 | T32: 51944.233
A33: KG56NVWD0N | B33: =IFERROR(HYPERLINK(VLOOKUP(A33,ÜRÜNLER!A:C,3,FALSE),VLOOKUP(A33,ÜRÜNLER!A:B,2,FALSE)),"") -> iQ300 Alttan Donduruculu Kulpsuz Buzdolabı, 70cm, Beyaz (Wi-Fi) | C33: 30 | N33: =M33+K33+L33+J33+I33+H33+G33+F33+E33+D33+C33 -> 30 | O33: 21 | Q33: 48309.397 | R33: 45893.927 | S33: 47729.685 | T33: 49565.442
A34: KG76APIE0N | B34: =IFERROR(HYPERLINK(VLOOKUP(A34,ÜRÜNLER!A:C,3,FALSE),VLOOKUP(A34,ÜRÜNLER!A:B,2,FALSE)),"") -> iQ700 Alttan Donduruculu Kulplu Buzdolabı, 75cm, Inox | C34: 13 | N34: =M34+K34+L34+J34+I34+H34+G34+F34+E34+D34+C34 -> 13 | Q34: 84646.164 | R34: 76181.548 | S34: 79228.81 | T34: 82276.072 | U34: 9762.4435
A35: KG76NCIE0N | B35: =IFERROR(HYPERLINK(VLOOKUP(A35,ÜRÜNLER!A:C,3,FALSE),VLOOKUP(A35,ÜRÜNLER!A:B,2,FALSE)),"") -> iQ500 Alttan Donduruculu Kulplu Buzdolabı, 75cm, Inox | C35: 4 | I35: 1 | J35: 1 | K35: 1 | L35: 3 | M35: 1 | N35: =M35+K35+L35+J35+I35+H35+G35+F35+E35+D35+C35 -> 11 | O35: 5 | Q35: 89337.569 | R35: 84870.691 | S35: 88265.519 | T35: 91660.346 | U35: 22186.407
A36: KG76NCWE0N | B36: =IFERROR(HYPERLINK(VLOOKUP(A36,ÜRÜNLER!A:C,3,FALSE),VLOOKUP(A36,ÜRÜNLER!A:B,2,FALSE)),"") -> iQ500 Alttan Donduruculu Kulplu Buzdolabı, 75cm, Beyaz | C36: 33 | I36: 1 | L36: 1 | N36: =M36+K36+L36+J36+I36+H36+G36+F36+E36+D36+C36 -> 35 | Q36: 80897.296 | R36: 75234.485 | S36: 78243.865 | T36: 81253.244 | U36: 15211.249
A37: KG76NCXE0N | B37: =IFERROR(HYPERLINK(VLOOKUP(A37,ÜRÜNLER!A:C,3,FALSE),VLOOKUP(A37,ÜRÜNLER!A:B,2,FALSE)),"") -> iQ500 Alttan Donduruculu Kulpsuz Buzdolabı, 75cm, darkSteel | C37: 115 | I37: 1 | J37: 1 | K37: 1 | M37: 1 | N37: =M37+K37+L37+J37+I37+H37+G37+F37+E37+D37+C37 -> 119 | Q37: 99433.9 | R37: 89490.51 | S37: 93070.13 | T37: 96649.751 | U37: 26829.249
A38: KG76NVIE0N | B38: =IFERROR(HYPERLINK(VLOOKUP(A38,ÜRÜNLER!A:C,3,FALSE),VLOOKUP(A38,ÜRÜNLER!A:B,2,FALSE)),"") -> iQ300 Alttan Donduruculu Kulpsuz Buzdolabı, 75cm, Inox | C38: 32 | G38: 2 | I38: 1 | L38: 2 | N38: =M38+K38+L38+J38+I38+H38+G38+F38+E38+D38+C38 -> 37 | Q38: 80743.426 | R38: 73000 | S38: 75920 | T38: 78840 | U38: 16034.124
A39: KG76NVWE0N | B39: =IFERROR(HYPERLINK(VLOOKUP(A39,ÜRÜNLER!A:C,3,FALSE),VLOOKUP(A39,ÜRÜNLER!A:B,2,FALSE)),"") -> iQ300 Alttan Donduruculu Kulpsuz Buzdolabı, 75cm, Beyaz | C39: 17 | I39: 1 | J39: 1 | M39: 1 | N39: =M39+K39+L39+J39+I39+H39+G39+F39+E39+D39+C39 -> 20 | Q39: 72507.334 | R39: 68881.968 | S39: 71637.246 | T39: 74392.525 | U39: 18216.637
A40: KG76PAIC0N | B40: =IFERROR(HYPERLINK(VLOOKUP(A40,ÜRÜNLER!A:C,3,FALSE),VLOOKUP(A40,ÜRÜNLER!A:B,2,FALSE)),"") -> iQ700 Alttan Donduruculu Kulplu Buzdolabı, 75cm, Inox | C40: 39 | E40: 2 | G40: 1 | I40: 1 | J40: 1 | M40: 1 | N40: =M40+K40+L40+J40+I40+H40+G40+F40+E40+D40+C40 -> 45 | Q40: 93563.754 | R40: 87014.292 | S40: 90494.863 | T40: 93975.435 | U40: 14366.08 | X40: =R40-U40 -> 72648.212
...

Sheet HESAPLAYICI
A1: STOK KODU | B1: AÇIKLAMA | C1: 10 EYLÜL HOROZ | D1: TEK ÇEKİM FİYATI | E1: TAKSİTLİ FİYATI 3/6 TAKSİT | F1: EYLÜL BİP | G1: 30.09.2026 montaj zorunlu PHASE OUT | H1: Hakedişler LİSTE FİYATINDAN SATILIRSA geçerli olacak | I1: Toplam Bundle İndirim Tutarını Aşağıya Yaz | J1: 0 | K1: ONLINE FİYATI | L1: BİP KOŞULU
A2: HB534FER0T | B2: iQ300 Ankastre Fırın, 1 Teleskopik Ray, Arkası Kendini Temizler, Siyah/Inox | C2: 0 | D2: devamı yok | E2: 18607 | F2: 19351.28 | G2: 20095.56 | H2: 0 | J2: 500 | K2: 1606.584 | L2: 0
B3: ? | C3: ? | D3: ? | E3: ? | F3: ? | G3: ? | H3: ? | J3: ? | K3: ? | L3: ?
B4: ? | C4: ? | D4: ? | E4: ? | F4: ? | G4: ? | H4: ? | J4: ? | K4: ? | L4: ?
B5: ? | C5: ? | D5: ? | E5: ? | F5: ? | G5: ? | H5: ? | J5: ? | K5: ? | L5: ?
B6: ? | C6: ? | D6: ? | E6: ? | F6: ? | G6: ? | H6: ? | J6: ? | K6: ? | L6: ?
B7: ? | C7: ? | D7: ? | E7: ? | F7: ? | G7: ? | H7: ? | J7: ? | K7: ? | L7: ?
B8: ? | C8: ? | D8: ? | E8: ? | F8: ? | G8: ? | H8: ? | J8: ? | K8: ? | L8: ?
B9: ? | C9: ? | D9: ? | E9: ? | F9: ? | G9: ? | H9: ? | J9: ? | K9: ? | L9: ?
B10: ? | C10: ? | D10: ? | E10: ? | F10: ? | G10: ? | H10: ? | J10: ? | K10: ? | L10: ?
B11: ? | C11: ? | D11: ? | E11: ? | F11: ? | G11: ? | H11: ? | J11: ? | K11: ? | L11: ?
A12: Toplam Satış Fiyatı | E12: =SUM(E2:E11) -> 18607 | F12: =SUM(F2:F11) -> 19351.28
A13: BİP İndirimi | E13: =SUM(G:G)*-1 -> -20095.56 | F13: =SUM(G:G)*-1 -> -20095.56
A14: PhaseOut İndirimi | E14: =SUM(H:H)*-1 -> 0 | F14: =SUM(H:H)*-1 -> 0
A15: Toplam Bundle İndirimi | E15: =I2*-1 -> 0 | F15: =I2*-1 -> 0
A16: Satılabilir Minimum Fiyat | E16: =SUM(E12:E15) -> -1488.56 | F16: =SUM(F12:F15) -> -744.28
A17: Satılabilir Minimum Taksitli Fiyat | E17: =E16*1.08 -> -1607.6448

Sheet Bundle Kampanya
G3: Seçili Ankastre Set Alımına 5.000 TL İndirim! | H3: Geçerli Ankastre Fırınlar
C5: 2'li LDA alımında 5.000 TL İndirim! | D5: 2’li LDA alımında 5.000 ₺ indirim uygulanır.“diğer kampanyalar ile birleşemez” 4.000 ₺ kdv dahil fiyat farkı hak edişi ödenecektir. (Buzdolabı-Çamaşır-Bulaşık-Kurutma-Derin Dondurucu) (XL-XXL Buzdolapları hariç) | H5: HB012FBH1T, HB012FBB1T, HB012FBW1T + (phase out iQ300 ve iQ500 segment modeller) Ankastre fırınlarda geçerlidir.
H9: Uygulama koşulları : Seçili ankastre fırınlar ile set (fırın+ocak+dav.) set alana 5.000 ₺ indirim uygulanır. Diğer fırınlarda geçerli değildir. KDV dahil 3.700 ₺ hak ediş ödenir. Giriş setlerde( HB011* ve giriş segment muadili fırın modelleri, EB6C5PK80O - EB6C5PB82O ocak, LC64PCC20T - LC64PCC50T - LC64PCC60T davlumbaz modelleri) geçerli değildir.
G17: Seçili Fırınlarla Ankastre set alana LC63KPJ60T Davlumbaz Hediye! | H17: Geçerli Ankastre Setler
C19: Çamaşır + Kurutma alımında 10.000 TL İndirim! | D19: Çamaşır ile Kurutma birlikte alımında 10.000 ₺ indirim uygulanır.“diğer kampanyalar ile birleşemez” 8.000 ₺ kdv dahil fiyat farkı hak edişi ödenecektir. (Çamaşır + Kurutma) | H19: HB557JEB6T, HB734G1B1, HB776G1B1, HB778G3B1, HR776G3B1, HS736G1B2, VB558C0S0, CM724G1B1, HJ852GYB0T, HJ852GYN0T, HJ852GYW0T, HU736AEN0T, HU736AEA0T, HU736AEV0T, HU736AEG0T, HR232GEB3, HU717ABN0T, HU717ABA0T, HU717ABV0T, CD714GXB1
H23: Uygulama koşulları : Seçili ankastre fırınlar ile set (fırın+ocak+dav.) set alana 12.800 ₺ indirim uygulanır. KDV dahil 9.800 ₺ hak ediş ödenir. Giriş setlerde( HB011* ve giriş segment muadili fırın modelleri, EB6C5PK80O - EB6C5PB82O ocak, LC64PCC20T - LC64PCC50T - LC64PCC60T davlumbaz modelleri) geçerli değildir.

Sheet ÜRÜNLER
A1: Ürün No | B1: Ürün Adı | C1: Ürün Linki | D1: Ürün Grubu | E1: Marka
A2: 50PUS8009/62 | B2: Philips 50" 4K Ambilight LED TV (Titan OS) (50PUS8009/62) | C2: https://www.philips.com.tr/c-p/50PUS8009_62/led-50pus8009-4k-ambilight-tv | D2: Televizyon | E2: Philips
A3: 55PUS8349/62 | B3: Philips 55" 4K Ambilight LED TV (Titan OS) (55PUS8349/62) | C3: https://www.philips.com.tr/c-p/55PUS8349_62/led-55pus8349-4k-ambilight-tv | D3: Televizyon | E3: Philips
A4: AS09IVW32N | B4: Siemens Ev Tipi Klima İç Ünite, 9.000BTU, Beyaz | C4: https://www.siemens-home.bsh-group.com/tr/tr/product/klimalar/AS09XVW32N | D4: Klima | E4: Siemens
A5: AS09OVW32N | B5: Siemens Ev Tipi Klima Dış Ünite, 9.000BTU, Beyaz | C5: https://www.siemens-home.bsh-group.com/tr/tr/product/klimalar/AS09XVW32N | D5: Klima | E5: Siemens
A6: AS12IVW30N | B6: Siemens Ev Tipi Klima İç Ünite, 12.000BTU, Beyaz | C6: https://www.siemens-home.bsh-group.com/tr/tr/product/klimalar/AS12XVW32N | D6: Klima | E6: Siemens
A7: AS12IVW32N | B7: Siemens Ev Tipi Klima İç Ünite, 12.000BTU, Beyaz | C7: https://www.siemens-home.bsh-group.com/tr/tr/product/klimalar/AS12XVW32N | D7: Klima | E7: Siemens
A8: AS12IXB32N | B8: Siemens Ev Tipi Klima İç Ünite, 12.000BTU, Siyah | C8: https://www.siemens-home.bsh-group.com/tr/tr/product/klimalar/AS12XXB32N | D8: Klima | E8: Siemens
A9: AS12OVW30N | B9: Siemens Ev Tipi Klima Dış Ünite, 12.000BTU, Beyaz | C9: https://www.siemens-home.bsh-group.com/tr/tr/product/klimalar/AS12XVW32N | D9: Klima | E9: Siemens
A10: AS12OVW32N | B10: Siemens Ev Tipi Klima Dış Ünite, 12.000BTU, Beyaz | C10: https://www.siemens-home.bsh-group.com/tr/tr/product/klimalar/AS12XVW32N | D10: Klima | E10: Siemens
A11: AS12OXB32N | B11: Siemens Ev Tipi Klima Dış Ünite, 12.000BTU, Beyaz | C11: https://www.siemens-home.bsh-group.com/tr/tr/product/klimalar/AS12XXB32N | D11: Klima | E11: Siemens
A12: AS18IVW30N | B12: Siemens Ev Tipi Klima İç Ünite, 18.000BTU, Beyaz | C12: https://www.siemens-home.bsh-group.com/tr/tr/product/klimalar/AS18XVW32N | D12: Klima | E12: Siemens
... A633: EP6A2PI40O | B633: iQ500 Gazlı Ocak, 60cm, Sert Cam, Beyaz, Döküm | C633: https://www.siemens-home.bsh-group.com/tr/tr/product/pisirme-grubu/ocaklar/gazli-ocaklar/EP6A2PI40O | D633: Ocak | E633: Siemens
A634: TP605EM3 | B634: EQ600 iAroma Tam Otomatik Kahve Makinesi, Siyah/Inox | D634: Kahve Makinesi | E634: Siemens
A635: TP607ET5 | B635: EQ600 iAroma Tam Otomatik Kahve Makinesi, Siyah/Dark Inox | C635: https://www.siemens-home.bsh-group.com/tr/tr/product/kahve-makineleri/tam-otomatik-kahve-makineleri/coffeemachinesautomatedfreestandingeq600/TP607ET5 | D635: Kahve Makinesi | E635: Siemens
A636: TP601E01 | B636: EQ600 iAroma Tam Otomatik Kahve Makinesi, Sabah Sisi Grisi | C636: https://www.siemens-home.bsh-group.com/tr/tr/product/kahve-makineleri/tam-otomatik-kahve-makineleri/coffeemachinesautomatedfreestandingeq600/TP601E01 | D636: Kahve Makinesi | E636: Siemens
A637: TP551E19 | B637: EQ500 iAroma Tam Otomatik Kahve Makinesi, Piano Black | D637: Kahve Makinesi | E637: Siemens
A638: TP553E05 | B638: EQ500 iAroma Tam Otomatik Kahve Makinesi, Piano Black | D638: Kahve Makinesi | E638: Siemens
