Workbook

Sheet Sayfa1
A1: STOK KODU | B1: AÇIKLAMA | C1: 04 TEMMUZ HOROZ | D1: 15 HAZİRAN Studioline HOROZ | E1: 26 HAZİRAN YILDIZ DEPO | F1: CAM OFİS | G1: İNTERNET DEPO | H1: STUDIO LINE CEPA | I1: ANKAMALL | J1: CEPA | K1: ONE TOWER | L1: PANORA | M1: OPTIMUM TEŞHİR | N1: TOPLAM STOK | O1: 23 HAZİRAN BEKLEYEN | P1: PRİM HARİÇ ÜRÜN | Q1: TEMMUZ TOPTAN | R1: HAVALE FİYATI | S1: TEK ÇEKİM FİYATI | T1: TAKSİTLİ FİYATI 3/6 TAKSİT | U1: WEB TAHSİLAT BONUS 9 | V1: TEMMUZ BİP | W1: 31.08.2026 montaj zorunlu phase out | X1: Hakedişler LİSTE FİYATINDAN SATILIRSA geçerli olacak
A2: KA93NVL30N | B2: =IFERROR(HYPERLINK(VLOOKUP(A2,ÜRÜNLER!A:C,3,FALSE),VLOOKUP(A2,ÜRÜNLER!A:B,2,FALSE)),"") -> iQ300 Gardırop Tipi Buzdolabı, 90.8cm, Inox | J2: 1 | K2: 1 | N2: =L2+M2+K2+J2+I2+H2+G2+F2+E2+D2+C2 -> 2 | Q2: devamı yok | R2: 80000 | S2: 83200 | T2: 86400 | U2: 88000 | X2: 250
A3: KF96RSBEA | B3: =IFERROR(HYPERLINK(VLOOKUP(A3,ÜRÜNLER!A:C,3,FALSE),VLOOKUP(A3,ÜRÜNLER!A:B,2,FALSE)),"") -> iQ700 Gardırop Tipi Buzdolabı, Cam Kapı, Alkol Çekmeceli, 90.5cm, Siyah | C3: 8 | I3: 1 | J3: 1 | L3: 1 | N3: =L3+M3+K3+J3+I3+H3+G3+F3+E3+D3+C3 -> 11 | Q3: 210521.14 | R3: 199995.08 | S3: 207994.89 | T3: 215994.69 | U3: 219994.59
A4: KF96NAXEA | B4: =IFERROR(HYPERLINK(VLOOKUP(A4,ÜRÜNLER!A:C,3,FALSE),VLOOKUP(A4,ÜRÜNLER!A:B,2,FALSE)),"") -> iQ300 Gardırop Tipi Buzdolabı, 90.5cm, BlackSteel | C4: 22 | I4: 1 | J4: 1 | K4: 2 | L4: 1 | N4: =L4+M4+K4+J4+I4+H4+G4+F4+E4+D4+C4 -> 27 | Q4: 128387.15 | R4: 119400.05 | S4: 124176.05 | T4: 128952.05 | U4: 131340.05 | V4: 32818.515
A5: KF96NVPEA | B5: =IFERROR(HYPERLINK(VLOOKUP(A5,ÜRÜNLER!A:C,3,FALSE),VLOOKUP(A5,ÜRÜNLER!A:B,2,FALSE)),"") -> iQ300 Gardırop Tipi Buzdolabı, 90.5cm, Inox | C5: 39 | I5: 1 | K5: 2 | N5: =L5+M5+K5+J5+I5+H5+G5+F5+E5+D5+C5 -> 42 | Q5: 113545.45 | R5: 105597.27 | S5: 109821.16 | T5: 114045.05 | U5: 116157 | V5: 18996.614
A6: KD43NNWE0N | B6: =IFERROR(HYPERLINK(VLOOKUP(A6,ÜRÜNLER!A:C,3,FALSE),VLOOKUP(A6,ÜRÜNLER!A:B,2,FALSE)),"") -> iQ100 Üstten Donduruculu Kulpsuz Buzdolabı, 70cm, Beyaz | C6: 3 | N6: =L6+M6+K6+J6+I6+H6+G6+F6+E6+D6+C6 -> 3 | P6: PRİM HARİÇ | Q6: 31769.317 | R6: 31769.317 | S6: 33040.09 | T6: 34310.863 | U6: 34946.249
A7: KD55NNWE0N | B7: =IFERROR(HYPERLINK(VLOOKUP(A7,ÜRÜNLER!A:C,3,FALSE),VLOOKUP(A7,ÜRÜNLER!A:B,2,FALSE)),"") -> iQ300 Üstten Donduruculu Kulpsuz Buzdolabı, 70cm, Beyaz | C7: 6 | N7: =L7+M7+K7+J7+I7+H7+G7+F7+E7+D7+C7 -> 6 | P7: PRİM HARİÇ | Q7: 35726.773 | R7: 35000 | S7: 36400 | T7: 37800 | U7: 38500 | V7: 979.09857
A8: KD55NNLE0N | B8: =IFERROR(HYPERLINK(VLOOKUP(A8,ÜRÜNLER!A:C,3,FALSE),VLOOKUP(A8,ÜRÜNLER!A:B,2,FALSE)),"") -> iQ300 Üstten Donduruculu Kulpsuz Buzdolabı, 70cm, Inox Görünümlü | C8: 8 | N8: =L8+M8+K8+J8+I8+H8+G8+F8+E8+D8+C8 -> 8 | P8: PRİM HARİÇ | Q8: 41958.595 | R8: 41000 | S8: 42640 | T8: 44280 | U8: 45100 | V8: 5859.7582
A9: KD56NXWF1N | B9: =IFERROR(HYPERLINK(VLOOKUP(A9,ÜRÜNLER!A:C,3,FALSE),VLOOKUP(A9,ÜRÜNLER!A:B,2,FALSE)),"") -> iQ300 Üstten Donduruculu Kulpsuz Buzdolabı, 70cm, Beyaz | K9: 1 | N9: =L9+M9+K9+J9+I9+H9+G9+F9+E9+D9+C9 -> 1 | Q9: devamı yok | R9: 40000 | S9: 41600 | T9: 43200 | U9: 44000 | X9: 250
A10: KD76NAIE1N | B10: =IFERROR(HYPERLINK(VLOOKUP(A10,ÜRÜNLER!A:C,3,FALSE),VLOOKUP(A10,ÜRÜNLER!A:B,2,FALSE)),"") -> iQ500 Üstten Donduruculu Kulplu Buzdolabı, 75cm, Inox | C10: 12 | N10: =L10+M10+K10+J10+I10+H10+G10+F10+E10+D10+C10 -> 12 | Q10: 82878.063 | R10: 77000 | S10: 80080 | T10: 83160 | U10: 84700 | V10: 14278.063
A11: KD76NAWE1N | B11: =IFERROR(HYPERLINK(VLOOKUP(A11,ÜRÜNLER!A:C,3,FALSE),VLOOKUP(A11,ÜRÜNLER!A:B,2,FALSE)),"") -> iQ500 Üstten Donduruculu Kulplu Buzdolabı, 75cm, Beyaz | C11: 5 | N11: =L11+M11+K11+J11+I11+H11+G11+F11+E11+D11+C11 -> 5 | Q11: 60820.823 | R11: 57779.782 | S11: 60090.973 | T11: 62402.164 | U11: 63557.76
A12: KD76NXIE1N | B12: =IFERROR(HYPERLINK(VLOOKUP(A12,ÜRÜNLER!A:C,3,FALSE),VLOOKUP(A12,ÜRÜNLER!A:B,2,FALSE)),"") -> iQ500 Üstten Donduruculu Kulpsuz Buzdolabı, 75cm, Inox | C12: 13 | N12: =L12+M12+K12+J12+I12+H12+G12+F12+E12+D12+C12 -> 13 | Q12: 66166.491 | R12: 61000 | S12: 63440 | T12: 65880 | U12: 67100 | V12: 4802.538
A13: KD76NXWE1N | B13: =IFERROR(HYPERLINK(VLOOKUP(A13,ÜRÜNLER!A:C,3,FALSE),VLOOKUP(A13,ÜRÜNLER!A:B,2,FALSE)),"") -> iQ300 Üstten Donduruculu, Kulpsuz Buzdolabı, 75cm, Beyaz | C13: 5 | I13: 1 | J13: 1 | L13: 1 | N13: =L13+M13+K13+J13+I13+H13+G13+F13+E13+D13+C13 -> 8 | O13: 1 | Q13: 61265.27 | R13: 58202.006 | S13: 60530.087 | T13: 62858.167 | U13: 64022.207 | V13: 3669.921
A14: KD76NXWE0N | B14: =IFERROR(HYPERLINK(VLOOKUP(A14,ÜRÜNLER!A:C,3,FALSE),VLOOKUP(A14,ÜRÜNLER!A:B,2,FALSE)),"") -> iQ300 Üstten Donduruculu Kulpsuz Buzdolabı, 75cm, Beyaz | K14: 1 | N14: =L14+M14+K14+J14+I14+H14+G14+F14+E14+D14+C14 -> 1 | Q14: devamı yok | R14: 55000 | S14: 57200 | T14: 59400 | U14: 60500 | X14: 250
A15: KD86NAID1N | B15: =IFERROR(HYPERLINK(VLOOKUP(A15,ÜRÜNLER!A:C,3,FALSE),VLOOKUP(A15,ÜRÜNLER!A:B,2,FALSE)),"") -> iQ500 Üstten Donduruculu Kulplu Buzdolabı, 86cm, Inox | C15: 11 | E15: 1 | I15: 1 | J15: 1 | M15: 1 | N15: =L15+M15+K15+J15+I15+H15+G15+F15+E15+D15+C15 -> 15 | O15: 2 | Q15: 95662.202 | R15: 90879.092 | S15: 94514.256 | T15: 98149.42 | U15: 99967.001 | V15: 20501.737
A16: KD86NAWE1N | B16: =IFERROR(HYPERLINK(VLOOKUP(A16,ÜRÜNLER!A:C,3,FALSE),VLOOKUP(A16,ÜRÜNLER!A:B,2,FALSE)),"") -> iQ500 Üstten Donduruculu Kulplu Buzdolabı, 86cm, Beyaz | C16: 8 | N16: =L16+M16+K16+J16+I16+H16+G16+F16+E16+D16+C16 -> 8 | Q16: 83239.542 | R16: 79077.565 | S16: 82240.667 | T16: 85403.77 | U16: 86985.321 | V16: 13182.565
A17: KD86NHID1N | B17: =IFERROR(HYPERLINK(VLOOKUP(A17,ÜRÜNLER!A:C,3,FALSE),VLOOKUP(A17,ÜRÜNLER!A:B,2,FALSE)),"") -> iQ500 Üstten Donduruculu Kulplu Buzdolabı, 86cm, Inox | K17: 1 | N17: =L17+M17+K17+J17+I17+H17+G17+F17+E17+D17+C17 -> 1 | Q17: devamı yok | R17: 55000 | S17: 57200 | T17: 59400 | U17: 60500 | X17: 250
A18: KG36NNLE0N | B18: =IFERROR(HYPERLINK(VLOOKUP(A18,ÜRÜNLER!A:C,3,FALSE),VLOOKUP(A18,ÜRÜNLER!A:B,2,FALSE)),"") -> iQ100 Alttan Donduruculu Kulpsuz Buzdolabı, 60cm, Inox | F18: 1 | N18: =L18+M18+K18+J18+I18+H18+G18+F18+E18+D18+C18 -> 1 | Q18: devamı yok | R18: 40000 | S18: 41600 | T18: 43200 | U18: 44000 | X18: 250
A19: KG55NCIE0N | B19: =IFERROR(HYPERLINK(VLOOKUP(A19,ÜRÜNLER!A:C,3,FALSE),VLOOKUP(A19,ÜRÜNLER!A:B,2,FALSE)),"") -> iQ300 Alttan Donduruculu Kulpsuz Buzdolabı, 70cm, Inox | C19: 112 | E19: 4 | F19: 1 | I19: 1 | J19: 1 | K19: 1 | L19: 1 | N19: =L19+M19+K19+J19+I19+H19+G19+F19+E19+D19+C19 -> 121 | Q19: 63469.622 | R19: 59026.749 | S19: 61387.819 | T19: 63748.889 | U19: 64929.423 | V19: 15763.808
A20: KG55NCWE0N | B20: =IFERROR(HYPERLINK(VLOOKUP(A20,ÜRÜNLER!A:C,3,FALSE),VLOOKUP(A20,ÜRÜNLER!A:B,2,FALSE)),"") -> iQ300 Alttan Donduruculu Kulpsuz Buzdolabı, 70cm, Beyaz | C20: 93 | I20: 1 | K20: 2 | N20: =L20+M20+K20+J20+I20+H20+G20+F20+E20+D20+C20 -> 96 | Q20: 57039.061 | R20: 53046.327 | S20: 55168.18 | T20: 57290.033 | U20: 58350.96 | V20: 11099.526
A21: KG55NVIE0N | B21: =IFERROR(HYPERLINK(VLOOKUP(A21,ÜRÜNLER!A:C,3,FALSE),VLOOKUP(A21,ÜRÜNLER!A:B,2,FALSE)),"") -> iQ300 Alttan Donduruculu Kulpsuz Buzdolabı, 70cm, Inox | C21: 15 | E21: 1 | K21: 1 | N21: =L21+M21+K21+J21+I21+H21+G21+F21+E21+D21+C21 -> 17 | Q21: 51274.363 | R21: 47685.157 | S21: 49592.564 | T21: 51499.97 | U21: 52453.673 | V21: 7695.2929
A22: KG55NVWE0N | B22: =IFERROR(HYPERLINK(VLOOKUP(A22,ÜRÜNLER!A:C,3,FALSE),VLOOKUP(A22,ÜRÜNLER!A:B,2,FALSE)),"") -> iQ300 Alttan Donduruculu Kulpsuz Buzdolabı, 70cm, Beyaz | E22: 1 | I22: 1 | K22: 1 | N22: =L22+M22+K22+J22+I22+H22+G22+F22+E22+D22+C22 -> 3 | Q22: 46796.713 | R22: 44456.877 | S22: 46235.152 | T22: 48013.427 | U22: 48902.565 | V22: 6481.5964
A23: KG56NLBE0N | B23: =IFERROR(HYPERLINK(VLOOKUP(A23,ÜRÜNLER!A:C,3,FALSE),VLOOKUP(A23,ÜRÜNLER!A:B,2,FALSE)),"") -> iQ500 Alttan Donduruculu Kulpsuz Buzdolabı, 70cm, Parlak Siyah | C23: 10 | I23: 2 | J23: 1 | L23: 2 | M23: 1 | N23: =L23+M23+K23+J23+I23+H23+G23+F23+E23+D23+C23 -> 16 | Q23: 58065.822 | R23: 55162.531 | S23: 57369.032 | T23: 59575.533 | U23: 60678.784
A24: KG56NQWF0N | B24: =IFERROR(HYPERLINK(VLOOKUP(A24,ÜRÜNLER!A:C,3,FALSE),VLOOKUP(A24,ÜRÜNLER!A:B,2,FALSE)),"") -> iQ500 Alttan Donduruculu Kulpsuz Buzdolabı, 70cm, Seramik Desen | J24: 1 | N24: =L24+M24+K24+J24+I24+H24+G24+F24+E24+D24+C24 -> 1 | Q24: devamı yok | R24: 48000 | S24: 49920 | T24: 51840 | U24: 52800 | X24: 250
A25: KG56NTEE0N | B25: =IFERROR(HYPERLINK(VLOOKUP(A25,ÜRÜNLER!A:C,3,FALSE),VLOOKUP(A25,ÜRÜNLER!A:B,2,FALSE)),"") -> iQ500 Alttan Donduruculu Kulpsuz Buzdolabı, 70cm, Mat Siyah | F25: 1 | N25: =L25+M25+K25+J25+I25+H25+G25+F25+E25+D25+C25 -> 1 | Q25: devamı yok | R25: 48000 | S25: 49920 | T25: 51840 | U25: 52800 | X25: 250
A26: KG56NTWE0N | B26: =IFERROR(HYPERLINK(VLOOKUP(A26,ÜRÜNLER!A:C,3,FALSE),VLOOKUP(A26,ÜRÜNLER!A:B,2,FALSE)),"") -> iQ500 Alttan Donduruculu Kulpsuz Buzdolabı, 70cm, Seramik Desen | I26: 1 | K26: 1 | N26: =L26+M26+K26+J26+I26+H26+G26+F26+E26+D26+C26 -> 2 | Q26: devamı yok | R26: 48000 | S26: 49920 | T26: 51840 | U26: 52800 | X26: 250
A27: KG56NNWD0N | B27: =IFERROR(HYPERLINK(VLOOKUP(A27,ÜRÜNLER!A:C,3,FALSE),VLOOKUP(A27,ÜRÜNLER!A:B,2,FALSE)),"") -> iQ100 Alttan Donduruculu Kulpsuz Buzdolabı, 70cm, Beyaz (Wi-Fi) | C27: 5 | N27: =L27+M27+K27+J27+I27+H27+G27+F27+E27+D27+C27 -> 5 | Q27: 38507.814 | R27: 38507.814 | S27: 40048.127 | T27: 41588.439 | U27: 42358.595
A28: KG56NVPD0N | B28: =IFERROR(HYPERLINK(VLOOKUP(A28,ÜRÜNLER!A:C,3,FALSE),VLOOKUP(A28,ÜRÜNLER!A:B,2,FALSE)),"") -> iQ300 Alttan Donduruculu Kulpsuz Buzdolabı, 70cm, Inox (Wi-Fi) | C28: 1 | N28: =L28+M28+K28+J28+I28+H28+G28+F28+E28+D28+C28 -> 1 | Q28: 45794.451 | R28: 45794.451 | S28: 47626.229 | T28: 49458.007 | U28: 50373.897 | V28: 367.70719
A29: KG56NVWD0N | B29: =IFERROR(HYPERLINK(VLOOKUP(A29,ÜRÜNLER!A:C,3,FALSE),VLOOKUP(A29,ÜRÜNLER!A:B,2,FALSE)),"") -> iQ300 Alttan Donduruculu Kulpsuz Buzdolabı, 70cm, Beyaz (Wi-Fi) | N29: =L29+M29+K29+J29+I29+H29+G29+F29+E29+D29+C29 -> 0 | O29: 5 | Q29: 42393.399 | R29: 42393.399 | S29: 44089.134 | T29: 45784.87 | U29: 46632.738
A30: KG76APIE0N | B30: =IFERROR(HYPERLINK(VLOOKUP(A30,ÜRÜNLER!A:C,3,FALSE),VLOOKUP(A30,ÜRÜNLER!A:B,2,FALSE)),"") -> iQ700 Alttan Donduruculu Kulplu Buzdolabı, 75cm, Inox | C30: 16 | N30: =L30+M30+K30+J30+I30+H30+G30+F30+E30+D30+C30 -> 16 | Q30: 82180.742 | R30: 78071.705 | S30: 81194.573 | T30: 84317.441 | U30: 85878.876 | V30: 2991.2073 | X30: 250
A31: KG76NCIE0N | B31: =IFERROR(HYPERLINK(VLOOKUP(A31,ÜRÜNLER!A:C,3,FALSE),VLOOKUP(A31,ÜRÜNLER!A:B,2,FALSE)),"") -> iQ500 Alttan Donduruculu Kulplu Buzdolabı, 75cm, Inox | C31: 34 | I31: 1 | J31: 1 | K31: 3 | L31: 1 | N31: =L31+M31+K31+J31+I31+H31+G31+F31+E31+D31+C31 -> 40 | O31: 1 | Q31: 84280.726 | R31: 80066.69 | S31: 83269.357 | T31: 86472.025 | U31: 88073.359 | V31: 13930.726
A32: KG76NCWE0N | B32: =IFERROR(HYPERLINK(VLOOKUP(A32,ÜRÜNLER!A:C,3,FALSE),VLOOKUP(A32,ÜRÜNLER!A:B,2,FALSE)),"") -> iQ500 Alttan Donduruculu Kulplu Buzdolabı, 75cm, Beyaz | C32: 46 | I32: 1 | K32: 1 | N32: =L32+M32+K32+J32+I32+H32+G32+F32+E32+D32+C32 -> 48 | Q32: 77045.044 | R32: 73192.792 | S32: 76120.503 | T32: 79048.215 | U32: 80512.071 | V32: 9714.8112
A33: KG76NCXE0N | B33: =IFERROR(HYPERLINK(VLOOKUP(A33,ÜRÜNLER!A:C,3,FALSE),VLOOKUP(A33,ÜRÜNLER!A:B,2,FALSE)),"") -> iQ500 Alttan Donduruculu Kulpsuz Buzdolabı, 75cm, darkSteel | I33: 1 | J33: 1 | L33: 1 | N33: =L33+M33+K33+J33+I33+H33+G33+F33+E33+D33+C33 -> 3 | O33: 39 | Q33: 95152.057 | R33: 95152.057 | S33: 98958.14 | T33: 102764.22 | U33: 104667.26 | V33: 23157.871
A34: KG76NVIE0N | B34: =IFERROR(HYPERLINK(VLOOKUP(A34,ÜRÜNLER!A:C,3,FALSE),VLOOKUP(A34,ÜRÜNLER!A:B,2,FALSE)),"") -> iQ300 Alttan Donduruculu Kulpsuz Buzdolabı, 75cm, Inox | C34: 37 | F34: 1 | I34: 1 | K34: 2 | N34: =L34+M34+K34+J34+I34+H34+G34+F34+E34+D34+C34 -> 41 | O34: 1 | Q34: 76173.043 | R34: 72364.391 | S34: 75258.967 | T34: 78153.542 | U34: 79600.83 | V34: 12090.485
A35: KG76NVWE0N | B35: =IFERROR(HYPERLINK(VLOOKUP(A35,ÜRÜNLER!A:C,3,FALSE),VLOOKUP(A35,ÜRÜNLER!A:B,2,FALSE)),"") -> iQ300 Alttan Donduruculu Kulpsuz Buzdolabı, 75cm, Beyaz | C35: 48 | I35: 1 | J35: 1 | L35: 1 | N35: =L35+M35+K35+J35+I35+H35+G35+F35+E35+D35+C35 -> 51 | Q35: 68727.331 | R35: 63916.418 | S35: 66473.075 | T35: 69029.731 | U35: 70308.06 | V35: 7119.1916
A36: KG76PAIC0N | B36: =IFERROR(HYPERLINK(VLOOKUP(A36,ÜRÜNLER!A:C,3,FALSE),VLOOKUP(A36,ÜRÜNLER!A:B,2,FALSE)),"") -> iQ700 Alttan Donduruculu Kulplu Buzdolabı, 75cm, Inox | C36: 59 | E36: 2 | F36: 1 | I36: 1 | J36: 1 | L36: 1 | N36: =L36+M36+K36+J36+I36+H36+G36+F36+E36+D36+C36 -> 65 | O36: 1 | Q36: 89108.337 | R36: 82870.754 | S36: 86185.584 | T36: 89500.414 | U36: 91157.829 | V36: 11562.989
A37: KG76PAWC0N | B37: =IFERROR(HYPERLINK(VLOOKUP(A37,ÜRÜNLER!A:C,3,FALSE),VLOOKUP(A37,ÜRÜNLER!A:B,2,FALSE)),"") -> iQ700 Alttan Donduruculu Kulplu Buzdolabı, 75cm, Beyaz | C37: 33 | E37: 1 | I37: 1 | K37: 3 | N37: =L37+M37+K37+J37+I37+H37+G37+F37+E37+D37+C37 -> 38 | O37: 1 | Q37: 82556.235 | R37: 76777.298 | S37: 79848.39 | T37: 82919.482 | U37: 84455.028 | V37: 9308.5602
A38: KG86NAID2N | B38: =IFERROR(HYPERLINK(VLOOKUP(A38,ÜRÜNLER!A:C,3,FALSE),VLOOKUP(A38,ÜRÜNLER!A:B,2,FALSE)),"") -> iQ500 Alttan Donduruculu Kulplu Buzdolabı, 86cm, Inox | C38: 189 | E38: 1 | F38: 2 | I38: 1 | J38: 1 | K38: 1 | L38: 1 | N38: =L38+M38+K38+J38+I38+H38+G38+F38+E38+D38+C38 -> 196 | Q38: 97945.234 | R38: 91089.067 | S38: 94732.63 | T38: 98376.193 | U38: 100197.97 | V38: 22125.466
A39: KG86NCWE0N | B39: =IFERROR(HYPERLINK(VLOOKUP(A39,ÜRÜNLER!A:C,3,FALSE),VLOOKUP(A39,ÜRÜNLER!A:B,2,FALSE)),"") -> iQ500 Alttan Donduruculu Kulplu Buzdolabı, 86cm, Beyaz | C39: 23 | F39: 1 | I39: 1 | N39: =L39+M39+K39+J39+I39+H39+G39+F39+E39+D39+C39 -> 25 | Q39: 84927.533 | R39: 78982.606 | S39: 82141.91 | T39: 85301.214 | U39: 86880.866 | V39: 13169.393
A40: KG86NVWE0N | B40: =IFERROR(HYPERLINK(VLOOKUP(A40,ÜRÜNLER!A:C,3,FALSE),VLOOKUP(A40,ÜRÜNLER!A:B,2,FALSE)),"") -> iQ500 Alttan Donduruculu Kulpsuz Buzdolabı, 86cm, Beyaz | C40: 47 | F40: 1 | J40: 1 | N40: =L40+M40+K40+J40+I40+H40+G40+F40+E40+D40+C40 -> 49 | O40: 1 | Q40: 75297.093 | R40: 70026.296 | S40: 72827.348 | T40: 75628.4 | U40: 77028.926 | V40: 7901.7438
...

Sheet HESAPLAYICI
A1: =Sayfa1!A1 -> STOK KODU | B1: =Sayfa1!B1 -> AÇIKLAMA | C1: =Sayfa1!C1 -> 04 TEMMUZ HOROZ | D1: =Sayfa1!$R$1 -> HAVALE FİYATI | E1: =Sayfa1!$S$1 -> TEK ÇEKİM FİYATI | F1: =Sayfa1!$T$1 -> TAKSİTLİ FİYATI 3/6 TAKSİT | G1: =Sayfa1!$U$1 -> WEB TAHSİLAT BONUS 9 | H1: =Sayfa1!$V$1 -> TEMMUZ BİP | I1: Toplam Bundle İndirim Tutarını Aşağıya Yaz | J1: =Sayfa1!$X$1 -> Hakedişler LİSTE FİYATINDAN SATILIRSA geçerli olacak | K1: =Sayfa1!$W$1 -> 31.08.2026 montaj zorunlu phase out | L1: BİP KOŞULU
A2: HB534FER0T | B2: =IFERROR(VLOOKUP(A2,Sayfa1!A:B,2,FALSE),"?") -> iQ300 Ankastre Fırın, 1 Teleskopik Ray, Arkası Kendini Temizler, Siyah/Inox | C2: =IFERROR(VLOOKUP(A2,Sayfa1!A:C,3,FALSE),"?") -> 0 | D2: =IFERROR(VLOOKUP(A2,Sayfa1!$A:$R,17,FALSE),"?") -> devamı yok | E2: =IFERROR(VLOOKUP(A2,Sayfa1!$A:$S,18,FALSE),"?") -> 17000 | F2: =IFERROR(VLOOKUP(A2,Sayfa1!$A:$T,19,FALSE),"?") -> 17680 | G2: =IFERROR(VLOOKUP(A2,Sayfa1!$A:$U,20,FALSE),"?") -> 18360 | H2: =IFERROR(VLOOKUP(A2,Sayfa1!$A:$V,21,FALSE),"?") -> 18700 | J2: =IFERROR(VLOOKUP(A2,Sayfa1!$A:$X,23,FALSE),"?") -> 1656.58 | K2: =IFERROR(VLOOKUP(A2,Sayfa1!$A:$W,22,FALSE),"?") -> 0 | L2: =IFERROR(VLOOKUP(A2,Sayfa1!$A:$Y,24,FALSE),"?") -> 250
B3: =IFERROR(VLOOKUP(A3,Sayfa1!A:B,2,FALSE),"?") -> ? | C3: =IFERROR(VLOOKUP(A3,Sayfa1!A:C,3,FALSE),"?") -> ? | D3: =IFERROR(VLOOKUP(A3,Sayfa1!$A:$R,17,FALSE),"?") -> ? | E3: =IFERROR(VLOOKUP(A3,Sayfa1!$A:$S,18,FALSE),"?") -> ? | F3: =IFERROR(VLOOKUP(A3,Sayfa1!$A:$T,19,FALSE),"?") -> ? | G3: =IFERROR(VLOOKUP(A3,Sayfa1!$A:$U,20,FALSE),"?") -> ? | H3: =IFERROR(VLOOKUP(A3,Sayfa1!$A:$V,21,FALSE),"?") -> ? | J3: =IFERROR(VLOOKUP(A3,Sayfa1!$A:$X,23,FALSE),"?") -> ? | K3: =IFERROR(VLOOKUP(A3,Sayfa1!$A:$W,22,FALSE),"?") -> ? | L3: =IFERROR(VLOOKUP(A3,Sayfa1!$A:$Y,24,FALSE),"?") -> ?
B4: =IFERROR(VLOOKUP(A4,Sayfa1!A:B,2,FALSE),"?") -> ? | C4: =IFERROR(VLOOKUP(A4,Sayfa1!A:C,3,FALSE),"?") -> ? | D4: =IFERROR(VLOOKUP(A4,Sayfa1!$A:$R,17,FALSE),"?") -> ? | E4: =IFERROR(VLOOKUP(A4,Sayfa1!$A:$S,18,FALSE),"?") -> ? | F4: =IFERROR(VLOOKUP(A4,Sayfa1!$A:$T,19,FALSE),"?") -> ? | G4: =IFERROR(VLOOKUP(A4,Sayfa1!$A:$U,20,FALSE),"?") -> ? | H4: =IFERROR(VLOOKUP(A4,Sayfa1!$A:$V,21,FALSE),"?") -> ? | J4: =IFERROR(VLOOKUP(A4,Sayfa1!$A:$X,23,FALSE),"?") -> ? | K4: =IFERROR(VLOOKUP(A4,Sayfa1!$A:$W,22,FALSE),"?") -> ? | L4: =IFERROR(VLOOKUP(A4,Sayfa1!$A:$Y,24,FALSE),"?") -> ?
B5: =IFERROR(VLOOKUP(A5,Sayfa1!A:B,2,FALSE),"?") -> ? | C5: =IFERROR(VLOOKUP(A5,Sayfa1!A:C,3,FALSE),"?") -> ? | D5: =IFERROR(VLOOKUP(A5,Sayfa1!$A:$R,17,FALSE),"?") -> ? | E5: =IFERROR(VLOOKUP(A5,Sayfa1!$A:$S,18,FALSE),"?") -> ? | F5: =IFERROR(VLOOKUP(A5,Sayfa1!$A:$T,19,FALSE),"?") -> ? | G5: =IFERROR(VLOOKUP(A5,Sayfa1!$A:$U,20,FALSE),"?") -> ? | H5: =IFERROR(VLOOKUP(A5,Sayfa1!$A:$V,21,FALSE),"?") -> ? | J5: =IFERROR(VLOOKUP(A5,Sayfa1!$A:$X,23,FALSE),"?") -> ? | K5: =IFERROR(VLOOKUP(A5,Sayfa1!$A:$W,22,FALSE),"?") -> ? | L5: =IFERROR(VLOOKUP(A5,Sayfa1!$A:$Y,24,FALSE),"?") -> ?
B6: =IFERROR(VLOOKUP(A6,Sayfa1!A:B,2,FALSE),"?") -> ? | C6: =IFERROR(VLOOKUP(A6,Sayfa1!A:C,3,FALSE),"?") -> ? | D6: =IFERROR(VLOOKUP(A6,Sayfa1!$A:$R,17,FALSE),"?") -> ? | E6: =IFERROR(VLOOKUP(A6,Sayfa1!$A:$S,18,FALSE),"?") -> ? | F6: =IFERROR(VLOOKUP(A6,Sayfa1!$A:$T,19,FALSE),"?") -> ? | G6: =IFERROR(VLOOKUP(A6,Sayfa1!$A:$U,20,FALSE),"?") -> ? | H6: =IFERROR(VLOOKUP(A6,Sayfa1!$A:$V,21,FALSE),"?") -> ? | J6: =IFERROR(VLOOKUP(A6,Sayfa1!$A:$X,23,FALSE),"?") -> ? | K6: =IFERROR(VLOOKUP(A6,Sayfa1!$A:$W,22,FALSE),"?") -> ? | L6: =IFERROR(VLOOKUP(A6,Sayfa1!$A:$Y,24,FALSE),"?") -> ?
B7: =IFERROR(VLOOKUP(A7,Sayfa1!A:B,2,FALSE),"?") -> ? | C7: =IFERROR(VLOOKUP(A7,Sayfa1!A:C,3,FALSE),"?") -> ? | D7: =IFERROR(VLOOKUP(A7,Sayfa1!$A:$R,17,FALSE),"?") -> ? | E7: =IFERROR(VLOOKUP(A7,Sayfa1!$A:$S,18,FALSE),"?") -> ? | F7: =IFERROR(VLOOKUP(A7,Sayfa1!$A:$T,19,FALSE),"?") -> ? | G7: =IFERROR(VLOOKUP(A7,Sayfa1!$A:$U,20,FALSE),"?") -> ? | H7: =IFERROR(VLOOKUP(A7,Sayfa1!$A:$V,21,FALSE),"?") -> ? | J7: =IFERROR(VLOOKUP(A7,Sayfa1!$A:$X,23,FALSE),"?") -> ? | K7: =IFERROR(VLOOKUP(A7,Sayfa1!$A:$W,22,FALSE),"?") -> ? | L7: =IFERROR(VLOOKUP(A7,Sayfa1!$A:$Y,24,FALSE),"?") -> ?
B8: =IFERROR(VLOOKUP(A8,Sayfa1!A:B,2,FALSE),"?") -> ? | C8: =IFERROR(VLOOKUP(A8,Sayfa1!A:C,3,FALSE),"?") -> ? | D8: =IFERROR(VLOOKUP(A8,Sayfa1!$A:$R,17,FALSE),"?") -> ? | E8: =IFERROR(VLOOKUP(A8,Sayfa1!$A:$S,18,FALSE),"?") -> ? | F8: =IFERROR(VLOOKUP(A8,Sayfa1!$A:$T,19,FALSE),"?") -> ? | G8: =IFERROR(VLOOKUP(A8,Sayfa1!$A:$U,20,FALSE),"?") -> ? | H8: =IFERROR(VLOOKUP(A8,Sayfa1!$A:$V,21,FALSE),"?") -> ? | J8: =IFERROR(VLOOKUP(A8,Sayfa1!$A:$X,23,FALSE),"?") -> ? | K8: =IFERROR(VLOOKUP(A8,Sayfa1!$A:$W,22,FALSE),"?") -> ? | L8: =IFERROR(VLOOKUP(A8,Sayfa1!$A:$Y,24,FALSE),"?") -> ?
B9: =IFERROR(VLOOKUP(A9,Sayfa1!A:B,2,FALSE),"?") -> ? | C9: =IFERROR(VLOOKUP(A9,Sayfa1!A:C,3,FALSE),"?") -> ? | D9: =IFERROR(VLOOKUP(A9,Sayfa1!$A:$R,17,FALSE),"?") -> ? | E9: =IFERROR(VLOOKUP(A9,Sayfa1!$A:$S,18,FALSE),"?") -> ? | F9: =IFERROR(VLOOKUP(A9,Sayfa1!$A:$T,19,FALSE),"?") -> ? | G9: =IFERROR(VLOOKUP(A9,Sayfa1!$A:$U,20,FALSE),"?") -> ? | H9: =IFERROR(VLOOKUP(A9,Sayfa1!$A:$V,21,FALSE),"?") -> ? | J9: =IFERROR(VLOOKUP(A9,Sayfa1!$A:$X,23,FALSE),"?") -> ? | K9: =IFERROR(VLOOKUP(A9,Sayfa1!$A:$W,22,FALSE),"?") -> ? | L9: =IFERROR(VLOOKUP(A9,Sayfa1!$A:$Y,24,FALSE),"?") -> ?
B10: =IFERROR(VLOOKUP(A10,Sayfa1!A:B,2,FALSE),"?") -> ? | C10: =IFERROR(VLOOKUP(A10,Sayfa1!A:C,3,FALSE),"?") -> ? | D10: =IFERROR(VLOOKUP(A10,Sayfa1!$A:$R,17,FALSE),"?") -> ? | E10: =IFERROR(VLOOKUP(A10,Sayfa1!$A:$S,18,FALSE),"?") -> ? | F10: =IFERROR(VLOOKUP(A10,Sayfa1!$A:$T,19,FALSE),"?") -> ? | G10: =IFERROR(VLOOKUP(A10,Sayfa1!$A:$U,20,FALSE),"?") -> ? | H10: =IFERROR(VLOOKUP(A10,Sayfa1!$A:$V,21,FALSE),"?") -> ? | J10: =IFERROR(VLOOKUP(A10,Sayfa1!$A:$X,23,FALSE),"?") -> ? | K10: =IFERROR(VLOOKUP(A10,Sayfa1!$A:$W,22,FALSE),"?") -> ? | L10: =IFERROR(VLOOKUP(A10,Sayfa1!$A:$Y,24,FALSE),"?") -> ?
B11: =IFERROR(VLOOKUP(A11,Sayfa1!A:B,2,FALSE),"?") -> ? | C11: =IFERROR(VLOOKUP(A11,Sayfa1!A:C,3,FALSE),"?") -> ? | D11: =IFERROR(VLOOKUP(A11,Sayfa1!$A:$R,17,FALSE),"?") -> ? | E11: =IFERROR(VLOOKUP(A11,Sayfa1!$A:$S,18,FALSE),"?") -> ? | F11: =IFERROR(VLOOKUP(A11,Sayfa1!$A:$T,19,FALSE),"?") -> ? | G11: =IFERROR(VLOOKUP(A11,Sayfa1!$A:$U,20,FALSE),"?") -> ? | H11: =IFERROR(VLOOKUP(A11,Sayfa1!$A:$V,21,FALSE),"?") -> ? | J11: =IFERROR(VLOOKUP(A11,Sayfa1!$A:$X,23,FALSE),"?") -> ? | K11: =IFERROR(VLOOKUP(A11,Sayfa1!$A:$W,22,FALSE),"?") -> ? | L11: =IFERROR(VLOOKUP(A11,Sayfa1!$A:$Y,24,FALSE),"?") -> ?
A12: Toplam Satış Fiyatı | E12: =SUM(E2:E11) -> 17000 | F12: =SUM(F2:F11) -> 17680
A13: BİP İndirimi | E13: =SUM(G:G)*-1 -> -18360 | F13: =SUM(G:G)*-1 -> -18360
A14: PhaseOut İndirimi | E14: =SUM(H:H)*-1 -> -18700 | F14: =SUM(H:H)*-1 -> -18700
A15: Toplam Bundle İndirimi | E15: =I2*-1 -> 0 | F15: =I2*-1 -> 0
A16: Satılabilir Minimum Fiyat | E16: =SUM(E12:E15) -> -20060 | F16: =SUM(F12:F15) -> -19380
A17: Satılabilir Minimum Taksitli Fiyat | E17: =E16*1.08 -> -21664.8

Sheet Bundle Kampanya
K3: Seçili Ankastre Set Alımına perakende de 5.000 TL İndirim! | L3: Geçerli Ankastre Fırınlar
C5: 2'li LDA alımında perakende de 5.000 TL İndirim! | D5: 2’li LDA alımında 5.000 ₺ indirim uygulanır.“diğer kampanyalar ile birleşemez” 4.000 ₺ kdv dahil fiyat farkı hak edişi ödenecektir. (Buzdolabı – Bulaşık – Çamaşır – Kurutma – Derin Dondurucu) | L5: HB012FBH1T, HB012FBB1T, HB012FBW1T + (phase out iQ300 ve iQ500 segment modeller) Ankastre fırınlarda geçerlidir. (HB011* ve giriş segment muadili modeller dahil değildir.)
L9: Uygulama koşulları : Seçili ankastre fırınlar ile set (fırın+ocak+dav.) set alana perakende de 5.000 ₺ indirim uygulanır. Diğer fırınlarda geçerli değildir. KDV dahil 3.700 ₺ hak ediş ödenir. Giriş setlerde geçerli değildir.
C17: XL - XXL Buzdolabı alana VSX21A300 Toz Torbasız Süpürge Hediye! “diğer kampanyalar ile birleşemez” | D17: XL veya XXL Buzdolabı alana perakende de VSX21A300 Toz Torbasız Süpürge Hediye verilir veya "Diğer Süpürgelerde perakende de 11.500 ₺ indirim uygulanır" (Dik şarjlı süpürgelerde dahildir.) 8.200 ₺ kdv dahil fiyat farkı hak edişi ödenecektir. “Diğer kampanyalar ile birleşemez” (Süpürge almak istemeyen tüketiciler için Buzdolaplarında indirim yapılabilir.)
K21: Seçili Ankastre Set Alımına perakende de 9.000 TL İndirim! | L21: Geçerli Ankastre Setler
L23: HB778G3B1, HR776G3B1, HS736G1B2, HB776G1B1, HB734G1B1, HR232GEB3, HB557JEB6T, HJ852GYN0T, HJ852GYB0T, HJ852GYW0T, HU736AEG0T, HU736AEV0T, HU736AEA0T, HU736AEN0T, HU717ABN0T, HU717ABA0T, HU717ABV0T
L27: Uygulama koşulları : Seçili ankastre fırınlar ile set (fırın+ocak+dav.) set alana perakende de 9.000 ₺ indirim uygulanır. KDV dahil 6.900 ₺ hak ediş ödenir. Giriş setlerde geçerli değildir.

Sheet ÜRÜNLER
A1: Ürün No | B1: Ürün Adı | C1: Ürün Linki | D1: Ürün Grubu | E1: Marka
A2: 50PUS8009/62 | B2: Philips 50" 4K Ambilight LED TV (Titan OS) (50PUS8009/62) | C2: https://www.philips.com.tr/c-p/50PUS8009_62/led-50pus8009-4k-ambilight-tv | D2: Televizyon | E2: Philips
A3: 55PUS8349/62 | B3: Philips 55" 4K Ambilight LED TV (Titan OS) (55PUS8349/62) | C3: https://www.philips.com.tr/c-p/55PUS8349_62/led-55pus8349-4k-ambilight-tv | D3: Televizyon | E3: Philips
A4: AS09IVW32N | B4: Siemens Ev Tipi Klima İç Ünite, 9.000BTU, Beyaz | C4: https://www.siemens-home.bsh-group.com/tr/tr/product/klimalar/AS09XVW32N | D4: Klima | E4: Siemens
A5: AS09OVW32N | B5: Siemens Ev Tipi Klima Dış Ünite, 9.000BTU, Beyaz | C5: https://www.siemens-home.bsh-group.com/tr/tr/product/klimalar/AS09XVW32N | D5: Klima | E5: Siemens
A6: AS12IVW30N | B6: Siemens Ev Tipi Klima İç Ünite, 12.000BTU, Beyaz | C6: https://www.siemens-home.bsh-group.com/tr/tr/product/klimalar/AS12XVW32N | D6: Klima | E6: Siemens
A7: AS12IVW32N | B7: Siemens Ev Tipi Klima İç Ünite, 12.000BTU, Beyaz | C7: https://www.siemens-home.bsh-group.com/tr/tr/product/klimalar/AS12XVW32N | D7: Klima | E7: Siemens
A8: AS12IXB32N | B8: Siemens Ev Tipi Klima İç Ünite, 12.000BTU, Siyah | C8: https://www.siemens-home.bsh-group.com/tr/tr/product/klimalar/AS12XXB32N | D8: Klima | E8: Siemens
A9: AS12OVW30N | B9: Siemens Ev Tipi Klima Dış Ünite, 12.000BTU, Beyaz | C9: https://www.siemens-home.bsh-group.com/tr/tr/product/klimalar/AS12XVW32N | D9: Klima | E9: Siemens
A10: AS12OVW32N | B10: Siemens Ev Tipi Klima Dış Ünite, 12.000BTU, Beyaz | C10: https://www.siemens-home.bsh-group.com/tr/tr/product/klimalar/AS12XVW32N | D10: Klima | E10: Siemens
A11: AS12OXB32N | B11: Siemens Ev Tipi Klima Dış Ünite, 12.000BTU, Beyaz | C11: https://www.siemens-home.bsh-group.com/tr/tr/product/klimalar/AS12XXB32N | D11: Klima | E11: Siemens
A12: AS18IVW30N | B12: Siemens Ev Tipi Klima İç Ünite, 18.000BTU, Beyaz | C12: https://www.siemens-home.bsh-group.com/tr/tr/product/klimalar/AS18XVW32N | D12: Klima | E12: Siemens
... A617: WT47XK8XTR | B617: iQ700 Isı Pompalı Kurutma Makinesi, 9kg, Beyaz | C617: https://www.siemens-home.bsh-group.com/tr/tr/product/prsiemensdryer/WT47XK8XTR | D617: Kurutma Makinesi | E617: Siemens
