Workbook
Name __DAT1: #REF!
Name __DAT10: #REF!
Name __DAT11: #REF!
Name __DAT2: #REF!
Name __DAT3: #REF!
Name __DAT4: #REF!
Name __DAT5: #REF!
Name __DAT6: #REF!
Name __DAT7: #REF!
Name __DAT8: #REF!
Name __DAT9: #REF!
Name _DAT1: #REF!
Name _DAT10: #REF!
Name _DAT11: #REF!
Name _DAT2: #REF!
Name _DAT3: #REF!
Name _DAT4: #REF!
Name _DAT5: #REF!
Name _DAT6: #REF!
Name _DAT7: #REF!
Name _DAT8: #REF!
Name _DAT9: #REF!
Name A: #REF!
Name ddd: #REF!
Name e: #REF!
Name Print_Area_MI: #REF!
Name Print_Area_MIe: #REF!
Name Query1: #REF!
Name Query11: #REF!
Name sss: #REF!
Name sssssss: #REF!
Name TEST0: #REF!
Name TEST1: #REF!
Name TEST122: #REF!
Name TEST2: #REF!
Name TEST33939: #REF!
Name TESTHKEY: #REF!
Name tt: #REF!
Name tttt: #REF!
Name xx: #REF!

Sheet Sayfa1
A1: STOK KODU | B1: AÇIKLAMA | C1: 21 EKİM HOROZ | D1: 21 EKİM studioLine HOROZ | E1: 16 EKİM YILDIZ DEPO | F1: CAM OFİS KAPALI KUTU | G1: CAM OFİS TEŞHİR | H1: STUDIO LINE CEPA | I1: ANKAMALL | J1: CEPA | K1: OPTIMUM | L1: ONE TOWER | M1: PANORA | N1: TOPLAM STOK | O1: 21 EKİM BEKLEYEN | P1: PRİM HARİÇ ÜRÜN | Q1: EKİM TOPTAN | R1: HAVALE FİYATI | S1: TEK ÇEKİM FİYATI | T1: TAKSİTLİ FİYATI 3/6 TAKSİT | U1: EKİM BİP | V1: 30.11.2026 montaj zorunlu PHASE OUT | W1: Hakedişler LİSTE FİYATINDAN SATILIRSA geçerli olacak | X1: ONLINE FİYATI | Y1: ÜRÜN NOTLARI
A2: KA93NVL30N | B2: =IFERROR(HYPERLINK(VLOOKUP(A2,ÜRÜNLER!A:C,3,FALSE),VLOOKUP(A2,ÜRÜNLER!A:B,2,FALSE)),"") -> iQ300 Gardırop Tipi Buzdolabı, 90.8cm, Inox | E2: 0 | F2: 0 | G2: 0 | H2: 0 | I2: 0 | J2: 1 | K2: 0 | L2: 1 | M2: 0 | N2: =SUM(C2:M2) -> 2 | Q2: devamı yok | R2: 80000 | S2: =R2*1.04 -> 83200 | T2: =R2*1.08 -> 86400 | W2: 1000
A3: KF96RSBEA | B3: =IFERROR(HYPERLINK(VLOOKUP(A3,ÜRÜNLER!A:C,3,FALSE),VLOOKUP(A3,ÜRÜNLER!A:B,2,FALSE)),"") -> iQ700 Gardırop Tipi Buzdolabı, Cam Kapı, Alkol Çekmeceli, 90.5cm, Siyah | C3: 15 | E3: 0 | F3: 1 | G3: 0 | H3: 0 | I3: 1 | J3: 1 | K3: 0 | L3: 0 | M3: 1 | N3: =SUM(C3:M3) -> 19 | Q3: 215784.17 | R3: 204994.96 | S3: =R3*1.04 -> 213194.76 | T3: =R3*1.08 -> 221394.56
A4: KF96NAXEA | B4: =IFERROR(HYPERLINK(VLOOKUP(A4,ÜRÜNLER!A:C,3,FALSE),VLOOKUP(A4,ÜRÜNLER!A:B,2,FALSE)),"") -> iQ300 Gardırop Tipi Buzdolabı, 90.5cm, BlackSteel | E4: 0 | F4: 0 | G4: 0 | H4: 0 | I4: 1 | J4: 0 | K4: 1 | L4: 2 | M4: 1 | N4: =SUM(C4:M4) -> 5 | O4: 16 | Q4: 134806.51 | R4: 134806.51 | S4: =R4*1.04 -> 140198.77 | T4: =R4*1.08 -> 145591.03 | U4: 37017.155
A5: KF96NVPEA | B5: =IFERROR(HYPERLINK(VLOOKUP(A5,ÜRÜNLER!A:C,3,FALSE),VLOOKUP(A5,ÜRÜNLER!A:B,2,FALSE)),"") -> iQ300 Gardırop Tipi Buzdolabı, 90.5cm, Inox | C5: 13 | E5: 0 | F5: 0 | G5: 0 | H5: 0 | I5: 1 | J5: 0 | K5: 0 | L5: 2 | M5: 0 | N5: =SUM(C5:M5) -> 16 | O5: 1 | Q5: 118087.27 | R5: 112182.91 | S5: =R5*1.04 -> 116670.22 | T5: =R5*1.08 -> 121157.54 | U5: 22366.339 | W5: 250
A6: KD43NNWE0N | B6: =IFERROR(HYPERLINK(VLOOKUP(A6,ÜRÜNLER!A:C,3,FALSE),VLOOKUP(A6,ÜRÜNLER!A:B,2,FALSE)),"") -> iQ100 Üstten Donduruculu Kulpsuz Buzdolabı, 70cm, Beyaz | E6: 0 | F6: 0 | G6: 0 | H6: 0 | I6: 0 | J6: 0 | K6: 0 | L6: 0 | M6: 0 | N6: =SUM(C6:M6) -> 0 | P6: PRİM HARİÇ | Q6: 35217.432 | R6: 35569.606 | S6: =R6*1.04 -> 36992.39 | T6: =R6*1.08 -> 38415.175
A7: KD55NNWE0N | B7: =IFERROR(HYPERLINK(VLOOKUP(A7,ÜRÜNLER!A:C,3,FALSE),VLOOKUP(A7,ÜRÜNLER!A:B,2,FALSE)),"") -> iQ300 Üstten Donduruculu Kulpsuz Buzdolabı, 70cm, Beyaz | E7: 0 | F7: 1 | G7: 0 | H7: 0 | I7: 0 | J7: 0 | K7: 0 | L7: 0 | M7: 0 | N7: =SUM(C7:M7) -> 1 | Q7: devamı yok | R7: 36986.142 | S7: =R7*1.04 -> 38465.587 | T7: =R7*1.08 -> 39945.033
A8: KD55NNWE1N | B8: =IFERROR(HYPERLINK(VLOOKUP(A8,ÜRÜNLER!A:C,3,FALSE),VLOOKUP(A8,ÜRÜNLER!A:B,2,FALSE)),"") -> iQ300 Üstten Donduruculu Kulpsuz Buzdolabı, 70cm, Beyaz (TF70 Kahvaltılık Çekmeceli) | C8: 10 | E8: 0 | F8: 0 | G8: 0 | H8: 0 | I8: 0 | J8: 0 | K8: 0 | L8: 0 | M8: 0 | N8: =SUM(C8:M8) -> 10 | P8: PRİM HARİÇ | Q8: 39558.14 | R8: 39558 | S8: =R8*1.04 -> 41140.32 | T8: =R8*1.08 -> 42722.64
A9: KD55NNLE0N | B9: =IFERROR(HYPERLINK(VLOOKUP(A9,ÜRÜNLER!A:C,3,FALSE),VLOOKUP(A9,ÜRÜNLER!A:B,2,FALSE)),"") -> iQ300 Üstten Donduruculu Kulpsuz Buzdolabı, 70cm, Inox Görünümlü | C9: 2 | E9: 0 | F9: 0 | G9: 0 | H9: 0 | I9: 0 | J9: 0 | K9: 0 | L9: 0 | M9: 0 | N9: =SUM(C9:M9) -> 2 | Q9: devamı yok | R9: 43670 | S9: =R9*1.04 -> 45416.8 | T9: =R9*1.08 -> 47163.6 | U9: 2879.6533
A10: KD55NNLE1N | B10: =IFERROR(HYPERLINK(VLOOKUP(A10,ÜRÜNLER!A:C,3,FALSE),VLOOKUP(A10,ÜRÜNLER!A:B,2,FALSE)),"") -> iQ300 Üstten Donduruculu Kulpsuz Buzdolabı, 70cm, Inox Görünümlü (TF70 Kahvaltılık Çekmeceli) | C10: 5 | E10: 0 | F10: 0 | G10: 0 | H10: 0 | I10: 0 | J10: 0 | K10: 0 | L10: 0 | M10: 0 | N10: =SUM(C10:M10) -> 5 | P10: PRİM HARİÇ | Q10: 42427.1 | R10: 42427 | S10: =R10*1.04 -> 44124.08 | T10: =R10*1.08 -> 45821.16
A11: KD56NXWF1N | B11: =IFERROR(HYPERLINK(VLOOKUP(A11,ÜRÜNLER!A:C,3,FALSE),VLOOKUP(A11,ÜRÜNLER!A:B,2,FALSE)),"") -> iQ300 Üstten Donduruculu Kulpsuz Buzdolabı, 70cm, Beyaz | E11: 0 | F11: 0 | G11: 0 | H11: 0 | I11: 0 | J11: 0 | K11: 0 | L11: 1 | M11: 0 | N11: =SUM(C11:M11) -> 1 | Q11: devamı yok | R11: 40000 | S11: =R11*1.04 -> 41600 | T11: =R11*1.08 -> 43200 | W11: 500
A12: KD76NAIE1N | B12: =IFERROR(HYPERLINK(VLOOKUP(A12,ÜRÜNLER!A:C,3,FALSE),VLOOKUP(A12,ÜRÜNLER!A:B,2,FALSE)),"") -> iQ500 Üstten Donduruculu Kulplu Buzdolabı, 75cm, Inox | C12: 11 | E12: 0 | F12: 0 | G12: 0 | H12: 0 | I12: 0 | J12: 0 | K12: 0 | L12: 0 | M12: 0 | N12: =SUM(C12:M12) -> 11 | Q12: 84535.625 | R12: 80308.843 | S12: =R12*1.04 -> 83521.197 | T12: =R12*1.08 -> 86733.551 | U12: 12012.369
A13: KD76NAWE1N | B13: =IFERROR(HYPERLINK(VLOOKUP(A13,ÜRÜNLER!A:C,3,FALSE),VLOOKUP(A13,ÜRÜNLER!A:B,2,FALSE)),"") -> iQ500 Üstten Donduruculu Kulplu Buzdolabı, 75cm, Beyaz | C13: 14 | E13: 0 | F13: 0 | G13: 0 | H13: 0 | I13: 0 | J13: 0 | K13: 0 | L13: 0 | M13: 0 | N13: =SUM(C13:M13) -> 14 | Q13: 62949.551 | R13: 59802.074 | S13: =R13*1.04 -> 62194.157 | T13: =R13*1.08 -> 64586.24
A14: KD76NXIE1N | B14: =IFERROR(HYPERLINK(VLOOKUP(A14,ÜRÜNLER!A:C,3,FALSE),VLOOKUP(A14,ÜRÜNLER!A:B,2,FALSE)),"") -> iQ500 Üstten Donduruculu Kulpsuz Buzdolabı, 75cm, Inox | C14: 11 | E14: 0 | F14: 0 | G14: 0 | H14: 0 | I14: 0 | J14: 0 | K14: 0 | L14: 0 | M14: 0 | N14: =SUM(C14:M14) -> 11 | Q14: 70136.481 | R14: 66629.657 | S14: =R14*1.04 -> 69294.843 | T14: =R14*1.08 -> 71960.029 | U14: 5101.5972
A15: KD76NXWE1N | B15: =IFERROR(HYPERLINK(VLOOKUP(A15,ÜRÜNLER!A:C,3,FALSE),VLOOKUP(A15,ÜRÜNLER!A:B,2,FALSE)),"") -> iQ300 Üstten Donduruculu, Kulpsuz Buzdolabı, 75cm, Beyaz | C15: 30 | E15: 0 | F15: 0 | G15: 0 | H15: 0 | I15: 1 | J15: 1 | K15: 0 | L15: 0 | M15: 1 | N15: =SUM(C15:M15) -> 33 | O15: 9 | Q15: 64328.533 | R15: 61112.107 | S15: =R15*1.04 -> 63556.591 | T15: =R15*1.08 -> 66001.075 | U15: 11177.371
A16: KD76NXWE0N | B16: =IFERROR(HYPERLINK(VLOOKUP(A16,ÜRÜNLER!A:C,3,FALSE),VLOOKUP(A16,ÜRÜNLER!A:B,2,FALSE)),"") -> iQ300 Üstten Donduruculu Kulpsuz Buzdolabı, 75cm, Beyaz | E16: 0 | F16: 0 | G16: 0 | H16: 0 | I16: 0 | J16: 0 | K16: 0 | L16: 1 | M16: 0 | N16: =SUM(C16:M16) -> 1 | Q16: devamı yok | R16: 55000 | S16: =R16*1.04 -> 57200 | T16: =R16*1.08 -> 59400 | W16: 500
A17: KD76NNWE0N | B17: =IFERROR(HYPERLINK(VLOOKUP(A17,ÜRÜNLER!A:C,3,FALSE),VLOOKUP(A17,ÜRÜNLER!A:B,2,FALSE)),"") -> iQ300 Üstten Donduruculu Kulpsuz Buzdolabı, 75cm, Beyaz | C17: 20 | E17: 0 | F17: 0 | G17: 0 | H17: 0 | I17: 0 | J17: 0 | K17: 0 | L17: 0 | M17: 0 | N17: =SUM(C17:M17) -> 20 | Q17: 56792.905 | R17: 56793 | S17: =R17*1.04 -> 59064.72 | T17: =R17*1.08 -> 61336.44 | U17: 5920.8122
A18: KD86NAID1N | B18: =IFERROR(HYPERLINK(VLOOKUP(A18,ÜRÜNLER!A:C,3,FALSE),VLOOKUP(A18,ÜRÜNLER!A:B,2,FALSE)),"") -> iQ500 Üstten Donduruculu Kulplu Buzdolabı, 86cm, Inox | C18: 8 | E18: 1 | F18: 0 | G18: 0 | H18: 0 | I18: 1 | J18: 1 | K18: 1 | L18: 0 | M18: 0 | N18: =SUM(C18:M18) -> 12 | Q18: 98053.757 | R18: 93151.069 | S18: =R18*1.04 -> 96877.112 | T18: =R18*1.08 -> 100603.16 | U18: 19751.432
A19: KD86NAWE1N | B19: =IFERROR(HYPERLINK(VLOOKUP(A19,ÜRÜNLER!A:C,3,FALSE),VLOOKUP(A19,ÜRÜNLER!A:B,2,FALSE)),"") -> iQ500 Üstten Donduruculu Kulplu Buzdolabı, 86cm, Beyaz | C19: 21 | E19: 0 | F19: 0 | G19: 0 | H19: 0 | I19: 0 | J19: 0 | K19: 0 | L19: 0 | M19: 0 | N19: =SUM(C19:M19) -> 21 | Q19: 85320.531 | R19: 81054.504 | S19: =R19*1.04 -> 84296.684 | T19: =R19*1.08 -> 87538.864 | U19: 12797.275
A20: KD86NHID1N | B20: =IFERROR(HYPERLINK(VLOOKUP(A20,ÜRÜNLER!A:C,3,FALSE),VLOOKUP(A20,ÜRÜNLER!A:B,2,FALSE)),"") -> iQ500 Üstten Donduruculu Kulplu Buzdolabı, 86cm, Inox | E20: 0 | F20: 0 | G20: 0 | H20: 0 | I20: 0 | J20: 0 | K20: 0 | L20: 1 | M20: 0 | N20: =SUM(C20:M20) -> 1 | Q20: devamı yok | R20: 55000 | S20: =R20*1.04 -> 57200 | T20: =R20*1.08 -> 59400 | W20: 500
A21: KG36NNLE0N | B21: =IFERROR(HYPERLINK(VLOOKUP(A21,ÜRÜNLER!A:C,3,FALSE),VLOOKUP(A21,ÜRÜNLER!A:B,2,FALSE)),"") -> iQ100 Alttan Donduruculu Kulpsuz Buzdolabı, 60cm, Inox | E21: 0 | F21: 0 | G21: 0 | H21: 0 | I21: 0 | J21: 0 | K21: 0 | L21: 0 | M21: 0 | N21: =SUM(C21:M21) -> 0 | Q21: devamı yok | R21: 40000 | S21: =R21*1.04 -> 41600 | T21: =R21*1.08 -> 43200 | W21: 500
A22: KG55NCIE0N | B22: =IFERROR(HYPERLINK(VLOOKUP(A22,ÜRÜNLER!A:C,3,FALSE),VLOOKUP(A22,ÜRÜNLER!A:B,2,FALSE)),"") -> iQ300 Alttan Donduruculu Kulpsuz Buzdolabı, 70cm, Inox | C22: 41 | E22: 4 | F22: 0 | G22: 0 | H22: 0 | I22: 1 | J22: 1 | K22: 0 | L22: 1 | M22: 1 | N22: =SUM(C22:M22) -> 49 | Q22: 65373.711 | R22: 62105.025 | S22: =R22*1.04 -> 64589.226 | T22: =R22*1.08 -> 67073.427 | U22: 15803.943
A23: KG55NCWE0N | B23: =IFERROR(HYPERLINK(VLOOKUP(A23,ÜRÜNLER!A:C,3,FALSE),VLOOKUP(A23,ÜRÜNLER!A:B,2,FALSE)),"") -> iQ300 Alttan Donduruculu Kulpsuz Buzdolabı, 70cm, Beyaz | C23: 70 | E23: 0 | F23: 0 | G23: 0 | H23: 0 | I23: 1 | J23: 0 | K23: 1 | L23: 2 | M23: 0 | N23: =SUM(C23:M23) -> 74 | Q23: 60461.405 | R23: 57438.335 | S23: =R23*1.04 -> 59735.868 | T23: =R23*1.08 -> 62033.401 | U23: 12845.126
A24: KG55NVIE0N | B24: =IFERROR(HYPERLINK(VLOOKUP(A24,ÜRÜNLER!A:C,3,FALSE),VLOOKUP(A24,ÜRÜNLER!A:B,2,FALSE)),"") -> iQ300 Alttan Donduruculu Kulpsuz Buzdolabı, 70cm, Inox | E24: 1 | F24: 0 | G24: 0 | H24: 0 | I24: 0 | J24: 0 | K24: 0 | L24: 1 | M24: 0 | N24: =SUM(C24:M24) -> 2 | Q24: devamı yok | R24: 55000 | S24: =R24*1.04 -> 57200 | T24: =R24*1.08 -> 59400 | U24: 6001.9872
A25: KG55NVWE0N | B25: =IFERROR(HYPERLINK(VLOOKUP(A25,ÜRÜNLER!A:C,3,FALSE),VLOOKUP(A25,ÜRÜNLER!A:B,2,FALSE)),"") -> iQ300 Alttan Donduruculu Kulpsuz Buzdolabı, 70cm, Beyaz | E25: 1 | F25: 0 | G25: 0 | H25: 0 | I25: 0 | J25: 0 | K25: 0 | L25: 1 | M25: 0 | N25: =SUM(C25:M25) -> 2 | Q25: devamı yok | R25: 44500 | S25: =R25*1.04 -> 46280 | T25: =R25*1.08 -> 48060 | U25: 2497.0134 | W25: 500
A26: KG56NCID0N | B26: =IFERROR(HYPERLINK(VLOOKUP(A26,ÜRÜNLER!A:C,3,FALSE),VLOOKUP(A26,ÜRÜNLER!A:B,2,FALSE)),"") -> iQ300 Alttan Donduruculu Kulpsuz Buzdolabı, 70cm, Inox (Wi-Fi) | C26: 2 | E26: 0 | F26: 0 | G26: 0 | H26: 0 | I26: 0 | J26: 0 | K26: 0 | L26: 0 | M26: 0 | N26: =SUM(C26:M26) -> 2 | Q26: 60254.001 | R26: 57241.301 | S26: =R26*1.04 -> 59530.953 | T26: =R26*1.08 -> 61820.605 | U26: 3277.2569
A27: KG56NCWD0N | B27: =IFERROR(HYPERLINK(VLOOKUP(A27,ÜRÜNLER!A:C,3,FALSE),VLOOKUP(A27,ÜRÜNLER!A:B,2,FALSE)),"") -> iQ300 Alttan Donduruculu Kulpsuz Buzdolabı, 70cm, Beyaz (Wi-Fi) | C27: 1 | E27: 0 | F27: 0 | G27: 0 | H27: 0 | I27: 0 | J27: 0 | K27: 0 | L27: 0 | M27: 0 | N27: =SUM(C27:M27) -> 1 | Q27: 55360.41 | R27: 52592.39 | S27: =R27*1.04 -> 54696.085 | T27: =R27*1.08 -> 56799.781
A28: KG56NCXD0N | B28: =IFERROR(HYPERLINK(VLOOKUP(A28,ÜRÜNLER!A:C,3,FALSE),VLOOKUP(A28,ÜRÜNLER!A:B,2,FALSE)),"") -> iQ300 Alttan Donduruculu Kulpsuz Buzdolabı, 70cm, Black Inox (Wi-Fi) | E28: 0 | F28: 0 | G28: 0 | H28: 0 | I28: 0 | J28: 0 | K28: 0 | L28: 0 | M28: 0 | N28: =SUM(C28:M28) -> 0 | Q28: 63899.365 | R28: 60704.397 | S28: =R28*1.04 -> 63132.573 | T28: =R28*1.08 -> 65560.749 | U28: 3992.3887
A29: KG56NLBE0N | B29: =IFERROR(HYPERLINK(VLOOKUP(A29,ÜRÜNLER!A:C,3,FALSE),VLOOKUP(A29,ÜRÜNLER!A:B,2,FALSE)),"") -> iQ500 Alttan Donduruculu Kulpsuz Buzdolabı, 70cm, Parlak Siyah | C29: 4 | E29: 0 | F29: 0 | G29: 0 | H29: 0 | I29: 2 | J29: 1 | K29: 1 | L29: 0 | M29: 2 | N29: =SUM(C29:M29) -> 10 | Q29: 65451.17 | R29: 62178.612 | S29: =R29*1.04 -> 64665.756 | T29: =R29*1.08 -> 67152.901
A30: KG56NNWD0N | B30: =IFERROR(HYPERLINK(VLOOKUP(A30,ÜRÜNLER!A:C,3,FALSE),VLOOKUP(A30,ÜRÜNLER!A:B,2,FALSE)),"") -> iQ100 Alttan Donduruculu Kulpsuz Buzdolabı, 70cm, Beyaz (Wi-Fi) | C30: 41 | E30: 0 | F30: 0 | G30: 0 | H30: 0 | I30: 1 | J30: 0 | K30: 0 | L30: 0 | M30: 0 | N30: =SUM(C30:M30) -> 42 | P30: PRİM HARİÇ | Q30: 46178.679 | R30: 43869.745 | S30: =R30*1.04 -> 45624.535 | T30: =R30*1.08 -> 47379.324
A31: KG56NQWF0N | B31: =IFERROR(HYPERLINK(VLOOKUP(A31,ÜRÜNLER!A:C,3,FALSE),VLOOKUP(A31,ÜRÜNLER!A:B,2,FALSE)),"") -> iQ500 Alttan Donduruculu Kulpsuz Buzdolabı, 70cm, Seramik Desen | E31: 0 | F31: 0 | G31: 0 | H31: 0 | I31: 0 | J31: 1 | K31: 0 | L31: 0 | M31: 0 | N31: =SUM(C31:M31) -> 1 | Q31: devamı yok | R31: 48000 | S31: =R31*1.04 -> 49920 | T31: =R31*1.08 -> 51840 | W31: 500
A32: KG56NTEE0N | B32: =IFERROR(HYPERLINK(VLOOKUP(A32,ÜRÜNLER!A:C,3,FALSE),VLOOKUP(A32,ÜRÜNLER!A:B,2,FALSE)),"") -> iQ500 Alttan Donduruculu Kulpsuz Buzdolabı, 70cm, Mat Siyah | E32: 0 | F32: 0 | G32: 1 | H32: 0 | I32: 0 | J32: 0 | K32: 0 | L32: 0 | M32: 0 | N32: =SUM(C32:M32) -> 1 | Q32: devamı yok | R32: 48000 | S32: =R32*1.04 -> 49920 | T32: =R32*1.08 -> 51840 | W32: 500
A33: KG56NTWE0N | B33: =IFERROR(HYPERLINK(VLOOKUP(A33,ÜRÜNLER!A:C,3,FALSE),VLOOKUP(A33,ÜRÜNLER!A:B,2,FALSE)),"") -> iQ500 Alttan Donduruculu Kulpsuz Buzdolabı, 70cm, Seramik Desen | E33: 0 | F33: 0 | G33: 0 | H33: 0 | I33: 0 | J33: 0 | K33: 0 | L33: 1 | M33: 0 | N33: =SUM(C33:M33) -> 1 | Q33: devamı yok | R33: 48000 | S33: =R33*1.04 -> 49920 | T33: =R33*1.08 -> 51840 | W33: 500
A34: KG56NVPD0N | B34: =IFERROR(HYPERLINK(VLOOKUP(A34,ÜRÜNLER!A:C,3,FALSE),VLOOKUP(A34,ÜRÜNLER!A:B,2,FALSE)),"") -> iQ300 Alttan Donduruculu Kulpsuz Buzdolabı, 70cm, Inox (Wi-Fi) | C34: 41 | E34: 0 | F34: 0 | G34: 0 | H34: 0 | I34: 1 | J34: 0 | K34: 0 | L34: 0 | M34: 0 | N34: =SUM(C34:M34) -> 42 | Q34: 52906.163 | R34: 50260.855 | S34: =R34*1.04 -> 52271.289 | T34: =R34*1.08 -> 54281.723
A35: KG56NVWD0N | B35: =IFERROR(HYPERLINK(VLOOKUP(A35,ÜRÜNLER!A:C,3,FALSE),VLOOKUP(A35,ÜRÜNLER!A:B,2,FALSE)),"") -> iQ300 Alttan Donduruculu Kulpsuz Buzdolabı, 70cm, Beyaz (Wi-Fi) | C35: 31 | E35: 0 | F35: 0 | G35: 0 | H35: 0 | I35: 0 | J35: 0 | K35: 0 | L35: 0 | M35: 0 | N35: =SUM(C35:M35) -> 31 | O35: 20 | Q35: 50483.32 | R35: 47959.154 | S35: =R35*1.04 -> 49877.52 | T35: =R35*1.08 -> 51795.886
A36: KG76APIE0N | B36: =IFERROR(HYPERLINK(VLOOKUP(A36,ÜRÜNLER!A:C,3,FALSE),VLOOKUP(A36,ÜRÜNLER!A:B,2,FALSE)),"") -> iQ700 Alttan Donduruculu Kulplu Buzdolabı, 75cm, Inox | C36: 13 | E36: 0 | F36: 0 | G36: 0 | H36: 0 | I36: 0 | J36: 0 | K36: 0 | L36: 0 | M36: 0 | N36: =SUM(C36:M36) -> 13 | Q36: 84646.164 | R36: 80413.856 | S36: =R36*1.04 -> 83630.41 | T36: =R36*1.08 -> 86846.965 | U36: 6343.8389
A37: KG76NCIE0N | B37: =IFERROR(HYPERLINK(VLOOKUP(A37,ÜRÜNLER!A:C,3,FALSE),VLOOKUP(A37,ÜRÜNLER!A:B,2,FALSE)),"") -> iQ500 Alttan Donduruculu Kulplu Buzdolabı, 75cm, Inox | C37: 2 | E37: 0 | F37: 1 | G37: 0 | H37: 0 | I37: 1 | J37: 1 | K37: 1 | L37: 3 | M37: 1 | N37: =SUM(C37:M37) -> 10 | Q37: 89337.569 | R37: 84870.691 | S37: =R37*1.04 -> 88265.519 | T37: =R37*1.08 -> 91660.346 | U37: 19093.383
A38: KG76NCWE0N | B38: =IFERROR(HYPERLINK(VLOOKUP(A38,ÜRÜNLER!A:C,3,FALSE),VLOOKUP(A38,ÜRÜNLER!A:B,2,FALSE)),"") -> iQ500 Alttan Donduruculu Kulplu Buzdolabı, 75cm, Beyaz | C38: 33 | E38: 0 | F38: 0 | G38: 0 | H38: 0 | I38: 1 | J38: 0 | K38: 0 | L38: 1 | M38: 0 | N38: =SUM(C38:M38) -> 35 | Q38: 80897.296 | R38: 76852.431 | S38: =R38*1.04 -> 79926.528 | T38: =R38*1.08 -> 83000.626 | U38: 12199.622
A39: KG76NCXE0N | B39: =IFERROR(HYPERLINK(VLOOKUP(A39,ÜRÜNLER!A:C,3,FALSE),VLOOKUP(A39,ÜRÜNLER!A:B,2,FALSE)),"") -> iQ500 Alttan Donduruculu Kulpsuz Buzdolabı, 75cm, darkSteel | C39: 108 | E39: 0 | F39: 0 | G39: 0 | H39: 0 | I39: 1 | J39: 1 | K39: 1 | L39: 0 | M39: 1 | N39: =SUM(C39:M39) -> 112 | Q39: 99433.9 | R39: 94462.205 | S39: =R39*1.04 -> 98240.693 | T39: =R39*1.08 -> 102019.18 | U39: 23492.04
A40: KG76NVIE0N | B40: =IFERROR(HYPERLINK(VLOOKUP(A40,ÜRÜNLER!A:C,3,FALSE),VLOOKUP(A40,ÜRÜNLER!A:B,2,FALSE)),"") -> iQ300 Alttan Donduruculu Kulpsuz Buzdolabı, 75cm, Inox | C40: 29 | E40: 0 | F40: 0 | G40: 2 | H40: 0 | I40: 1 | J40: 0 | K40: 0 | L40: 2 | M40: 0 | N40: =SUM(C40:M40) -> 34 | Q40: 80743.426 | R40: 76706.255 | S40: =R40*1.04 -> 79774.505 | T40: =R40*1.08 -> 82842.755 | U40: 13103.891
...

Sheet HESAPLAYICI
A1: STOK KODU | B1: AÇIKLAMA | C1: ADET | D1: =Sayfa1!Q1 -> EKİM TOPTAN | E1: =Sayfa1!R1 -> HAVALE FİYATI | F1: =Sayfa1!S1 -> TEK ÇEKİM FİYATI | G1: =Sayfa1!T1 -> TAKSİTLİ FİYATI 3/6 TAKSİT | H1: =Sayfa1!U1 -> EKİM BİP | I1: =Sayfa1!V1 -> 30.11.2026 montaj zorunlu PHASE OUT | J1: Toplam Bundle İndirim Tutarını Aşağıya Yaz
A2: HJ852GYW0T | B2: =IF($A2="","",VLOOKUP($A2,Sayfa1!A:U,2,FALSE)) -> iQ500 Ankastre Fırın, 2 Teleskopik Ray, Komple Kendini Temizler, Beyaz | C2: 1 | D2: =IF($A2="","",VLOOKUP($A2,Sayfa1!A:U,17,FALSE)) -> 37217.365 | E2: =IF($A2="","",VLOOKUP($A2,Sayfa1!A:U,18,FALSE)*C2) -> 35356.497 | F2: =IF($A2="","",VLOOKUP($A2,Sayfa1!A:U,19,FALSE)*C2) -> 36770.757 | G2: =IF($A2="","",VLOOKUP($A2,Sayfa1!A:U,20,FALSE)*C2) -> 38185.017 | H2: =IFERROR(VLOOKUP(A2,Sayfa1!A:U,21,FALSE)*VALUE(C2),"") | I2: =IF($A2="","",VLOOKUP($A2,Sayfa1!A:V,22,FALSE)) | J2: 7600
A3: EO7C2PP30L | B3: =IF($A3="","",VLOOKUP($A3,Sayfa1!A:U,2,FALSE)) -> iQ300 Gazlı Ocak, 67cm, Sert Cam, Beyaz | C3: 1 | D3: =IF($A3="","",VLOOKUP($A3,Sayfa1!A:U,17,FALSE)) -> 17392.82 | E3: =IF($A3="","",VLOOKUP($A3,Sayfa1!A:U,18,FALSE)*C3) -> 16643.847 | F3: =IF($A3="","",VLOOKUP($A3,Sayfa1!A:U,19,FALSE)*C3) -> 17309.601 | G3: =IF($A3="","",VLOOKUP($A3,Sayfa1!A:U,20,FALSE)*C3) -> 17975.355 | H3: =IFERROR(VLOOKUP(A3,Sayfa1!A:U,21,FALSE)*VALUE(C3),"") | I3: =IF($A3="","",VLOOKUP($A3,Sayfa1!A:V,22,FALSE))
A4: LC67KPJ20T | B4: =IF($A4="","",VLOOKUP($A4,Sayfa1!A:U,2,FALSE)) -> iQ500 Eğimli Davlumbaz, 60cm, 510m3, Beyaz Cam | C4: 1 | D4: =IF($A4="","",VLOOKUP($A4,Sayfa1!A:U,17,FALSE)) -> 23225.183 | E4: =IF($A4="","",VLOOKUP($A4,Sayfa1!A:U,18,FALSE)*C4) -> 24386.442 | F4: =IF($A4="","",VLOOKUP($A4,Sayfa1!A:U,19,FALSE)*C4) -> 25361.9 | G4: =IF($A4="","",VLOOKUP($A4,Sayfa1!A:U,20,FALSE)*C4) -> 26337.358 | H4: =IFERROR(VLOOKUP(A4,Sayfa1!A:U,21,FALSE)*VALUE(C4),"") | I4: =IF($A4="","",VLOOKUP($A4,Sayfa1!A:V,22,FALSE))
B5: =IF($A5="","",VLOOKUP($A5,Sayfa1!A:U,2,FALSE)) | C5: 1 | D5: =IF($A5="","",VLOOKUP($A5,Sayfa1!A:U,17,FALSE)) | E5: =IF($A5="","",VLOOKUP($A5,Sayfa1!A:U,18,FALSE)*C5) | F5: =IF($A5="","",VLOOKUP($A5,Sayfa1!A:U,19,FALSE)*C5) | G5: =IF($A5="","",VLOOKUP($A5,Sayfa1!A:U,20,FALSE)*C5) | H5: =IFERROR(VLOOKUP(A5,Sayfa1!A:U,21,FALSE)*VALUE(C5),"") | I5: =IF($A5="","",VLOOKUP($A5,Sayfa1!A:V,22,FALSE))
B6: =IF($A6="","",VLOOKUP($A6,Sayfa1!A:U,2,FALSE)) | C6: 1 | D6: =IF($A6="","",VLOOKUP($A6,Sayfa1!A:U,17,FALSE)) | E6: =IF($A6="","",VLOOKUP($A6,Sayfa1!A:U,18,FALSE)*C6) | F6: =IF($A6="","",VLOOKUP($A6,Sayfa1!A:U,19,FALSE)*C6) | G6: =IF($A6="","",VLOOKUP($A6,Sayfa1!A:U,20,FALSE)*C6) | H6: =IFERROR(VLOOKUP(A6,Sayfa1!A:U,21,FALSE)*VALUE(C6),"") | I6: =IF($A6="","",VLOOKUP($A6,Sayfa1!A:V,22,FALSE))
B7: =IF($A7="","",VLOOKUP($A7,Sayfa1!A:U,2,FALSE)) | C7: 1 | D7: =IF($A7="","",VLOOKUP($A7,Sayfa1!A:U,17,FALSE)) | E7: =IF($A7="","",VLOOKUP($A7,Sayfa1!A:U,18,FALSE)*C7) | F7: =IF($A7="","",VLOOKUP($A7,Sayfa1!A:U,19,FALSE)*C7) | G7: =IF($A7="","",VLOOKUP($A7,Sayfa1!A:U,20,FALSE)*C7) | H7: =IFERROR(VLOOKUP(A7,Sayfa1!A:U,21,FALSE)*VALUE(C7),"") | I7: =IF($A7="","",VLOOKUP($A7,Sayfa1!A:V,22,FALSE))
B8: =IF($A8="","",VLOOKUP($A8,Sayfa1!A:U,2,FALSE)) | C8: 1 | D8: =IF($A8="","",VLOOKUP($A8,Sayfa1!A:U,17,FALSE)) | E8: =IF($A8="","",VLOOKUP($A8,Sayfa1!A:U,18,FALSE)*C8) | F8: =IF($A8="","",VLOOKUP($A8,Sayfa1!A:U,19,FALSE)*C8) | G8: =IF($A8="","",VLOOKUP($A8,Sayfa1!A:U,20,FALSE)*C8) | H8: =IFERROR(VLOOKUP(A8,Sayfa1!A:U,21,FALSE)*VALUE(C8),"") | I8: =IF($A8="","",VLOOKUP($A8,Sayfa1!A:V,22,FALSE))
B9: =IF($A9="","",VLOOKUP($A9,Sayfa1!A:U,2,FALSE)) | C9: 1 | D9: =IF($A9="","",VLOOKUP($A9,Sayfa1!A:U,17,FALSE)) | E9: =IF($A9="","",VLOOKUP($A9,Sayfa1!A:U,18,FALSE)*C9) | F9: =IF($A9="","",VLOOKUP($A9,Sayfa1!A:U,19,FALSE)*C9) | G9: =IF($A9="","",VLOOKUP($A9,Sayfa1!A:U,20,FALSE)*C9) | H9: =IFERROR(VLOOKUP(A9,Sayfa1!A:U,21,FALSE)*VALUE(C9),"") | I9: =IF($A9="","",VLOOKUP($A9,Sayfa1!A:V,22,FALSE))
B10: =IF($A10="","",VLOOKUP($A10,Sayfa1!A:U,2,FALSE)) | C10: 1 | D10: =IF($A10="","",VLOOKUP($A10,Sayfa1!A:U,17,FALSE)) | E10: =IF($A10="","",VLOOKUP($A10,Sayfa1!A:U,18,FALSE)*C10) | F10: =IF($A10="","",VLOOKUP($A10,Sayfa1!A:U,19,FALSE)*C10) | G10: =IF($A10="","",VLOOKUP($A10,Sayfa1!A:U,20,FALSE)*C10) | H10: =IFERROR(VLOOKUP(A10,Sayfa1!A:U,21,FALSE)*VALUE(C10),"") | I10: =IF($A10="","",VLOOKUP($A10,Sayfa1!A:V,22,FALSE))
B11: =IF($A11="","",VLOOKUP($A11,Sayfa1!A:U,2,FALSE)) | C11: 1 | D11: =IF($A11="","",VLOOKUP($A11,Sayfa1!A:U,17,FALSE)) | E11: =IF($A11="","",VLOOKUP($A11,Sayfa1!A:U,18,FALSE)*C11) | F11: =IF($A11="","",VLOOKUP($A11,Sayfa1!A:U,19,FALSE)*C11) | G11: =IF($A11="","",VLOOKUP($A11,Sayfa1!A:U,20,FALSE)*C11) | H11: =IFERROR(VLOOKUP(A11,Sayfa1!A:U,21,FALSE)*VALUE(C11),"") | I11: =IF($A11="","",VLOOKUP($A11,Sayfa1!A:V,22,FALSE))
B12: =IF($A12="","",VLOOKUP($A12,Sayfa1!A:U,2,FALSE)) | C12: 1 | D12: =IF($A12="","",VLOOKUP($A12,Sayfa1!A:U,17,FALSE)) | E12: =IF($A12="","",VLOOKUP($A12,Sayfa1!A:U,18,FALSE)*C12) | F12: =IF($A12="","",VLOOKUP($A12,Sayfa1!A:U,19,FALSE)*C12) | G12: =IF($A12="","",VLOOKUP($A12,Sayfa1!A:U,20,FALSE)*C12) | H12: =IFERROR(VLOOKUP(A12,Sayfa1!A:U,21,FALSE)*VALUE(C12),"") | I12: =IF($A12="","",VLOOKUP($A12,Sayfa1!A:V,22,FALSE))
A13: Toplam Satış Fiyatı | E13: =SUM(E2:E12) -> 76386.786 | F13: =SUM(F2:F12) -> 79442.258 | G13: =SUM(G2:G12) -> 82497.729
A14: BİP İndirimi | E14: =SUM(H:H)*-1 -> 0 | F14: =SUM(H:H)*-1 -> 0 | G14: =SUM(H:H)*-1 -> 0
A15: PhaseOut İndirimi | E15: =SUM(I:I)*-1 -> 0 | F15: =SUM(I:I)*-1 -> 0 | G15: =SUM(I:I)*-1 -> 0
A16: Toplam Bundle İndirimi | E16: =J2*-1 -> -7600 | F16: =J2*-1 -> -7600 | G16: =J2*-1 -> -7600
A17: Satılabilir Minimum Fiyat | E17: =SUM(E13:E16) -> 68786.786 | F17: =SUM(F13:F16) -> 71842.258 | G17: =SUM(G13:G16) -> 74897.729

Sheet Bundle Kampanya
C3: 2'li LDA alımında perakende de 5.000 TL İndirim! | D3: 2’li LDA alımında perakende de 5.000 ₺ indirim uygulanır. “diğer kampanyalar ile birleşemez” 4.000 ₺ kdv dahil fiyat farkı hak edişi ödenecektir. (Buzdolabı-Çamaşır-Bulaşık-Kurutma-Derin Dondurucu) (XL-XXL Buzdolapları hariç) | I3: Seçili Ankastre Set Alımına perakende de 5.000 TL İndirim! | J3: Geçerli Ankastre Fırınlar
J5: HB012FBH1T, HB012FBB1T, HB012FBW1T + (phase out iQ300 ve iQ500 segment modeller) Ankastre fırınlarda geçerlidir.
J9: Uygulama koşulları : Seçili ankastre fırınlar ile set (fırın+ocak+dav.) set alana perakende de 5.000 ₺ indirim uygulanır. Diğer fırınlarda geçerli değildir. KDV dahil 3.700 ₺ hak ediş ödenir. Giriş setlerde( HB011* ve giriş segment muadili fırın modelleri, EB6C5PK80O - EB6C5PB82O ocak, LC64PCC20T - LC64PCC50T - LC64PCC60T davlumbaz modelleri) geçerli değildir.
C13: Çamaşır + Kurutma alımında perakende de 10.000 TL İndirim! | D13: Çamaşır ile Kurutma birlikte alımında perakende de 10.000 ₺ indirim uygulanır.“diğer kampanyalar ile birleşemez” 8.000 ₺ kdv dahil fiyat farkı hak edişi ödenecektir. (Çamaşır + Kurutma)
I17: Seçili Fırınlarla Ankastre set alana perakende de 10.000 TL indirim! | J17: Geçerli Ankastre Setler
J19: HB557JEB6T, HB734G1B1, HB776G1B1, HB778G3B1, HR776G3B1, HS736G1B2, VB558C0S0, CM724G1B1, HJ852GYB0T, HJ852GYN0T, HJ852GYW0T, HU736AEN0T, HU736AEA0T, HU736AEV0T, HU736AEG0T, HR232GEB3, HU717ABN0T, HU717ABA0T, HU717ABV0T, CD714GXB1
C23: 150.000 TL ve üzeri Beyaz Eşya alımlarında TE651209RW kahve makinesi perakende de 50% indirimli! | D23: 150.000 TL ve üzeri beyaz eşya alımlarında TE651209RW kahve makinesi perakende de 50% (20.000 TL) indirim uygulanır. Diğer FAEM'lerde aynı tutarda indirim uygulanır. 5.000₺ kdv dahil fiyat farkı hak edişi ödenecektir . (150.000 TL ve üzeri sepet tutarında Buzdolabı-Çamaşır-Bulaşık-Kurutma-Derin Dondurucu ürün grupları dahildir.) | J23: Uygulama koşulları : Seçili ankastre fırınlar ile set (fırın+ocak+dav.) set alana perakende de 10.000 ₺ indirim uygulanır. KDV dahil 7.600 ₺ hak ediş ödenir. Giriş setlerde( HB011* ve giriş segment muadili fırın modelleri, EB6C5PK80O - EB6C5PB82O ocak, LC64PCC20T - LC64PCC50T - LC64PCC60T davlumbaz modelleri) geçerli değildir.

Sheet ÜRÜNLER
A1: Ürün No | B1: Ürün Adı | C1: Ürün Linki | D1: Ürün Grubu | E1: Marka
A2: 50PUS8009/62 | B2: Philips 50" 4K Ambilight LED TV (Titan OS) (50PUS8009/62) | C2: https://www.philips.com.tr/c-p/50PUS8009_62/led-50pus8009-4k-ambilight-tv | D2: Televizyon | E2: Philips
A3: 55PUS8349/62 | B3: Philips 55" 4K Ambilight LED TV (Titan OS) (55PUS8349/62) | C3: https://www.philips.com.tr/c-p/55PUS8349_62/led-55pus8349-4k-ambilight-tv | D3: Televizyon | E3: Philips
A4: AS09IVW32N | B4: Siemens Ev Tipi Klima İç Ünite, 9.000BTU, Beyaz | C4: https://www.siemens-home.bsh-group.com/tr/tr/product/klimalar/AS09XVW32N | D4: Klima | E4: Siemens
A5: AS09OVW32N | B5: Siemens Ev Tipi Klima Dış Ünite, 9.000BTU, Beyaz | C5: https://www.siemens-home.bsh-group.com/tr/tr/product/klimalar/AS09XVW32N | D5: Klima | E5: Siemens
A6: AS12IVW30N | B6: Siemens Ev Tipi Klima İç Ünite, 12.000BTU, Beyaz | C6: https://www.siemens-home.bsh-group.com/tr/tr/product/klimalar/AS12XVW32N | D6: Klima | E6: Siemens
A7: AS12IVW32N | B7: Siemens Ev Tipi Klima İç Ünite, 12.000BTU, Beyaz | C7: https://www.siemens-home.bsh-group.com/tr/tr/product/klimalar/AS12XVW32N | D7: Klima | E7: Siemens
A8: AS12IXB32N | B8: Siemens Ev Tipi Klima İç Ünite, 12.000BTU, Siyah | C8: https://www.siemens-home.bsh-group.com/tr/tr/product/klimalar/AS12XXB32N | D8: Klima | E8: Siemens
A9: AS12OVW30N | B9: Siemens Ev Tipi Klima Dış Ünite, 12.000BTU, Beyaz | C9: https://www.siemens-home.bsh-group.com/tr/tr/product/klimalar/AS12XVW32N | D9: Klima | E9: Siemens
A10: AS12OVW32N | B10: Siemens Ev Tipi Klima Dış Ünite, 12.000BTU, Beyaz | C10: https://www.siemens-home.bsh-group.com/tr/tr/product/klimalar/AS12XVW32N | D10: Klima | E10: Siemens
A11: AS12OXB32N | B11: Siemens Ev Tipi Klima Dış Ünite, 12.000BTU, Beyaz | C11: https://www.siemens-home.bsh-group.com/tr/tr/product/klimalar/AS12XXB32N | D11: Klima | E11: Siemens
A12: AS18IVW30N | B12: Siemens Ev Tipi Klima İç Ünite, 18.000BTU, Beyaz | C12: https://www.siemens-home.bsh-group.com/tr/tr/product/klimalar/AS18XVW32N | D12: Klima | E12: Siemens
... A633: EP6A2PI40O | B633: iQ500 Gazlı Ocak, 60cm, Sert Cam, Beyaz, Döküm | C633: https://www.siemens-home.bsh-group.com/tr/tr/product/pisirme-grubu/ocaklar/gazli-ocaklar/EP6A2PI40O | D633: Ocak | E633: Siemens
A634: TP605EM3 | B634: EQ600 iAroma Tam Otomatik Kahve Makinesi, Siyah/Inox | D634: Kahve Makinesi | E634: Siemens
A635: TP607ET5 | B635: EQ600 iAroma Tam Otomatik Kahve Makinesi, Siyah/Dark Inox | C635: https://www.siemens-home.bsh-group.com/tr/tr/product/kahve-makineleri/tam-otomatik-kahve-makineleri/coffeemachinesautomatedfreestandingeq600/TP607ET5 | D635: Kahve Makinesi | E635: Siemens
A636: TP601E01 | B636: EQ600 iAroma Tam Otomatik Kahve Makinesi, Sabah Sisi Grisi | C636: https://www.siemens-home.bsh-group.com/tr/tr/product/kahve-makineleri/tam-otomatik-kahve-makineleri/coffeemachinesautomatedfreestandingeq600/TP601E01 | D636: Kahve Makinesi | E636: Siemens
A637: TP551E19 | B637: EQ500 iAroma Tam Otomatik Kahve Makinesi, Piano Black | D637: Kahve Makinesi | E637: Siemens
A638: TP553E05 | B638: EQ500 iAroma Tam Otomatik Kahve Makinesi, Piano Black | D638: Kahve Makinesi | E638: Siemens
A639: KD55NNWE1N | B639: iQ300 Üstten Donduruculu Kulpsuz Buzdolabı, 70cm, Beyaz (TF70 Kahvaltılık Çekmeceli) | C639: https://www.siemens-home.bsh-group.com/tr/tr/product/buzdolaplari-ve-derin-dondurucular/solo-buzdolaplari-ve-derin-dondurucular/ustten-donduruculu-solo-buzdolaplari/KD55NNWE1N | D639: Buzdolabı | E639: Siemens
A640: KD55NNLE1N | B640: iQ300 Üstten Donduruculu Kulpsuz Buzdolabı, 70cm, Inox Görünümlü (TF70 Kahvaltılık Çekmeceli) | C640: https://www.siemens-home.bsh-group.com/tr/tr/product/buzdolaplari-ve-derin-dondurucular/solo-buzdolaplari-ve-derin-dondurucular/ustten-donduruculu-solo-buzdolaplari/KD55NNLE1N | D640: Buzdolabı | E640: Siemens
A641: EP6A9HB20 | B641: iQ500 Gazlı Ocak, 60cm, Sert Cam, Antrasit Gri, Döküm, Wok | C641: https://www.siemens-home.bsh-group.com/tr/tr/product/kampanyalar/ankastre-set-indirim/ocaklar/EP6A9HB20 | D641: Ocak | E641: Siemens
A642: LC66GCD50T | B642: iQ300 Düz Davlumbaz, 60cm, 620m3, Cam Dekor Inox | C642: https://www.siemens-home.bsh-group.com/tr/tr/product/LC66GCD50T | D642: Davlumbaz/Aspiratör | E642: Siemens
A643: WT7WH460TR | B643: iQ500 Isı Pompalı Kurutma Makinesi, 9kg, Beyaz | C643: https://www.siemens-home.bsh-group.com/tr/tr/product/camasir-ve-kurutma-makineleri/WT7WH460TR | D643: Kurutma Makinesi | E643: Siemens
A644: KG56NUWF0N | B644: iQ300 Alttan Donduruculu Kulpsuz Buzdolabı, 70cm, Beyaz | C644: https://www.siemens-home.bsh-group.com/tr/tr/product/prsiemensfridge/KG56NUWF0N | D644: Buzdolabı | E644: Siemens
A645: HF12G240 | B645: iQ500 Ankastre Mikrodalga, Izgaralı, Beyaz | C645: https://www.siemens-home.bsh-group.com/tr/tr/product/HF12G240 | D645: Mikrodalga | E645: Siemens
A646: EO7C2HO12O | B646: iQ300 Gazlı Ocak, 67cm, Sert Cam, Beyaz, Wok | C646: https://www.siemens-home.bsh-group.com/tr/tr/product/pisirme-grubu/ocaklar/gazli-ocaklar/EO7C2HO12O | D646: Ocak | E646: Siemens
A647: KG56NVIF0N | B647: iQ300 Alttan Donduruculu Kulpsuz Buzdolabı, 70cm, Inox | C647: https://www.siemens-home.bsh-group.com/tr/tr/product/prsiemensfridge15/KG56NVIF0N | D647: Buzdolabı | E647: Siemens
A648: EO0C6PO12O | B648: iQ300 Gazlı Ocak, 67cm, Sert Cam, Siyah | C648: https://www.siemens-home.bsh-group.com/tr/tr/product/EO0C6PO12O | D648: Ocak | E648: Siemens
A649: EN6B2PO10O | B649: iQ300 Gazlı Ocak, 67cm, Sert Cam, Beyaz | C649: https://www.siemens-home.bsh-group.com/tr/tr/product/EN6B2PO10O | D649: Ocak | E649: Siemens
A650: SN23EW63MT | B650: iQ300 Solo Bulaşık Makinesi, autoOpen dry, Üstten Sepetli, Beyaz | C650: https://www.siemens-home.bsh-group.com/tr/tr/product/bulasik-makineleri/solo-bulasik-makineleri/tam-ebatli-bulasik-makineleri-60cm/SN23EW63MT | D650: Bulaşık Makinesi | E650: Siemens
... A656: 65PUS8349/62 | B656: Philips 65" 4K Ambilight LED TV (Titan OS) (50PUS8349/62) | C656: https://www.epey.com/televizyon/philips-65pus8349.html | D656: Televizyon | E656: Siemens
