Workbook

Sheet Sayfa1
A1: STOK KODU | B1: AÇIKLAMA | C1: 16 MAYIS HOROZ | D1: 4 MAYIS Studioline HOROZ | E1: 25 NİSAN YILDIZ DEPO | F1: CAM OFİS | G1: İNTERNET DEPO | H1: STUDIO LINE CEPA | I1: ANKAMALL | J1: CEPA | K1: ONE TOWER | L1: OPTİMUM | M1: PANORA | N1: TOPLAM STOK | O1: 11 MAYIS BEKLEYEN | P1: AÇIĞA SATIŞ 29/04 | Q1: PRİM HARİÇ ÜRÜN | R1: MAYIS TOPTAN TOPTAN | S1: HAVALE FİYATI | T1: TEK ÇEKİM FİYATI | U1: TAKSİTLİ FİYATI 3/7 TAKSİT | V1: MAYIS BİP | W1: Mayıs / Phase out Fiyat farkları 30.06.2026 olarak montaj ZORUNLU | X1: Hakedişler LİSTE FİYATINDAN SATILIRSA geçerli olacak | Y1: BİP KOŞULU | Z1: ÜRÜN NOTLARI | AA1: ONLİNE FİYAT
A2: KA93NVL30N | B2: =IFERROR(HYPERLINK(VLOOKUP(A2,ÜRÜNLER!A:C,3,FALSE),VLOOKUP(A2,ÜRÜNLER!A:B,2,FALSE)),"") -> iQ300 Gardırop Tipi Buzdolabı, 90.8cm, Inox | J2: 1 | K2: 1 | N2: =M2+L2+K2+J2+I2+H2+G2+F2+E2+D2+C2 -> 2 | R2: devamı yok | S2: 80000 | T2: 83200 | U2: 86400 | X2: 1000
A3: KF96RSBEA | B3: =IFERROR(HYPERLINK(VLOOKUP(A3,ÜRÜNLER!A:C,3,FALSE),VLOOKUP(A3,ÜRÜNLER!A:B,2,FALSE)),"") -> iQ700 Gardırop Tipi Buzdolabı, Cam Kapı, Alkol Çekmeceli, 90.5cm, Siyah | C3: 8 | I3: 1 | J3: 1 | M3: 1 | N3: =M3+L3+K3+J3+I3+H3+G3+F3+E3+D3+C3 -> 11 | O3: 4 | R3: 210521.14 | S3: 204205.5 | T3: 212373.72 | U3: 220541.94
A4: KF96NAXEA | B4: =IFERROR(HYPERLINK(VLOOKUP(A4,ÜRÜNLER!A:C,3,FALSE),VLOOKUP(A4,ÜRÜNLER!A:B,2,FALSE)),"") -> iQ300 Gardırop Tipi Buzdolabı, 90.5cm, BlackSteel | C4: 18 | I4: 1 | J4: 1 | K4: 2 | M4: 1 | N4: =M4+L4+K4+J4+I4+H4+G4+F4+E4+D4+C4 -> 23 | O4: 5 | R4: 128387.15 | S4: 124535.53 | T4: 129516.96 | U4: 134498.38 | V4: 31213.538
A5: KF96NVPEA | B5: =IFERROR(HYPERLINK(VLOOKUP(A5,ÜRÜNLER!A:C,3,FALSE),VLOOKUP(A5,ÜRÜNLER!A:B,2,FALSE)),"") -> iQ300 Gardırop Tipi Buzdolabı, 90.5cm, Inox | C5: 17 | I5: 1 | K5: 2 | N5: =M5+L5+K5+J5+I5+H5+G5+F5+E5+D5+C5 -> 20 | O5: 4 | R5: 113545.45 | S5: 110139.09 | T5: 114544.65 | U5: 118950.21 | V5: 17401.265
A6: KD43NNWE0N | B6: =IFERROR(HYPERLINK(VLOOKUP(A6,ÜRÜNLER!A:C,3,FALSE),VLOOKUP(A6,ÜRÜNLER!A:B,2,FALSE)),"") -> iQ100 Üstten Donduruculu Kulpsuz Buzdolabı, 70cm, Beyaz | C6: 2 | N6: =M6+L6+K6+J6+I6+H6+G6+F6+E6+D6+C6 -> 2 | Q6: PRİM HARİÇ | R6: 31769.317 | S6: 31769.317 | T6: 33040.09 | U6: 34310.863
A7: KD55NNWE0N | B7: =IFERROR(HYPERLINK(VLOOKUP(A7,ÜRÜNLER!A:C,3,FALSE),VLOOKUP(A7,ÜRÜNLER!A:B,2,FALSE)),"") -> iQ300 Üstten Donduruculu Kulpsuz Buzdolabı, 70cm, Beyaz | C7: 1 | N7: =M7+L7+K7+J7+I7+H7+G7+F7+E7+D7+C7 -> 1 | Q7: PRİM HARİÇ | R7: 35726.773 | S7: 35726.773 | T7: 37155.844 | U7: 38584.915 | V7: 1565.1451
A8: KD55NNLE0N | B8: =IFERROR(HYPERLINK(VLOOKUP(A8,ÜRÜNLER!A:C,3,FALSE),VLOOKUP(A8,ÜRÜNLER!A:B,2,FALSE)),"") -> iQ300 Üstten Donduruculu Kulpsuz Buzdolabı, 70cm, Inox Görünümlü | N8: =M8+L8+K8+J8+I8+H8+G8+F8+E8+D8+C8 -> 0 | O8: 5 | Q8: PRİM HARİÇ | R8: 41958.595 | S8: 41958.595 | T8: 43636.939 | U8: 45315.283 | V8: 4378.3628
A9: KD56NXWF1N | B9: =IFERROR(HYPERLINK(VLOOKUP(A9,ÜRÜNLER!A:C,3,FALSE),VLOOKUP(A9,ÜRÜNLER!A:B,2,FALSE)),"") -> iQ300 Üstten Donduruculu Kulpsuz Buzdolabı, 70cm, Beyaz | K9: 1 | N9: =M9+L9+K9+J9+I9+H9+G9+F9+E9+D9+C9 -> 1 | R9: devamı yok | S9: 40000 | T9: 41600 | U9: 43200 | X9: 250
A10: KD76NAIE0N | B10: =IFERROR(HYPERLINK(VLOOKUP(A10,ÜRÜNLER!A:C,3,FALSE),VLOOKUP(A10,ÜRÜNLER!A:B,2,FALSE)),"") -> iQ500 Üstten Donduruculu Kulplu Buzdolabı, 75cm, Inox | N10: =M10+L10+K10+J10+I10+H10+G10+F10+E10+D10+C10 -> 0 | U10: 0 | X10: 250
A11: KD76NAIE1N | B11: =IFERROR(HYPERLINK(VLOOKUP(A11,ÜRÜNLER!A:C,3,FALSE),VLOOKUP(A11,ÜRÜNLER!A:B,2,FALSE)),"") -> iQ500 Üstten Donduruculu Kulplu Buzdolabı, 75cm, Inox | C11: 10 | N11: =M11+L11+K11+J11+I11+H11+G11+F11+E11+D11+C11 -> 10 | O11: 2 | R11: 82878.063 | S11: 80391.722 | T11: 83607.39 | U11: 86823.059 | V11: 17957.133
A12: KD76NAWE1N | B12: =IFERROR(HYPERLINK(VLOOKUP(A12,ÜRÜNLER!A:C,3,FALSE),VLOOKUP(A12,ÜRÜNLER!A:B,2,FALSE)),"") -> iQ500 Üstten Donduruculu Kulplu Buzdolabı, 75cm, Beyaz | C12: 10 | N12: =M12+L12+K12+J12+I12+H12+G12+F12+E12+D12+C12 -> 10 | R12: 57924.593 | S12: 56186.855 | T12: 58434.329 | U12: 60681.804
A13: KD76NHID1N | B13: =IFERROR(HYPERLINK(VLOOKUP(A13,ÜRÜNLER!A:C,3,FALSE),VLOOKUP(A13,ÜRÜNLER!A:B,2,FALSE)),"") -> iQ500 Üstten Donduruculu Kulplu Buzdolabı, 75cm, Inox | C13: 2 | N13: =M13+L13+K13+J13+I13+H13+G13+F13+E13+D13+C13 -> 2 | R13: devamı yok | S13: 60000 | T13: 62400 | U13: 64800
A14: KD76NXIE1N | B14: =IFERROR(HYPERLINK(VLOOKUP(A14,ÜRÜNLER!A:C,3,FALSE),VLOOKUP(A14,ÜRÜNLER!A:B,2,FALSE)),"") -> iQ500 Üstten Donduruculu Kulpsuz Buzdolabı, 75cm, Inox | C14: 7 | N14: =M14+L14+K14+J14+I14+H14+G14+F14+E14+D14+C14 -> 7 | O14: 2 | R14: 66166.491 | S14: 64181.497 | T14: 66748.757 | U14: 69316.016 | V14: 10174.631
A15: KD76NXWE1N | B15: =IFERROR(HYPERLINK(VLOOKUP(A15,ÜRÜNLER!A:C,3,FALSE),VLOOKUP(A15,ÜRÜNLER!A:B,2,FALSE)),"") -> iQ300 Üstten Donduruculu, Kulpsuz Buzdolabı, 75cm, Beyaz | C15: 8 | I15: 1 | J15: 1 | M15: 1 | N15: =M15+L15+K15+J15+I15+H15+G15+F15+E15+D15+C15 -> 11 | O15: 3 | R15: 61265.27 | S15: 59427.312 | T15: 61804.404 | U15: 64181.497 | V15: 6746.6652
A16: KD76NXWE0N | B16: =IFERROR(HYPERLINK(VLOOKUP(A16,ÜRÜNLER!A:C,3,FALSE),VLOOKUP(A16,ÜRÜNLER!A:B,2,FALSE)),"") -> iQ300 Üstten Donduruculu Kulpsuz Buzdolabı, 75cm, Beyaz | K16: 1 | N16: =M16+L16+K16+J16+I16+H16+G16+F16+E16+D16+C16 -> 1 | P16: 1 | R16: devamı yok | S16: 75000 | T16: 78000 | U16: 81000 | X16: 250
A17: KD86NAID1N | B17: =IFERROR(HYPERLINK(VLOOKUP(A17,ÜRÜNLER!A:C,3,FALSE),VLOOKUP(A17,ÜRÜNLER!A:B,2,FALSE)),"") -> iQ500 Üstten Donduruculu Kulplu Buzdolabı, 86cm, Inox | C17: 6 | E17: 1 | I17: 1 | J17: 1 | N17: =M17+L17+K17+J17+I17+H17+G17+F17+E17+D17+C17 -> 9 | O17: 2 | R17: 95662.202 | S17: 92792.336 | T17: 96504.03 | U17: 100215.72 | V17: 19655.226
A18: KD86NAWE1N | B18: =IFERROR(HYPERLINK(VLOOKUP(A18,ÜRÜNLER!A:C,3,FALSE),VLOOKUP(A18,ÜRÜNLER!A:B,2,FALSE)),"") -> iQ500 Üstten Donduruculu Kulplu Buzdolabı, 86cm, Beyaz | C18: 6 | N18: =M18+L18+K18+J18+I18+H18+G18+F18+E18+D18+C18 -> 6 | O18: 2 | R18: 83239.542 | S18: 80742.356 | T18: 83972.05 | U18: 87201.744 | V18: 13613.961
A19: KD86NHID1N | B19: =IFERROR(HYPERLINK(VLOOKUP(A19,ÜRÜNLER!A:C,3,FALSE),VLOOKUP(A19,ÜRÜNLER!A:B,2,FALSE)),"") -> iQ500 Üstten Donduruculu Kulplu Buzdolabı, 86cm, Inox | K19: 1 | N19: =M19+L19+K19+J19+I19+H19+G19+F19+E19+D19+C19 -> 1 | R19: devamı yok | S19: 55000 | T19: 57200 | U19: 59400 | X19: 250
A20: KG36NNLE0N | B20: =IFERROR(HYPERLINK(VLOOKUP(A20,ÜRÜNLER!A:C,3,FALSE),VLOOKUP(A20,ÜRÜNLER!A:B,2,FALSE)),"") -> iQ100 Alttan Donduruculu Kulpsuz Buzdolabı, 60cm, Inox | F20: 1 | K20: 1 | N20: =M20+L20+K20+J20+I20+H20+G20+F20+E20+D20+C20 -> 2 | R20: devamı yok | S20: 40000 | T20: 41600 | U20: 43200 | X20: 250
A21: KG55NCIE0N | B21: =IFERROR(HYPERLINK(VLOOKUP(A21,ÜRÜNLER!A:C,3,FALSE),VLOOKUP(A21,ÜRÜNLER!A:B,2,FALSE)),"") -> iQ300 Alttan Donduruculu Kulpsuz Buzdolabı, 70cm, Inox | C21: 102 | E21: 4 | F21: 1 | I21: 1 | J21: 1 | K21: 1 | M21: 1 | N21: =M21+L21+K21+J21+I21+H21+G21+F21+E21+D21+C21 -> 111 | R21: 63469.622 | S21: 63469.622 | T21: 66008.407 | U21: 68547.192 | V21: 11930.087 | Z21: ONLINE SATILABİLİR
A22: KG55NCWE0N | B22: =IFERROR(HYPERLINK(VLOOKUP(A22,ÜRÜNLER!A:C,3,FALSE),VLOOKUP(A22,ÜRÜNLER!A:B,2,FALSE)),"") -> iQ300 Alttan Donduruculu Kulpsuz Buzdolabı, 70cm, Beyaz | C22: 89 | I22: 1 | K22: 2 | N22: =M22+L22+K22+J22+I22+H22+G22+F22+E22+D22+C22 -> 92 | R22: 57039.061 | S22: 54187.108 | T22: 56354.593 | U22: 58522.077 | V22: 7884.4101
A23: KG55NVIE0N | B23: =IFERROR(HYPERLINK(VLOOKUP(A23,ÜRÜNLER!A:C,3,FALSE),VLOOKUP(A23,ÜRÜNLER!A:B,2,FALSE)),"") -> iQ300 Alttan Donduruculu Kulpsuz Buzdolabı, 70cm, Inox | C23: 6 | E23: 1 | K23: 1 | N23: =M23+L23+K23+J23+I23+H23+G23+F23+E23+D23+C23 -> 8 | R23: 51274.363 | S23: 51274.363 | T23: 53325.337 | U23: 55376.312 | V23: 6515.0603 | Z23: ONLINE SATILABİLİR
A24: KG55NVWE0N | B24: =IFERROR(HYPERLINK(VLOOKUP(A24,ÜRÜNLER!A:C,3,FALSE),VLOOKUP(A24,ÜRÜNLER!A:B,2,FALSE)),"") -> iQ300 Alttan Donduruculu Kulpsuz Buzdolabı, 70cm, Beyaz | C24: 1 | E24: 1 | I24: 1 | K24: 1 | N24: =M24+L24+K24+J24+I24+H24+G24+F24+E24+D24+C24 -> 4 | R24: 46796.713 | S24: 46796.713 | T24: 48668.581 | U24: 50540.45 | V24: 6164.1546 | Z24: ONLINE SATILABİLİR
A25: KG56NLBE0N | B25: =IFERROR(HYPERLINK(VLOOKUP(A25,ÜRÜNLER!A:C,3,FALSE),VLOOKUP(A25,ÜRÜNLER!A:B,2,FALSE)),"") -> iQ500 Alttan Donduruculu Kulpsuz Buzdolabı, 70cm, Parlak Siyah | C25: 14 | I25: 2 | J25: 1 | M25: 2 | N25: =M25+L25+K25+J25+I25+H25+G25+F25+E25+D25+C25 -> 19 | R25: 58065.822 | S25: 58065.822 | T25: 60388.455 | U25: 62711.088 | Z25: ONLINE SATILABİLİR
A26: KG56NQWF0N | B26: =IFERROR(HYPERLINK(VLOOKUP(A26,ÜRÜNLER!A:C,3,FALSE),VLOOKUP(A26,ÜRÜNLER!A:B,2,FALSE)),"") -> iQ500 Alttan Donduruculu Kulpsuz Buzdolabı, 70cm, Seramik Desen | J26: 1 | N26: =M26+L26+K26+J26+I26+H26+G26+F26+E26+D26+C26 -> 1 | R26: devamı yok | S26: 48000 | T26: 49920 | U26: 51840 | X26: 500
A27: KG56NTEE0N | B27: =IFERROR(HYPERLINK(VLOOKUP(A27,ÜRÜNLER!A:C,3,FALSE),VLOOKUP(A27,ÜRÜNLER!A:B,2,FALSE)),"") -> iQ500 Alttan Donduruculu Kulpsuz Buzdolabı, 70cm, Mat Siyah | F27: 1 | N27: =M27+L27+K27+J27+I27+H27+G27+F27+E27+D27+C27 -> 1 | R27: devamı yok | S27: 48000 | T27: 49920 | U27: 51840 | X27: 500
A28: KG56NTWE0N | B28: =IFERROR(HYPERLINK(VLOOKUP(A28,ÜRÜNLER!A:C,3,FALSE),VLOOKUP(A28,ÜRÜNLER!A:B,2,FALSE)),"") -> iQ500 Alttan Donduruculu Kulpsuz Buzdolabı, 70cm, Seramik Desen | I28: 1 | K28: 1 | N28: =M28+L28+K28+J28+I28+H28+G28+F28+E28+D28+C28 -> 2 | R28: devamı yok | S28: 48000 | T28: 49920 | U28: 51840 | X28: 500
A29: KG56NXWE0N | B29: =IFERROR(HYPERLINK(VLOOKUP(A29,ÜRÜNLER!A:C,3,FALSE),VLOOKUP(A29,ÜRÜNLER!A:B,2,FALSE)),"") -> iQ300 Alttan Donduruculu Kulpsuz Buzdolabı, 70cm, Beyaz | C29: 1 | N29: =M29+L29+K29+J29+I29+H29+G29+F29+E29+D29+C29 -> 1 | R29: devamı yok | S29: 48000 | T29: 49920 | U29: 51840
A30: KG76APIE0N | B30: =IFERROR(HYPERLINK(VLOOKUP(A30,ÜRÜNLER!A:C,3,FALSE),VLOOKUP(A30,ÜRÜNLER!A:B,2,FALSE)),"") -> iQ700 Alttan Donduruculu Kulplu Buzdolabı, 75cm, Inox | C30: 16 | N30: =M30+L30+K30+J30+I30+H30+G30+F30+E30+D30+C30 -> 16 | R30: 72088.36 | S30: 67042.175 | T30: 69723.862 | U30: 72405.549 | X30: 250
A31: KG76NCIE0N | B31: =IFERROR(HYPERLINK(VLOOKUP(A31,ÜRÜNLER!A:C,3,FALSE),VLOOKUP(A31,ÜRÜNLER!A:B,2,FALSE)),"") -> iQ500 Alttan Donduruculu Kulplu Buzdolabı, 75cm, Inox | C31: 27 | I31: 1 | J31: 1 | K31: 3 | M31: 1 | N31: =M31+L31+K31+J31+I31+H31+G31+F31+E31+D31+C31 -> 33 | O31: 34 | R31: 84280.726 | S31: 81752.304 | T31: 85022.396 | U31: 88292.488 | V31: 18545.842
A32: KG76NCWE0N | B32: =IFERROR(HYPERLINK(VLOOKUP(A32,ÜRÜNLER!A:C,3,FALSE),VLOOKUP(A32,ÜRÜNLER!A:B,2,FALSE)),"") -> iQ500 Alttan Donduruculu Kulplu Buzdolabı, 75cm, Beyaz | C32: 45 | I32: 1 | K32: 1 | N32: =M32+L32+K32+J32+I32+H32+G32+F32+E32+D32+C32 -> 47 | O32: 10 | R32: 77045.044 | S32: 73192.792 | T32: 76120.503 | U32: 79048.215 | V32: 14224.114
A33: KG76NCXE0N | B33: =IFERROR(HYPERLINK(VLOOKUP(A33,ÜRÜNLER!A:C,3,FALSE),VLOOKUP(A33,ÜRÜNLER!A:B,2,FALSE)),"") -> iQ500 Alttan Donduruculu Kulpsuz Buzdolabı, 75cm, darkSteel | C33: 13 | I33: 1 | J33: 1 | M33: 1 | N33: =M33+L33+K33+J33+I33+H33+G33+F33+E33+D33+C33 -> 16 | O33: 26 | R33: 95152.057 | S33: 90394.455 | T33: 94010.233 | U33: 97626.011 | V33: 26079.964
A34: KG76NVIE0N | B34: =IFERROR(HYPERLINK(VLOOKUP(A34,ÜRÜNLER!A:C,3,FALSE),VLOOKUP(A34,ÜRÜNLER!A:B,2,FALSE)),"") -> iQ300 Alttan Donduruculu Kulpsuz Buzdolabı, 75cm, Inox | C34: 31 | F34: 1 | I34: 1 | K34: 2 | N34: =M34+L34+K34+J34+I34+H34+G34+F34+E34+D34+C34 -> 35 | O34: 11 | R34: 76173.043 | S34: 73887.852 | T34: 76843.366 | U34: 79798.88 | V34: 16282.346
A35: KG76NVWE0N | B35: =IFERROR(HYPERLINK(VLOOKUP(A35,ÜRÜNLER!A:C,3,FALSE),VLOOKUP(A35,ÜRÜNLER!A:B,2,FALSE)),"") -> iQ300 Alttan Donduruculu Kulpsuz Buzdolabı, 75cm, Beyaz | C35: 37 | I35: 1 | J35: 1 | M35: 1 | N35: =M35+L35+K35+J35+I35+H35+G35+F35+E35+D35+C35 -> 40 | O35: 10 | R35: 68727.331 | S35: 65290.965 | T35: 67902.603 | U35: 70514.242 | V35: 10684.308
A36: KG76PAIC0N | B36: =IFERROR(HYPERLINK(VLOOKUP(A36,ÜRÜNLER!A:C,3,FALSE),VLOOKUP(A36,ÜRÜNLER!A:B,2,FALSE)),"") -> iQ700 Alttan Donduruculu Kulplu Buzdolabı, 75cm, Inox | C36: 41 | E36: 2 | F36: 1 | I36: 1 | J36: 1 | M36: 1 | N36: =M36+L36+K36+J36+I36+H36+G36+F36+E36+D36+C36 -> 47 | O36: 11 | R36: 89108.337 | S36: 84652.921 | T36: 88039.037 | U36: 91425.154 | V36: 13793.221
A37: KG76PAWC0N | B37: =IFERROR(HYPERLINK(VLOOKUP(A37,ÜRÜNLER!A:C,3,FALSE),VLOOKUP(A37,ÜRÜNLER!A:B,2,FALSE)),"") -> iQ700 Alttan Donduruculu Kulplu Buzdolabı, 75cm, Beyaz | C37: 20 | E37: 1 | I37: 1 | K37: 3 | N37: =M37+L37+K37+J37+I37+H37+G37+F37+E37+D37+C37 -> 25 | O37: 5 | R37: 82556.235 | S37: 78428.423 | T37: 81565.56 | U37: 84702.697 | V37: 13760.886
A38: KG86NAID2N | B38: =IFERROR(HYPERLINK(VLOOKUP(A38,ÜRÜNLER!A:C,3,FALSE),VLOOKUP(A38,ÜRÜNLER!A:B,2,FALSE)),"") -> iQ500 Alttan Donduruculu Kulplu Buzdolabı, 86cm, Inox | C38: 136 | E38: 1 | F38: 2 | I38: 1 | J38: 1 | K38: 1 | M38: 1 | N38: =M38+L38+K38+J38+I38+H38+G38+F38+E38+D38+C38 -> 143 | O38: 35 | R38: 97945.234 | S38: 93047.972 | T38: 96769.891 | U38: 100491.81 | V38: 23794.071 | AA38: =S38-V38 -> 69253.901
A39: KG86NCWE0N | B39: =IFERROR(HYPERLINK(VLOOKUP(A39,ÜRÜNLER!A:C,3,FALSE),VLOOKUP(A39,ÜRÜNLER!A:B,2,FALSE)),"") -> iQ500 Alttan Donduruculu Kulplu Buzdolabı, 86cm, Beyaz | C39: 21 | F39: 1 | I39: 1 | N39: =M39+L39+K39+J39+I39+H39+G39+F39+E39+D39+C39 -> 23 | O39: 7 | R39: 84927.533 | S39: 81530.432 | T39: 84791.649 | U39: 88052.866 | V39: 16653.114 | AA39: 70443
A40: KG86NVWE0N | B40: =IFERROR(HYPERLINK(VLOOKUP(A40,ÜRÜNLER!A:C,3,FALSE),VLOOKUP(A40,ÜRÜNLER!A:B,2,FALSE)),"") -> iQ500 Alttan Donduruculu Kulpsuz Buzdolabı, 86cm, Beyaz | C40: 14 | F40: 1 | J40: 1 | N40: =M40+L40+K40+J40+I40+H40+G40+F40+E40+D40+C40 -> 16 | O40: 9 | R40: 75297.093 | S40: 72285.209 | T40: 75176.617 | U40: 78068.026 | V40: 11125
...

Sheet HESAPLAYICI
A1: =Sayfa1!A1 -> STOK KODU | B1: =Sayfa1!B1 -> AÇIKLAMA | C1: =Sayfa1!C1 -> 16 MAYIS HOROZ | D1: =Sayfa1!$R$1 -> MAYIS TOPTAN TOPTAN | E1: =Sayfa1!$S$1 -> HAVALE FİYATI | F1: =Sayfa1!$T$1 -> TEK ÇEKİM FİYATI | G1: =Sayfa1!$U$1 -> TAKSİTLİ FİYATI 3/7 TAKSİT | H1: =Sayfa1!$V$1 -> MAYIS BİP | I1: Toplam Bundle İndirim Tutarını Aşağıya Yaz | J1: =Sayfa1!$X$1 -> Hakedişler LİSTE FİYATINDAN SATILIRSA geçerli olacak | K1: =Sayfa1!$W$1 -> Mayıs / Phase out Fiyat farkları 30.06.2026 olarak montaj ZORUNLU | L1: =Sayfa1!$Y$1 -> BİP KOŞULU
A2: HB534FER0T | B2: =IFERROR(VLOOKUP(A2,Sayfa1!A:B,2,FALSE),"?") -> iQ300 Ankastre Fırın, 1 Teleskopik Ray, Arkası Kendini Temizler, Siyah/Inox | C2: =IFERROR(VLOOKUP(A2,Sayfa1!A:C,3,FALSE),"?") -> 0 | D2: =IFERROR(VLOOKUP(A2,Sayfa1!$A:$R,17,FALSE),"?") -> 0 | E2: =IFERROR(VLOOKUP(A2,Sayfa1!$A:$S,18,FALSE),"?") -> devamı yok | F2: =IFERROR(VLOOKUP(A2,Sayfa1!$A:$T,19,FALSE),"?") -> 18000 | G2: =IFERROR(VLOOKUP(A2,Sayfa1!$A:$U,20,FALSE),"?") -> 18720 | H2: =IFERROR(VLOOKUP(A2,Sayfa1!$A:$V,21,FALSE),"?") -> 19440 | J2: =IFERROR(VLOOKUP(A2,Sayfa1!$A:$X,23,FALSE),"?") -> 1656.58 | K2: =IFERROR(VLOOKUP(A2,Sayfa1!$A:$W,22,FALSE),"?") -> 0 | L2: =IFERROR(VLOOKUP(A2,Sayfa1!$A:$Y,24,FALSE),"?") -> 250
B3: =IFERROR(VLOOKUP(A3,Sayfa1!A:B,2,FALSE),"?") -> ? | C3: =IFERROR(VLOOKUP(A3,Sayfa1!A:C,3,FALSE),"?") -> ? | D3: =IFERROR(VLOOKUP(A3,Sayfa1!$A:$R,17,FALSE),"?") -> ? | E3: =IFERROR(VLOOKUP(A3,Sayfa1!$A:$S,18,FALSE),"?") -> ? | F3: =IFERROR(VLOOKUP(A3,Sayfa1!$A:$T,19,FALSE),"?") -> ? | G3: =IFERROR(VLOOKUP(A3,Sayfa1!$A:$U,20,FALSE),"?") -> ? | H3: =IFERROR(VLOOKUP(A3,Sayfa1!$A:$V,21,FALSE),"?") -> ? | J3: =IFERROR(VLOOKUP(A3,Sayfa1!$A:$X,23,FALSE),"?") -> ? | K3: =IFERROR(VLOOKUP(A3,Sayfa1!$A:$W,22,FALSE),"?") -> ? | L3: =IFERROR(VLOOKUP(A3,Sayfa1!$A:$Y,24,FALSE),"?") -> ?
B4: =IFERROR(VLOOKUP(A4,Sayfa1!A:B,2,FALSE),"?") -> ? | C4: =IFERROR(VLOOKUP(A4,Sayfa1!A:C,3,FALSE),"?") -> ? | D4: =IFERROR(VLOOKUP(A4,Sayfa1!$A:$R,17,FALSE),"?") -> ? | E4: =IFERROR(VLOOKUP(A4,Sayfa1!$A:$S,18,FALSE),"?") -> ? | F4: =IFERROR(VLOOKUP(A4,Sayfa1!$A:$T,19,FALSE),"?") -> ? | G4: =IFERROR(VLOOKUP(A4,Sayfa1!$A:$U,20,FALSE),"?") -> ? | H4: =IFERROR(VLOOKUP(A4,Sayfa1!$A:$V,21,FALSE),"?") -> ? | J4: =IFERROR(VLOOKUP(A4,Sayfa1!$A:$X,23,FALSE),"?") -> ? | K4: =IFERROR(VLOOKUP(A4,Sayfa1!$A:$W,22,FALSE),"?") -> ? | L4: =IFERROR(VLOOKUP(A4,Sayfa1!$A:$Y,24,FALSE),"?") -> ?
B5: =IFERROR(VLOOKUP(A5,Sayfa1!A:B,2,FALSE),"?") -> ? | C5: =IFERROR(VLOOKUP(A5,Sayfa1!A:C,3,FALSE),"?") -> ? | D5: =IFERROR(VLOOKUP(A5,Sayfa1!$A:$R,17,FALSE),"?") -> ? | E5: =IFERROR(VLOOKUP(A5,Sayfa1!$A:$S,18,FALSE),"?") -> ? | F5: =IFERROR(VLOOKUP(A5,Sayfa1!$A:$T,19,FALSE),"?") -> ? | G5: =IFERROR(VLOOKUP(A5,Sayfa1!$A:$U,20,FALSE),"?") -> ? | H5: =IFERROR(VLOOKUP(A5,Sayfa1!$A:$V,21,FALSE),"?") -> ? | J5: =IFERROR(VLOOKUP(A5,Sayfa1!$A:$X,23,FALSE),"?") -> ? | K5: =IFERROR(VLOOKUP(A5,Sayfa1!$A:$W,22,FALSE),"?") -> ? | L5: =IFERROR(VLOOKUP(A5,Sayfa1!$A:$Y,24,FALSE),"?") -> ?
B6: =IFERROR(VLOOKUP(A6,Sayfa1!A:B,2,FALSE),"?") -> ? | C6: =IFERROR(VLOOKUP(A6,Sayfa1!A:C,3,FALSE),"?") -> ? | D6: =IFERROR(VLOOKUP(A6,Sayfa1!$A:$R,17,FALSE),"?") -> ? | E6: =IFERROR(VLOOKUP(A6,Sayfa1!$A:$S,18,FALSE),"?") -> ? | F6: =IFERROR(VLOOKUP(A6,Sayfa1!$A:$T,19,FALSE),"?") -> ? | G6: =IFERROR(VLOOKUP(A6,Sayfa1!$A:$U,20,FALSE),"?") -> ? | H6: =IFERROR(VLOOKUP(A6,Sayfa1!$A:$V,21,FALSE),"?") -> ? | J6: =IFERROR(VLOOKUP(A6,Sayfa1!$A:$X,23,FALSE),"?") -> ? | K6: =IFERROR(VLOOKUP(A6,Sayfa1!$A:$W,22,FALSE),"?") -> ? | L6: =IFERROR(VLOOKUP(A6,Sayfa1!$A:$Y,24,FALSE),"?") -> ?
B7: =IFERROR(VLOOKUP(A7,Sayfa1!A:B,2,FALSE),"?") -> ? | C7: =IFERROR(VLOOKUP(A7,Sayfa1!A:C,3,FALSE),"?") -> ? | D7: =IFERROR(VLOOKUP(A7,Sayfa1!$A:$R,17,FALSE),"?") -> ? | E7: =IFERROR(VLOOKUP(A7,Sayfa1!$A:$S,18,FALSE),"?") -> ? | F7: =IFERROR(VLOOKUP(A7,Sayfa1!$A:$T,19,FALSE),"?") -> ? | G7: =IFERROR(VLOOKUP(A7,Sayfa1!$A:$U,20,FALSE),"?") -> ? | H7: =IFERROR(VLOOKUP(A7,Sayfa1!$A:$V,21,FALSE),"?") -> ? | J7: =IFERROR(VLOOKUP(A7,Sayfa1!$A:$X,23,FALSE),"?") -> ? | K7: =IFERROR(VLOOKUP(A7,Sayfa1!$A:$W,22,FALSE),"?") -> ? | L7: =IFERROR(VLOOKUP(A7,Sayfa1!$A:$Y,24,FALSE),"?") -> ?
B8: =IFERROR(VLOOKUP(A8,Sayfa1!A:B,2,FALSE),"?") -> ? | C8: =IFERROR(VLOOKUP(A8,Sayfa1!A:C,3,FALSE),"?") -> ? | D8: =IFERROR(VLOOKUP(A8,Sayfa1!$A:$R,17,FALSE),"?") -> ? | E8: =IFERROR(VLOOKUP(A8,Sayfa1!$A:$S,18,FALSE),"?") -> ? | F8: =IFERROR(VLOOKUP(A8,Sayfa1!$A:$T,19,FALSE),"?") -> ? | G8: =IFERROR(VLOOKUP(A8,Sayfa1!$A:$U,20,FALSE),"?") -> ? | H8: =IFERROR(VLOOKUP(A8,Sayfa1!$A:$V,21,FALSE),"?") -> ? | J8: =IFERROR(VLOOKUP(A8,Sayfa1!$A:$X,23,FALSE),"?") -> ? | K8: =IFERROR(VLOOKUP(A8,Sayfa1!$A:$W,22,FALSE),"?") -> ? | L8: =IFERROR(VLOOKUP(A8,Sayfa1!$A:$Y,24,FALSE),"?") -> ?
B9: =IFERROR(VLOOKUP(A9,Sayfa1!A:B,2,FALSE),"?") -> ? | C9: =IFERROR(VLOOKUP(A9,Sayfa1!A:C,3,FALSE),"?") -> ? | D9: =IFERROR(VLOOKUP(A9,Sayfa1!$A:$R,17,FALSE),"?") -> ? | E9: =IFERROR(VLOOKUP(A9,Sayfa1!$A:$S,18,FALSE),"?") -> ? | F9: =IFERROR(VLOOKUP(A9,Sayfa1!$A:$T,19,FALSE),"?") -> ? | G9: =IFERROR(VLOOKUP(A9,Sayfa1!$A:$U,20,FALSE),"?") -> ? | H9: =IFERROR(VLOOKUP(A9,Sayfa1!$A:$V,21,FALSE),"?") -> ? | J9: =IFERROR(VLOOKUP(A9,Sayfa1!$A:$X,23,FALSE),"?") -> ? | K9: =IFERROR(VLOOKUP(A9,Sayfa1!$A:$W,22,FALSE),"?") -> ? | L9: =IFERROR(VLOOKUP(A9,Sayfa1!$A:$Y,24,FALSE),"?") -> ?
B10: =IFERROR(VLOOKUP(A10,Sayfa1!A:B,2,FALSE),"?") -> ? | C10: =IFERROR(VLOOKUP(A10,Sayfa1!A:C,3,FALSE),"?") -> ? | D10: =IFERROR(VLOOKUP(A10,Sayfa1!$A:$R,17,FALSE),"?") -> ? | E10: =IFERROR(VLOOKUP(A10,Sayfa1!$A:$S,18,FALSE),"?") -> ? | F10: =IFERROR(VLOOKUP(A10,Sayfa1!$A:$T,19,FALSE),"?") -> ? | G10: =IFERROR(VLOOKUP(A10,Sayfa1!$A:$U,20,FALSE),"?") -> ? | H10: =IFERROR(VLOOKUP(A10,Sayfa1!$A:$V,21,FALSE),"?") -> ? | J10: =IFERROR(VLOOKUP(A10,Sayfa1!$A:$X,23,FALSE),"?") -> ? | K10: =IFERROR(VLOOKUP(A10,Sayfa1!$A:$W,22,FALSE),"?") -> ? | L10: =IFERROR(VLOOKUP(A10,Sayfa1!$A:$Y,24,FALSE),"?") -> ?
B11: =IFERROR(VLOOKUP(A11,Sayfa1!A:B,2,FALSE),"?") -> ? | C11: =IFERROR(VLOOKUP(A11,Sayfa1!A:C,3,FALSE),"?") -> ? | D11: =IFERROR(VLOOKUP(A11,Sayfa1!$A:$R,17,FALSE),"?") -> ? | E11: =IFERROR(VLOOKUP(A11,Sayfa1!$A:$S,18,FALSE),"?") -> ? | F11: =IFERROR(VLOOKUP(A11,Sayfa1!$A:$T,19,FALSE),"?") -> ? | G11: =IFERROR(VLOOKUP(A11,Sayfa1!$A:$U,20,FALSE),"?") -> ? | H11: =IFERROR(VLOOKUP(A11,Sayfa1!$A:$V,21,FALSE),"?") -> ? | J11: =IFERROR(VLOOKUP(A11,Sayfa1!$A:$X,23,FALSE),"?") -> ? | K11: =IFERROR(VLOOKUP(A11,Sayfa1!$A:$W,22,FALSE),"?") -> ? | L11: =IFERROR(VLOOKUP(A11,Sayfa1!$A:$Y,24,FALSE),"?") -> ?
A12: Toplam Satış Fiyatı | E12: =SUM(E2:E11) -> 0 | F12: =SUM(F2:F11) -> 18000
A13: BİP İndirimi | E13: =SUM(G:G)*-1 -> -18720 | F13: =SUM(G:G)*-1 -> -18720
A14: PhaseOut İndirimi | E14: =SUM(H:H)*-1 -> -19440 | F14: =SUM(H:H)*-1 -> -19440
A15: Toplam Bundle İndirimi | E15: =I2*-1 -> 0 | F15: =I2*-1 -> 0
A16: Satılabilir Minimum Fiyat | E16: =SUM(E12:E15) -> -38160 | F16: =SUM(F12:F15) -> -20160
A17: Satılabilir Minimum Taksitli Fiyat | E17: =E16*1.08 -> -41212.8

Sheet Bundle Kampanya
C2: 2’li LDA alımında perakende de 5.000 ₺ indirim fırsatı! | D2: 2’li LDA alımında (Buzdolabı - Çamaşır - Kurutma - Bulaşık ) perakende de 5.000 ₺ indirim uygulanır. “diğer kampanyalar ile birleşemez” 4.000 ₺ kdv dahil fiyat farkı hak edişi ödenecektir.
K9: Seçili Ankastre fırın ile set alana perakende de 6.000 ₺ indirim! | L9: Geçerli Ankastre Fırınlar
C11: Çamaşır Makinesi ile Kurutma Makinesi alana perakende de 10.000 ₺ indirim fırsatı! | D11: 2’li LDA alımında (ÇAMAŞIR + KURUTMA) perakende de 10.000 ₺ indirim uygulanır. “diğer kampanyalar ile birleşemez” 8.000 ₺ kdv dahil fiyat farkı hak edişi ödenecektir. | L11: HB012FBH1T, HB012FBB1T, HB012FBW1T + (phase out iQ300 ve iQ500 segment modeller) Ankastre fırınlarda geçerlidir. (HB011* ve giriş segment muadili modeller dahil değildir.)
L15: Uygulama koşulları : Seçili ankastre fırınlar ile set (fırın+ocak+dav.) set alana perakende de 6.000 ₺ indirim uygulanır. Diğer fırınlarda geçerli değildir. KDV dahil 4.500 ₺ hak ediş ödenir.
C21: Seçili Beyaz eşya alana ile birlikte Derin Dondurucu alımına perakende de 7.500 TL indirim! | D21: Seçili LDA alımına Derin Dondurucu perakende de 7.500 TL indirim! (TOPLAM 2 LDA)
K27: Seçili Ankastre Fırın ve Ocak alana perakende de LC63KPJ60T kodlu davlumbaz hediye! | L27: Geçerli Ankastre Setler
D29: Uygulama koşulları : Seçili LDA alımına ilave Derin Dondurucu alımı için perakende de 7.500 TL indirim uygulanır. KDV dahil 6.000 ₺ hak ediş ödenir. | L29: ( HB778G3B1, HR776G3B1, HS736G1B2, HB776G1B1, HB734G1B1, HR232GEB3, HB557JEB6T, HJ852GYN0T, HJ852GYB0T, HJ852GYW0T, HU736AEG0T, HU736AEV0T, HU736AEA0T, HU736AEN0T, HU717ABN0T, HU717ABA0T, HU717ABV0T) ve (phase out iQ500 segment ve üzeri modeller) Ankastre fırınlarda geçerlidir. (HB011 ve giriş segment muadili modeller dahil değildir.)
L33: Uygulama koşulları : Seçili Ankastre Fırın ve Ocak alana perakende de LC63KPJ60T kodlu davlumbaz hediyedir. Diğer davlumbazlarda da perakende de 11.610 ₺ net indirim uygulanır. Giriş setlerde geçerli değildir. KDV dahil 8.850 ₺ hak ediş ödenir.
C36: Seçili Premium Ürünlerden 3'lü LDA Alımına Ek SN15EC00NT Model Bulaşık Makinesi perakende de 9.999 ₺! | D36: Kampanya Kapsamındaki Ürünler
D38: Buzdolabı (KG76NCXE0N, KG86PAXB0N, KG86PFIC0N, KF96NAXEA, KF96NVPEA, KF96RSBEA, KG76PAIC0N) Çamaşır Makinesi (WG44B2A0TR, WG52K2ZXTR, WG54B2A1TR, WG54B2ASTR, WG64K2F0TR, WG64K2Y0TR, WG64K2ZRTR, WG64K2Z0TR) Kurutma Makinesi (WQ42G20RTR, WQ42J200TR, WQ42J20XTR, WQ43J2C0TR, WQ45B2A0TR,WQ45B2AXTR, WQ52K200TR, WQ44G2C1TR, WQ52J20RTR) Bulaşık Makinesi (SN15EC00NT, SN15EI00K, SN23IC62MT, SN25EI70MT, SN27YI82DT, SN25EI82AT, SN25EI83CT, SN57ZS82DT, SN57ZS82DT, SN55ES82KT)
K40: Seçili Ankastre fırın segmenti ve üzeri Set alımlarına “SN616X00DT” kodlu tam ankastre bulaşık makinesi perakende de %50 indirimli! | L40: ( HB557 ile başlayan tüm modeller ve HB778G3B1, HR776G3B1, HS736G1B2, HB776G1B1, HB734G1B1, HR232GEB3, HJ852GYN0T, HJ852GYB0T, HJ852GYW0T) ve (phase out iQ500 segment ve üzeri modeller) Ankastre fırınlarda geçerlidir. (HB011 ve giriş segment muadili modeller dahil değildir.)
L42: "HB557" Ankastre fırın segmenti ve daha üst segment fırınlar dahildir.
D44: Uygulama koşulları : Seçili premium ürünlerden 3'lü alımına ek bulaşık alan tüketicilere SN15EC00NT Bulaşık Makinesi perakende de 9.999 ₺! Diğer seçili bulaşıklarda perakende de 34.971 ₺ indirim uygulanmalıdır. KDV dahil 27.000 ₺ hak ediş ödenir. (Buzdolabı+Çamaşır+Bulaşık+Bulaşık)
L46: Uygulama koşulları : Seçili ankastre set (fırın+ocak+dav.) alımlarında “SN616X00DT” kodlu tam ankastre bulaşık makinesine perakende de %50 indirim uygulanır. Diğer ankastre bulaşık makinlerinde perakende de 19.230 ₺ indirim uygulanır. Giriş setlerde geçerli değildir. KDV dahil 13.000 ₺ hak ediş ödenir.
C51: XL - XXL Buzdolabı alana perakende de VSX21A300 Toz Torbasız Süpürge Hediye! “diğer kampanyalar ile birleşemez” | D51: XL veya XXL Buzdolabı alana perakende de VSX21A300 Toz Torbasız Süpürge Hediye verilir veya "Diğer Süpürgelerde perakende de 10.840 ₺ indirim uygulanır" (Dik şarjlı süpürgelerde dahildir.) 8.200 ₺ kdv dahil fiyat farkı hak edişi ödenecektir. “Diğer kampanyalar ile birleşemez” (Süpürge almak istemeyen tüketiciler için Buzdolaplarında indirim yapılabilir.)
K58: Seçili Ankastre fırın segmenti ve üzeri Set alımlarına “BF623LMS3” kodlu ankastre mikrodalga perakende de 1.990₺! | L58: ( HB557 ile başlayan tüm modeller ve HB778G3B1, HR776G3B1, HS736G1B2, HB776G1B1, HB734G1B1, HR232GEB3, HJ852GYN0T, HJ852GYB0T, HJ852GYW0T) ve (phase out iQ500 segment ve üzeri modeller) Ankastre fırınlarda geçerlidir. (HB011 ve giriş segment muadili modeller dahil değildir.)
L60: "HB557" Ankastre fırın segmenti ve daha üst segment fırınlar dahildir.
L64: Uygulama koşulları : Seçili ankastre set (fırın+ocak+dav.) alımlarında “BF623LMS3” kodlu ankastre mikrodalga perakende de 1.990₺. Diğer ankastre mikrodalgalarda da perakende de 15.620 ₺ indirim uygulanır. Giriş setlerde geçerli değildir. KDV dahil 13.000 ₺ hak ediş ödenir.

Sheet ÜRÜNLER
A1: Ürün No | B1: Ürün Adı | C1: Ürün Linki
A2: 50PUS8009/62 | B2: Philips 50" 4K Ambilight LED TV (Titan OS) (50PUS8009/62) | C2: https://www.philips.com.tr/c-p/50PUS8009_62/led-50pus8009-4k-ambilight-tv
A3: AS09IVW32N | B3: Siemens Ev Tipi Klima İç Ünite, 9.000BTU, Beyaz | C3: https://www.siemens-home.bsh-group.com/tr/tr/product/klimalar/AS09XVW32N
A4: AS09OVW32N | B4: Siemens Ev Tipi Klima Dış Ünite, 9.000BTU, Beyaz | C4: https://www.siemens-home.bsh-group.com/tr/tr/product/klimalar/AS09XVW32N
A5: AS12IVW30N | B5: Siemens Ev Tipi Klima İç Ünite, 12.000BTU, Beyaz | C5: https://www.siemens-home.bsh-group.com/tr/tr/product/klimalar/AS12XVW32N
A6: AS12IVW32N | B6: Siemens Ev Tipi Klima İç Ünite, 12.000BTU, Beyaz | C6: https://www.siemens-home.bsh-group.com/tr/tr/product/klimalar/AS12XVW32N
A7: AS12IXB32N | B7: Siemens Ev Tipi Klima İç Ünite, 12.000BTU, Siyah | C7: https://www.siemens-home.bsh-group.com/tr/tr/product/klimalar/AS12XXB32N
A8: AS12OVW30N | B8: Siemens Ev Tipi Klima Dış Ünite, 12.000BTU, Beyaz | C8: https://www.siemens-home.bsh-group.com/tr/tr/product/klimalar/AS12XVW32N
A9: AS12OVW32N | B9: Siemens Ev Tipi Klima Dış Ünite, 12.000BTU, Beyaz | C9: https://www.siemens-home.bsh-group.com/tr/tr/product/klimalar/AS12XVW32N
A10: AS12OXB32N | B10: Siemens Ev Tipi Klima Dış Ünite, 12.000BTU, Beyaz | C10: https://www.siemens-home.bsh-group.com/tr/tr/product/klimalar/AS12XXB32N
A11: AS18IVW30N | B11: Siemens Ev Tipi Klima İç Ünite, 18.000BTU, Beyaz | C11: https://www.siemens-home.bsh-group.com/tr/tr/product/klimalar/AS18XVW32N
A12: AS18IXB32N | B12: Siemens Ev Tipi Klima İç Ünite, 18.000BTU, Siyah | C12: https://www.siemens-home.bsh-group.com/tr/tr/product/klimalar/AS18XXB32N
... A550: WT47XK80TR | B550: iQ700 Isı Pompalı Kurutma Makinesi, 9kg, Beyaz | C550: https://www.siemens-home.bsh-group.com/tr/tr/product/prsiemensdryer/WT47XK80TR
