Workbook

Sheet Sayfa1
A1: STOK KODU | B1: AÇIKLAMA | C1: 17 AĞUSTOS HOROZ | D1: 17 AĞUSTOS STUDIOLINE HOROZ | E1: 17 AĞUSTOS YILDIZ DEPO | F1: CAM OFİS | G1: CAM OFİS TEŞHİR | H1: STUDIO LINE CEPA | I1: ANKAMALL | J1: CEPA | K1: OPTIMUM | L1: ONE TOWER | M1: PANORA | N1: TOPLAM STOK | O1: 7 AĞUSTOS BEKLEYEN | P1: PRİM HARİÇ ÜRÜN | Q1: AĞUSTOS TOPTAN | R1: HAVALE FİYATI | S1: TEK ÇEKİM FİYATI | T1: TAKSİTLİ FİYATI 3/6 TAKSİT | U1: AĞUSTOS BİP | V1: 30.09.2026 montaj zorunlu PHASE OUT | W1: Hakedişler LİSTE FİYATINDAN SATILIRSA geçerli olacak | X1: VARSA BİP KOŞULU | Y1: ONLINE FİYATI
A2: KA93NVL30N | B2: =IFERROR(HYPERLINK(VLOOKUP(A2,ÜRÜNLER!A:C,3,FALSE),VLOOKUP(A2,ÜRÜNLER!A:B,2,FALSE)),"") -> iQ300 Gardırop Tipi Buzdolabı, 90.8cm, Inox | J2: 1 | L2: 1 | N2: =M2+K2+L2+J2+I2+H2+G2+F2+E2+D2+C2 -> 2 | Q2: devamı yok | R2: 80000 | S2: 83200 | T2: 86400 | W2: 1000
A3: KF96RSBEA | B3: =IFERROR(HYPERLINK(VLOOKUP(A3,ÜRÜNLER!A:C,3,FALSE),VLOOKUP(A3,ÜRÜNLER!A:B,2,FALSE)),"") -> iQ700 Gardırop Tipi Buzdolabı, Cam Kapı, Alkol Çekmeceli, 90.5cm, Siyah | C3: 7 | F3: 1 | I3: 1 | J3: 1 | M3: 1 | N3: =M3+K3+L3+J3+I3+H3+G3+F3+E3+D3+C3 -> 11 | O3: 1 | Q3: 215784.17 | R3: 204994.96 | S3: 213194.76 | T3: 221394.56 | U3: 6594.3524
A4: KF96NAXEA | B4: =IFERROR(HYPERLINK(VLOOKUP(A4,ÜRÜNLER!A:C,3,FALSE),VLOOKUP(A4,ÜRÜNLER!A:B,2,FALSE)),"") -> iQ300 Gardırop Tipi Buzdolabı, 90.5cm, BlackSteel | C4: 1 | I4: 1 | J4: 1 | K4: 1 | L4: 2 | M4: 1 | N4: =M4+K4+L4+J4+I4+H4+G4+F4+E4+D4+C4 -> 7 | O4: 11 | Q4: 134806.51 | R4: 128066.18 | S4: 133188.83 | T4: 138311.48 | U4: 41230.118
A5: KF96NVPEA | B5: =IFERROR(HYPERLINK(VLOOKUP(A5,ÜRÜNLER!A:C,3,FALSE),VLOOKUP(A5,ÜRÜNLER!A:B,2,FALSE)),"") -> iQ300 Gardırop Tipi Buzdolabı, 90.5cm, Inox | C5: 32 | F5: 1 | I5: 1 | L5: 2 | N5: =M5+K5+L5+J5+I5+H5+G5+F5+E5+D5+C5 -> 36 | O5: 1 | Q5: 118087.27 | R5: 102600 | S5: 106704 | T5: 110808 | U5: 26517.502 | W5: 250
A6: KD43NNWE0N | B6: =IFERROR(HYPERLINK(VLOOKUP(A6,ÜRÜNLER!A:C,3,FALSE),VLOOKUP(A6,ÜRÜNLER!A:B,2,FALSE)),"") -> iQ100 Üstten Donduruculu Kulpsuz Buzdolabı, 70cm, Beyaz | C6: 2 | N6: =M6+K6+L6+J6+I6+H6+G6+F6+E6+D6+C6 -> 2 | P6: PRİM HARİÇ | Q6: 32404.704 | R6: 34024.939 | S6: 35385.936 | T6: 36746.934
A7: KD55NNWE0N | B7: =IFERROR(HYPERLINK(VLOOKUP(A7,ÜRÜNLER!A:C,3,FALSE),VLOOKUP(A7,ÜRÜNLER!A:B,2,FALSE)),"") -> iQ300 Üstten Donduruculu Kulpsuz Buzdolabı, 70cm, Beyaz | C7: 4 | F7: 1 | N7: =M7+K7+L7+J7+I7+H7+G7+F7+E7+D7+C7 -> 5 | P7: PRİM HARİÇ | Q7: 36619.942 | R7: 38450.939 | S7: 39988.977 | T7: 41527.015 | U7: 968.77953
A8: KD55NNLE0N | B8: =IFERROR(HYPERLINK(VLOOKUP(A8,ÜRÜNLER!A:C,3,FALSE),VLOOKUP(A8,ÜRÜNLER!A:B,2,FALSE)),"") -> iQ300 Üstten Donduruculu Kulpsuz Buzdolabı, 70cm, Inox Görünümlü | C8: 6 | N8: =M8+K8+L8+J8+I8+H8+G8+F8+E8+D8+C8 -> 6 | P8: PRİM HARİÇ | Q8: 43007.56 | R8: 45157.938 | S8: 46964.256 | T8: 48770.573 | U8: 5972.6766
A9: KD56NXWF1N | B9: =IFERROR(HYPERLINK(VLOOKUP(A9,ÜRÜNLER!A:C,3,FALSE),VLOOKUP(A9,ÜRÜNLER!A:B,2,FALSE)),"") -> iQ300 Üstten Donduruculu Kulpsuz Buzdolabı, 70cm, Beyaz | L9: 1 | N9: =M9+K9+L9+J9+I9+H9+G9+F9+E9+D9+C9 -> 1 | Q9: devamı yok | R9: 40000 | S9: 41600 | T9: 43200 | W9: 500
A10: KD76NAIE1N | B10: =IFERROR(HYPERLINK(VLOOKUP(A10,ÜRÜNLER!A:C,3,FALSE),VLOOKUP(A10,ÜRÜNLER!A:B,2,FALSE)),"") -> iQ500 Üstten Donduruculu Kulplu Buzdolabı, 75cm, Inox | C10: 12 | N10: =M10+K10+L10+J10+I10+H10+G10+F10+E10+D10+C10 -> 12 | Q10: 84535.625 | R10: 80308.843 | S10: 83521.197 | T10: 86733.551 | U10: 21128.648
A11: KD76NAWE1N | B11: =IFERROR(HYPERLINK(VLOOKUP(A11,ÜRÜNLER!A:C,3,FALSE),VLOOKUP(A11,ÜRÜNLER!A:B,2,FALSE)),"") -> iQ500 Üstten Donduruculu Kulplu Buzdolabı, 75cm, Beyaz | C11: 8 | N11: =M11+K11+L11+J11+I11+H11+G11+F11+E11+D11+C11 -> 8 | Q11: 62949.551 | R11: 59802.074 | S11: 62194.157 | T11: 64586.24 | U11: 6705.3654
A12: KD76NXIE1N | B12: =IFERROR(HYPERLINK(VLOOKUP(A12,ÜRÜNLER!A:C,3,FALSE),VLOOKUP(A12,ÜRÜNLER!A:B,2,FALSE)),"") -> iQ500 Üstten Donduruculu Kulpsuz Buzdolabı, 75cm, Inox | C12: 11 | N12: =M12+K12+L12+J12+I12+H12+G12+F12+E12+D12+C12 -> 11 | Q12: 70136.481 | R12: 66629.657 | S12: 69294.843 | T12: 71960.029 | U12: 11938.807
A13: KD76NXWE1N | B13: =IFERROR(HYPERLINK(VLOOKUP(A13,ÜRÜNLER!A:C,3,FALSE),VLOOKUP(A13,ÜRÜNLER!A:B,2,FALSE)),"") -> iQ300 Üstten Donduruculu, Kulpsuz Buzdolabı, 75cm, Beyaz | C13: 1 | I13: 1 | J13: 1 | M13: 1 | N13: =M13+K13+L13+J13+I13+H13+G13+F13+E13+D13+C13 -> 4 | O13: 6 | Q13: 64328.533 | R13: 61112.107 | S13: 63556.591 | T13: 66001.075 | U13: 16712.254
A14: KD76NXWE0N | B14: =IFERROR(HYPERLINK(VLOOKUP(A14,ÜRÜNLER!A:C,3,FALSE),VLOOKUP(A14,ÜRÜNLER!A:B,2,FALSE)),"") -> iQ300 Üstten Donduruculu Kulpsuz Buzdolabı, 75cm, Beyaz | L14: 1 | N14: =M14+K14+L14+J14+I14+H14+G14+F14+E14+D14+C14 -> 1 | Q14: devamı yok | R14: 55000 | S14: 57200 | T14: 59400 | W14: 500
A15: KD76NNWE0N | B15: =IFERROR(HYPERLINK(VLOOKUP(A15,ÜRÜNLER!A:C,3,FALSE),VLOOKUP(A15,ÜRÜNLER!A:B,2,FALSE)),"") -> iQ300 Üstten Donduruculu Kulpsuz Buzdolabı, 75cm, Beyaz | N15: =M15+K15+L15+J15+I15+H15+G15+F15+E15+D15+C15 -> 0 | O15: 3 | Q15: 56792.905 | R15: 56793 | S15: 59064.72 | T15: 61336.44
A16: KD86NAID1N | B16: =IFERROR(HYPERLINK(VLOOKUP(A16,ÜRÜNLER!A:C,3,FALSE),VLOOKUP(A16,ÜRÜNLER!A:B,2,FALSE)),"") -> iQ500 Üstten Donduruculu Kulplu Buzdolabı, 86cm, Inox | C16: 12 | E16: 1 | I16: 1 | J16: 1 | K16: 1 | N16: =M16+K16+L16+J16+I16+H16+G16+F16+E16+D16+C16 -> 16 | O16: 1 | Q16: 98053.757 | R16: 93151.069 | S16: 96877.112 | T16: 100603.16 | U16: 27646.781
A17: KD86NAWE1N | B17: =IFERROR(HYPERLINK(VLOOKUP(A17,ÜRÜNLER!A:C,3,FALSE),VLOOKUP(A17,ÜRÜNLER!A:B,2,FALSE)),"") -> iQ500 Üstten Donduruculu Kulplu Buzdolabı, 86cm, Beyaz | C17: 4 | N17: =M17+K17+L17+J17+I17+H17+G17+F17+E17+D17+C17 -> 4 | O17: 1 | Q17: 85320.531 | R17: 81054.504 | S17: 84296.684 | T17: 87538.864 | U17: 20122.856
A18: KD86NHID1N | B18: =IFERROR(HYPERLINK(VLOOKUP(A18,ÜRÜNLER!A:C,3,FALSE),VLOOKUP(A18,ÜRÜNLER!A:B,2,FALSE)),"") -> iQ500 Üstten Donduruculu Kulplu Buzdolabı, 86cm, Inox | L18: 1 | N18: =M18+K18+L18+J18+I18+H18+G18+F18+E18+D18+C18 -> 1 | Q18: devamı yok | R18: 55000 | S18: 57200 | T18: 59400 | W18: 500
A19: KG36NNLE0N | B19: =IFERROR(HYPERLINK(VLOOKUP(A19,ÜRÜNLER!A:C,3,FALSE),VLOOKUP(A19,ÜRÜNLER!A:B,2,FALSE)),"") -> iQ100 Alttan Donduruculu Kulpsuz Buzdolabı, 60cm, Inox | F19: 1 | N19: =M19+K19+L19+J19+I19+H19+G19+F19+E19+D19+C19 -> 1 | Q19: devamı yok | R19: 40000 | S19: 41600 | T19: 43200 | W19: 250
A20: KG55NCIE0N | B20: =IFERROR(HYPERLINK(VLOOKUP(A20,ÜRÜNLER!A:C,3,FALSE),VLOOKUP(A20,ÜRÜNLER!A:B,2,FALSE)),"") -> iQ300 Alttan Donduruculu Kulpsuz Buzdolabı, 70cm, Inox | C20: 84 | E20: 4 | I20: 1 | J20: 1 | L20: 1 | M20: 1 | N20: =M20+K20+L20+J20+I20+H20+G20+F20+E20+D20+C20 -> 92 | O20: 3 | Q20: 65373.711 | R20: 65373.711 | S20: 67988.659 | T20: 70603.608 | U20: 16210.92 | Y20: 54300
A21: KG55NCWE0N | B21: =IFERROR(HYPERLINK(VLOOKUP(A21,ÜRÜNLER!A:C,3,FALSE),VLOOKUP(A21,ÜRÜNLER!A:B,2,FALSE)),"") -> iQ300 Alttan Donduruculu Kulpsuz Buzdolabı, 70cm, Beyaz | C21: 83 | I21: 1 | K21: 1 | L21: 2 | N21: =M21+K21+L21+J21+I21+H21+G21+F21+E21+D21+C21 -> 87 | O21: 5 | Q21: 60461.405 | R21: 60461.405 | S21: 62879.861 | T21: 65298.317 | U21: 11705.591 | Y21: 53800
A22: KG55NVIE0N | B22: =IFERROR(HYPERLINK(VLOOKUP(A22,ÜRÜNLER!A:C,3,FALSE),VLOOKUP(A22,ÜRÜNLER!A:B,2,FALSE)),"") -> iQ300 Alttan Donduruculu Kulpsuz Buzdolabı, 70cm, Inox | C22: 6 | E22: 1 | L22: 1 | N22: =M22+K22+L22+J22+I22+H22+G22+F22+E22+D22+C22 -> 8 | Q22: devamı yok | R22: 50000 | S22: 52000 | T22: 54000 | U22: 8118.2663
A23: KG55NVWE0N | B23: =IFERROR(HYPERLINK(VLOOKUP(A23,ÜRÜNLER!A:C,3,FALSE),VLOOKUP(A23,ÜRÜNLER!A:B,2,FALSE)),"") -> iQ300 Alttan Donduruculu Kulpsuz Buzdolabı, 70cm, Beyaz | E23: 1 | I23: 1 | L23: 1 | N23: =M23+K23+L23+J23+I23+H23+G23+F23+E23+D23+C23 -> 3 | Q23: devamı yok | R23: 44000 | S23: 45760 | T23: 47520 | U23: 6729.5716 | W23: 500
A24: KG56NLBE0N | B24: =IFERROR(HYPERLINK(VLOOKUP(A24,ÜRÜNLER!A:C,3,FALSE),VLOOKUP(A24,ÜRÜNLER!A:B,2,FALSE)),"") -> iQ500 Alttan Donduruculu Kulpsuz Buzdolabı, 70cm, Parlak Siyah | F24: 1 | I24: 2 | J24: 1 | K24: 1 | M24: 2 | N24: =M24+K24+L24+J24+I24+H24+G24+F24+E24+D24+C24 -> 7 | O24: 11 | Q24: 59227.138 | R24: 56265.782 | S24: 58516.413 | T24: 60767.044
A25: KG56NQWF0N | B25: =IFERROR(HYPERLINK(VLOOKUP(A25,ÜRÜNLER!A:C,3,FALSE),VLOOKUP(A25,ÜRÜNLER!A:B,2,FALSE)),"") -> iQ500 Alttan Donduruculu Kulpsuz Buzdolabı, 70cm, Seramik Desen | J25: 1 | N25: =M25+K25+L25+J25+I25+H25+G25+F25+E25+D25+C25 -> 1 | Q25: devamı yok | R25: 48000 | S25: 49920 | T25: 51840 | W25: 500
A26: KG56NTEE0N | B26: =IFERROR(HYPERLINK(VLOOKUP(A26,ÜRÜNLER!A:C,3,FALSE),VLOOKUP(A26,ÜRÜNLER!A:B,2,FALSE)),"") -> iQ500 Alttan Donduruculu Kulpsuz Buzdolabı, 70cm, Mat Siyah | F26: 1 | N26: =M26+K26+L26+J26+I26+H26+G26+F26+E26+D26+C26 -> 1 | Q26: devamı yok | R26: 48000 | S26: 49920 | T26: 51840 | W26: 500
A27: KG56NTWE0N | B27: =IFERROR(HYPERLINK(VLOOKUP(A27,ÜRÜNLER!A:C,3,FALSE),VLOOKUP(A27,ÜRÜNLER!A:B,2,FALSE)),"") -> iQ500 Alttan Donduruculu Kulpsuz Buzdolabı, 70cm, Seramik Desen | L27: 1 | N27: =M27+K27+L27+J27+I27+H27+G27+F27+E27+D27+C27 -> 1 | Q27: devamı yok | R27: 48000 | S27: 49920 | T27: 51840 | W27: 500
A28: KG56NNWD0N | B28: =IFERROR(HYPERLINK(VLOOKUP(A28,ÜRÜNLER!A:C,3,FALSE),VLOOKUP(A28,ÜRÜNLER!A:B,2,FALSE)),"") -> iQ100 Alttan Donduruculu Kulpsuz Buzdolabı, 70cm, Beyaz (Wi-Fi) | C28: 32 | N28: =M28+K28+L28+J28+I28+H28+G28+F28+E28+D28+C28 -> 32 | O28: 21 | Q28: 41395.9 | R28: 39326.105 | S28: 40899.149 | T28: 42472.193
A29: KG56NVPD0N | B29: =IFERROR(HYPERLINK(VLOOKUP(A29,ÜRÜNLER!A:C,3,FALSE),VLOOKUP(A29,ÜRÜNLER!A:B,2,FALSE)),"") -> iQ300 Alttan Donduruculu Kulpsuz Buzdolabı, 70cm, Inox (Wi-Fi) | C29: 35 | I29: 1 | N29: =M29+K29+L29+J29+I29+H29+G29+F29+E29+D29+C29 -> 36 | O29: 24 | Q29: 49000.063 | R29: 46550.06 | S29: 48412.062 | T29: 50274.065 | U29: 325.64437
A30: KG56NVWD0N | B30: =IFERROR(HYPERLINK(VLOOKUP(A30,ÜRÜNLER!A:C,3,FALSE),VLOOKUP(A30,ÜRÜNLER!A:B,2,FALSE)),"") -> iQ300 Alttan Donduruculu Kulpsuz Buzdolabı, 70cm, Beyaz (Wi-Fi) | C30: 33 | N30: =M30+K30+L30+J30+I30+H30+G30+F30+E30+D30+C30 -> 33 | O30: 21 | Q30: 45360.936 | R30: 43092.89 | S30: 44816.605 | T30: 46540.321
A31: KG56NCID0N | B31: =IFERROR(HYPERLINK(VLOOKUP(A31,ÜRÜNLER!A:C,3,FALSE),VLOOKUP(A31,ÜRÜNLER!A:B,2,FALSE)),"") -> iQ300 Alttan Donduruculu Kulpsuz Buzdolabı, 70cm, Inox (Wi-Fi) | N31: =M31+K31+L31+J31+I31+H31+G31+F31+E31+D31+C31 -> 0 | O31: 5 | Q31: 60254.001 | R31: 60254.001 | S31: 62664.161 | T31: 65074.321
A32: KG56NCWD0N | B32: =IFERROR(HYPERLINK(VLOOKUP(A32,ÜRÜNLER!A:C,3,FALSE),VLOOKUP(A32,ÜRÜNLER!A:B,2,FALSE)),"") -> iQ300 Alttan Donduruculu Kulpsuz Buzdolabı, 70cm, Beyaz (Wi-Fi) | N32: =M32+K32+L32+J32+I32+H32+G32+F32+E32+D32+C32 -> 0 | O32: 5 | Q32: 55360.41 | R32: 55360.41 | S32: 57574.827 | T32: 59789.243
A33: KG56NCXD0N | B33: =IFERROR(HYPERLINK(VLOOKUP(A33,ÜRÜNLER!A:C,3,FALSE),VLOOKUP(A33,ÜRÜNLER!A:B,2,FALSE)),"") -> iQ300 Alttan Donduruculu Kulpsuz Buzdolabı, 70cm, Black Inox (Wi-Fi) | N33: =M33+K33+L33+J33+I33+H33+G33+F33+E33+D33+C33 -> 0 | O33: 5 | Q33: 63899.365 | R33: 63899.365 | S33: 66455.34 | T33: 69011.315
A34: KG76APIE0N | B34: =IFERROR(HYPERLINK(VLOOKUP(A34,ÜRÜNLER!A:C,3,FALSE),VLOOKUP(A34,ÜRÜNLER!A:B,2,FALSE)),"") -> iQ700 Alttan Donduruculu Kulplu Buzdolabı, 75cm, Inox | C34: 14 | N34: =M34+K34+L34+J34+I34+H34+G34+F34+E34+D34+C34 -> 14 | Q34: 84646.164 | R34: 80413.856 | S34: 83630.41 | T34: 86846.965 | U34: 9762.4435
A35: KG76NCIE0N | B35: =IFERROR(HYPERLINK(VLOOKUP(A35,ÜRÜNLER!A:C,3,FALSE),VLOOKUP(A35,ÜRÜNLER!A:B,2,FALSE)),"") -> iQ500 Alttan Donduruculu Kulplu Buzdolabı, 75cm, Inox | C35: 1 | F35: 2 | I35: 1 | J35: 1 | K35: 1 | L35: 3 | M35: 1 | N35: =M35+K35+L35+J35+I35+H35+G35+F35+E35+D35+C35 -> 10 | O35: 21 | Q35: 89337.569 | R35: 84870.691 | S35: 88265.519 | T35: 91660.346 | U35: 26744.546
A36: KG76NCWE0N | B36: =IFERROR(HYPERLINK(VLOOKUP(A36,ÜRÜNLER!A:C,3,FALSE),VLOOKUP(A36,ÜRÜNLER!A:B,2,FALSE)),"") -> iQ500 Alttan Donduruculu Kulplu Buzdolabı, 75cm, Beyaz | C36: 41 | I36: 1 | L36: 1 | N36: =M36+K36+L36+J36+I36+H36+G36+F36+E36+D36+C36 -> 43 | O36: 1 | Q36: 80897.296 | R36: 75234.485 | S36: 78243.865 | T36: 81253.244 | U36: 18955.435
A37: KG76NCXE0N | B37: =IFERROR(HYPERLINK(VLOOKUP(A37,ÜRÜNLER!A:C,3,FALSE),VLOOKUP(A37,ÜRÜNLER!A:B,2,FALSE)),"") -> iQ500 Alttan Donduruculu Kulpsuz Buzdolabı, 75cm, darkSteel | C37: 11 | I37: 1 | J37: 1 | M37: 1 | N37: =M37+K37+L37+J37+I37+H37+G37+F37+E37+D37+C37 -> 14 | O37: 119 | Q37: 99433.9 | R37: 94462.205 | S37: 98240.693 | T37: 102019.18 | U37: 30980.412
A38: KG76NVIE0N | B38: =IFERROR(HYPERLINK(VLOOKUP(A38,ÜRÜNLER!A:C,3,FALSE),VLOOKUP(A38,ÜRÜNLER!A:B,2,FALSE)),"") -> iQ300 Alttan Donduruculu Kulpsuz Buzdolabı, 75cm, Inox | C38: 37 | G38: 1 | I38: 1 | L38: 2 | N38: =M38+K38+L38+J38+I38+H38+G38+F38+E38+D38+C38 -> 41 | O38: 1 | Q38: 80743.426 | R38: 75091.386 | S38: 78095.042 | T38: 81098.697 | U38: 19696.914
A39: KG76NVWE0N | B39: =IFERROR(HYPERLINK(VLOOKUP(A39,ÜRÜNLER!A:C,3,FALSE),VLOOKUP(A39,ÜRÜNLER!A:B,2,FALSE)),"") -> iQ300 Alttan Donduruculu Kulpsuz Buzdolabı, 75cm, Beyaz | C39: 32 | I39: 1 | J39: 1 | M39: 1 | N39: =M39+K39+L39+J39+I39+H39+G39+F39+E39+D39+C39 -> 35 | O39: 1 | Q39: 72507.334 | R39: 68881.968 | S39: 71637.246 | T39: 74392.525 | U39: 20821.288
A40: KG76PAIC0N | B40: =IFERROR(HYPERLINK(VLOOKUP(A40,ÜRÜNLER!A:C,3,FALSE),VLOOKUP(A40,ÜRÜNLER!A:B,2,FALSE)),"") -> iQ700 Alttan Donduruculu Kulplu Buzdolabı, 75cm, Inox | C40: 47 | E40: 2 | F40: 1 | I40: 1 | J40: 1 | M40: 1 | N40: =M40+K40+L40+J40+I40+H40+G40+F40+E40+D40+C40 -> 53 | O40: 1 | Q40: 93563.754 | R40: 88885.567 | S40: 92440.989 | T40: 95996.412 | U40: 18924.219
...

Sheet HESAPLAYICI
A1: =Sayfa1!A1 -> STOK KODU | B1: =Sayfa1!B1 -> AÇIKLAMA | C1: =Sayfa1!C1 -> 17 AĞUSTOS HOROZ | D1: =Sayfa1!$S$1 -> TEK ÇEKİM FİYATI | E1: =Sayfa1!$T$1 -> TAKSİTLİ FİYATI 3/6 TAKSİT | F1: =Sayfa1!$U$1 -> AĞUSTOS BİP | G1: =Sayfa1!$V$1 -> 30.09.2026 montaj zorunlu PHASE OUT | H1: =Sayfa1!$W$1 -> Hakedişler LİSTE FİYATINDAN SATILIRSA geçerli olacak | I1: Toplam Bundle İndirim Tutarını Aşağıya Yaz | J1: =Sayfa1!$Y$1 -> ONLINE FİYATI | K1: =Sayfa1!$X$1 -> VARSA BİP KOŞULU | L1: BİP KOŞULU
A2: HB534FER0T | B2: =IFERROR(VLOOKUP(A2,Sayfa1!A:B,2,FALSE),"?") -> iQ300 Ankastre Fırın, 1 Teleskopik Ray, Arkası Kendini Temizler, Siyah/Inox | C2: =IFERROR(VLOOKUP(A2,Sayfa1!A:C,3,FALSE),"?") -> 0 | D2: =IFERROR(VLOOKUP(A2,Sayfa1!$A:$S,17,FALSE),"?") -> devamı yok | E2: =IFERROR(VLOOKUP(A2,Sayfa1!$A:$T,18,FALSE),"?") -> 18607 | F2: =IFERROR(VLOOKUP(A2,Sayfa1!$A:$U,19,FALSE),"?") -> 19351.28 | G2: =IFERROR(VLOOKUP(A2,Sayfa1!$A:$V,20,FALSE),"?") -> 20095.56 | H2: =IFERROR(VLOOKUP(A2,Sayfa1!$A:$W,21,FALSE),"?") -> 0 | J2: =IFERROR(VLOOKUP(A2,Sayfa1!$A:$Y,23,FALSE),"?") -> 500 | K2: =IFERROR(VLOOKUP(A2,Sayfa1!$A:$X,22,FALSE),"?") -> 1606.584 | L2: =IFERROR(VLOOKUP(A2,Sayfa1!$A:$Z,24,FALSE),"?") -> 0
B3: =IFERROR(VLOOKUP(A3,Sayfa1!A:B,2,FALSE),"?") -> ? | C3: =IFERROR(VLOOKUP(A3,Sayfa1!A:C,3,FALSE),"?") -> ? | D3: =IFERROR(VLOOKUP(A3,Sayfa1!$A:$S,17,FALSE),"?") -> ? | E3: =IFERROR(VLOOKUP(A3,Sayfa1!$A:$T,18,FALSE),"?") -> ? | F3: =IFERROR(VLOOKUP(A3,Sayfa1!$A:$U,19,FALSE),"?") -> ? | G3: =IFERROR(VLOOKUP(A3,Sayfa1!$A:$V,20,FALSE),"?") -> ? | H3: =IFERROR(VLOOKUP(A3,Sayfa1!$A:$W,21,FALSE),"?") -> ? | J3: =IFERROR(VLOOKUP(A3,Sayfa1!$A:$Y,23,FALSE),"?") -> ? | K3: =IFERROR(VLOOKUP(A3,Sayfa1!$A:$X,22,FALSE),"?") -> ? | L3: =IFERROR(VLOOKUP(A3,Sayfa1!$A:$Z,24,FALSE),"?") -> ?
B4: =IFERROR(VLOOKUP(A4,Sayfa1!A:B,2,FALSE),"?") -> ? | C4: =IFERROR(VLOOKUP(A4,Sayfa1!A:C,3,FALSE),"?") -> ? | D4: =IFERROR(VLOOKUP(A4,Sayfa1!$A:$S,17,FALSE),"?") -> ? | E4: =IFERROR(VLOOKUP(A4,Sayfa1!$A:$T,18,FALSE),"?") -> ? | F4: =IFERROR(VLOOKUP(A4,Sayfa1!$A:$U,19,FALSE),"?") -> ? | G4: =IFERROR(VLOOKUP(A4,Sayfa1!$A:$V,20,FALSE),"?") -> ? | H4: =IFERROR(VLOOKUP(A4,Sayfa1!$A:$W,21,FALSE),"?") -> ? | J4: =IFERROR(VLOOKUP(A4,Sayfa1!$A:$Y,23,FALSE),"?") -> ? | K4: =IFERROR(VLOOKUP(A4,Sayfa1!$A:$X,22,FALSE),"?") -> ? | L4: =IFERROR(VLOOKUP(A4,Sayfa1!$A:$Z,24,FALSE),"?") -> ?
B5: =IFERROR(VLOOKUP(A5,Sayfa1!A:B,2,FALSE),"?") -> ? | C5: =IFERROR(VLOOKUP(A5,Sayfa1!A:C,3,FALSE),"?") -> ? | D5: =IFERROR(VLOOKUP(A5,Sayfa1!$A:$S,17,FALSE),"?") -> ? | E5: =IFERROR(VLOOKUP(A5,Sayfa1!$A:$T,18,FALSE),"?") -> ? | F5: =IFERROR(VLOOKUP(A5,Sayfa1!$A:$U,19,FALSE),"?") -> ? | G5: =IFERROR(VLOOKUP(A5,Sayfa1!$A:$V,20,FALSE),"?") -> ? | H5: =IFERROR(VLOOKUP(A5,Sayfa1!$A:$W,21,FALSE),"?") -> ? | J5: =IFERROR(VLOOKUP(A5,Sayfa1!$A:$Y,23,FALSE),"?") -> ? | K5: =IFERROR(VLOOKUP(A5,Sayfa1!$A:$X,22,FALSE),"?") -> ? | L5: =IFERROR(VLOOKUP(A5,Sayfa1!$A:$Z,24,FALSE),"?") -> ?
B6: =IFERROR(VLOOKUP(A6,Sayfa1!A:B,2,FALSE),"?") -> ? | C6: =IFERROR(VLOOKUP(A6,Sayfa1!A:C,3,FALSE),"?") -> ? | D6: =IFERROR(VLOOKUP(A6,Sayfa1!$A:$S,17,FALSE),"?") -> ? | E6: =IFERROR(VLOOKUP(A6,Sayfa1!$A:$T,18,FALSE),"?") -> ? | F6: =IFERROR(VLOOKUP(A6,Sayfa1!$A:$U,19,FALSE),"?") -> ? | G6: =IFERROR(VLOOKUP(A6,Sayfa1!$A:$V,20,FALSE),"?") -> ? | H6: =IFERROR(VLOOKUP(A6,Sayfa1!$A:$W,21,FALSE),"?") -> ? | J6: =IFERROR(VLOOKUP(A6,Sayfa1!$A:$Y,23,FALSE),"?") -> ? | K6: =IFERROR(VLOOKUP(A6,Sayfa1!$A:$X,22,FALSE),"?") -> ? | L6: =IFERROR(VLOOKUP(A6,Sayfa1!$A:$Z,24,FALSE),"?") -> ?
B7: =IFERROR(VLOOKUP(A7,Sayfa1!A:B,2,FALSE),"?") -> ? | C7: =IFERROR(VLOOKUP(A7,Sayfa1!A:C,3,FALSE),"?") -> ? | D7: =IFERROR(VLOOKUP(A7,Sayfa1!$A:$S,17,FALSE),"?") -> ? | E7: =IFERROR(VLOOKUP(A7,Sayfa1!$A:$T,18,FALSE),"?") -> ? | F7: =IFERROR(VLOOKUP(A7,Sayfa1!$A:$U,19,FALSE),"?") -> ? | G7: =IFERROR(VLOOKUP(A7,Sayfa1!$A:$V,20,FALSE),"?") -> ? | H7: =IFERROR(VLOOKUP(A7,Sayfa1!$A:$W,21,FALSE),"?") -> ? | J7: =IFERROR(VLOOKUP(A7,Sayfa1!$A:$Y,23,FALSE),"?") -> ? | K7: =IFERROR(VLOOKUP(A7,Sayfa1!$A:$X,22,FALSE),"?") -> ? | L7: =IFERROR(VLOOKUP(A7,Sayfa1!$A:$Z,24,FALSE),"?") -> ?
B8: =IFERROR(VLOOKUP(A8,Sayfa1!A:B,2,FALSE),"?") -> ? | C8: =IFERROR(VLOOKUP(A8,Sayfa1!A:C,3,FALSE),"?") -> ? | D8: =IFERROR(VLOOKUP(A8,Sayfa1!$A:$S,17,FALSE),"?") -> ? | E8: =IFERROR(VLOOKUP(A8,Sayfa1!$A:$T,18,FALSE),"?") -> ? | F8: =IFERROR(VLOOKUP(A8,Sayfa1!$A:$U,19,FALSE),"?") -> ? | G8: =IFERROR(VLOOKUP(A8,Sayfa1!$A:$V,20,FALSE),"?") -> ? | H8: =IFERROR(VLOOKUP(A8,Sayfa1!$A:$W,21,FALSE),"?") -> ? | J8: =IFERROR(VLOOKUP(A8,Sayfa1!$A:$Y,23,FALSE),"?") -> ? | K8: =IFERROR(VLOOKUP(A8,Sayfa1!$A:$X,22,FALSE),"?") -> ? | L8: =IFERROR(VLOOKUP(A8,Sayfa1!$A:$Z,24,FALSE),"?") -> ?
B9: =IFERROR(VLOOKUP(A9,Sayfa1!A:B,2,FALSE),"?") -> ? | C9: =IFERROR(VLOOKUP(A9,Sayfa1!A:C,3,FALSE),"?") -> ? | D9: =IFERROR(VLOOKUP(A9,Sayfa1!$A:$S,17,FALSE),"?") -> ? | E9: =IFERROR(VLOOKUP(A9,Sayfa1!$A:$T,18,FALSE),"?") -> ? | F9: =IFERROR(VLOOKUP(A9,Sayfa1!$A:$U,19,FALSE),"?") -> ? | G9: =IFERROR(VLOOKUP(A9,Sayfa1!$A:$V,20,FALSE),"?") -> ? | H9: =IFERROR(VLOOKUP(A9,Sayfa1!$A:$W,21,FALSE),"?") -> ? | J9: =IFERROR(VLOOKUP(A9,Sayfa1!$A:$Y,23,FALSE),"?") -> ? | K9: =IFERROR(VLOOKUP(A9,Sayfa1!$A:$X,22,FALSE),"?") -> ? | L9: =IFERROR(VLOOKUP(A9,Sayfa1!$A:$Z,24,FALSE),"?") -> ?
B10: =IFERROR(VLOOKUP(A10,Sayfa1!A:B,2,FALSE),"?") -> ? | C10: =IFERROR(VLOOKUP(A10,Sayfa1!A:C,3,FALSE),"?") -> ? | D10: =IFERROR(VLOOKUP(A10,Sayfa1!$A:$S,17,FALSE),"?") -> ? | E10: =IFERROR(VLOOKUP(A10,Sayfa1!$A:$T,18,FALSE),"?") -> ? | F10: =IFERROR(VLOOKUP(A10,Sayfa1!$A:$U,19,FALSE),"?") -> ? | G10: =IFERROR(VLOOKUP(A10,Sayfa1!$A:$V,20,FALSE),"?") -> ? | H10: =IFERROR(VLOOKUP(A10,Sayfa1!$A:$W,21,FALSE),"?") -> ? | J10: =IFERROR(VLOOKUP(A10,Sayfa1!$A:$Y,23,FALSE),"?") -> ? | K10: =IFERROR(VLOOKUP(A10,Sayfa1!$A:$X,22,FALSE),"?") -> ? | L10: =IFERROR(VLOOKUP(A10,Sayfa1!$A:$Z,24,FALSE),"?") -> ?
B11: =IFERROR(VLOOKUP(A11,Sayfa1!A:B,2,FALSE),"?") -> ? | C11: =IFERROR(VLOOKUP(A11,Sayfa1!A:C,3,FALSE),"?") -> ? | D11: =IFERROR(VLOOKUP(A11,Sayfa1!$A:$S,17,FALSE),"?") -> ? | E11: =IFERROR(VLOOKUP(A11,Sayfa1!$A:$T,18,FALSE),"?") -> ? | F11: =IFERROR(VLOOKUP(A11,Sayfa1!$A:$U,19,FALSE),"?") -> ? | G11: =IFERROR(VLOOKUP(A11,Sayfa1!$A:$V,20,FALSE),"?") -> ? | H11: =IFERROR(VLOOKUP(A11,Sayfa1!$A:$W,21,FALSE),"?") -> ? | J11: =IFERROR(VLOOKUP(A11,Sayfa1!$A:$Y,23,FALSE),"?") -> ? | K11: =IFERROR(VLOOKUP(A11,Sayfa1!$A:$X,22,FALSE),"?") -> ? | L11: =IFERROR(VLOOKUP(A11,Sayfa1!$A:$Z,24,FALSE),"?") -> ?
A12: Toplam Satış Fiyatı | E12: =SUM(E2:E11) -> 18607 | F12: =SUM(F2:F11) -> 19351.28
A13: BİP İndirimi | E13: =SUM(G:G)*-1 -> -20095.56 | F13: =SUM(G:G)*-1 -> -20095.56
A14: PhaseOut İndirimi | E14: =SUM(H:H)*-1 -> 0 | F14: =SUM(H:H)*-1 -> 0
A15: Toplam Bundle İndirimi | E15: =I2*-1 -> 0 | F15: =I2*-1 -> 0
A16: Satılabilir Minimum Fiyat | E16: =SUM(E12:E15) -> -1488.56 | F16: =SUM(F12:F15) -> -744.28
A17: Satılabilir Minimum Taksitli Fiyat | E17: =E16*1.08 -> -1607.6448

Sheet Bundle Kampanya
K3: Seçili Ankastre Set Alımına perakende de 5.000 TL İndirim! | L3: Geçerli Ankastre Fırınlar
C5: 2'li LDA alımında perakende de 5.000 TL İndirim! | D5: 2’li LDA alımında perakende de 5.000 ₺ indirim uygulanır. “diğer kampanyalar ile birleşemez” 4.000 ₺ kdv dahil fiyat farkı hak edişi ödenecektir. (Buzdolabı-Çamaşır-Bulaşık-Kurutma-Derin Dondurucu) (XL-XXL Buzdolapları hariç) | L5: HB012FBH1T, HB012FBB1T, HB012FBW1T + (phase out iQ300 ve iQ500 segment modeller) Ankastre fırınlarda geçerlidir.
L9: Uygulama koşulları : Seçili ankastre fırınlar ile set (fırın+ocak+dav.) set alana perakende de 5.000 ₺ indirim uygulanır. Diğer fırınlarda geçerli değildir. KDV dahil 3.700 ₺ hak ediş ödenir. Giriş setlerde( HB011* ve giriş segment muadili fırın modelleri, EB6C5PK80O - EB6C5PB82O ocak, LC64PCC20T - LC64PCC50T - LC64PCC60T davlumbaz modelleri) geçerli değildir.
K17: Seçili Fırınlarla Ankastre set alana perakende de LC63KPJ60T Davlumbaz Hediye! | L17: Geçerli Ankastre Setler
L19: HB557JEB6T, HB734G1B1, HB776G1B1, HB778G3B1, HR776G3B1, HS736G1B2, VB558C0S0, CM724G1B1, HJ852GYB0T, HJ852GYN0T, HJ852GYW0T, HU736AEN0T, HU736AEA0T, HU736AEV0T, HU736AEG0T, HR232GEB3, HU717ABN0T, HU717ABA0T, HU717ABV0T, CD714GXB1
L23: Uygulama koşulları : Seçili ankastre fırınlar ile set (fırın+ocak+dav.) set alana perakende de 12.400 ₺ indirim uygulanır. KDV dahil 9.400 ₺ hak ediş ödenir. Giriş setlerde( HB011* ve giriş segment muadili fırın modelleri, EB6C5PK80O - EB6C5PB82O ocak, LC64PCC20T - LC64PCC50T - LC64PCC60T davlumbaz modelleri) geçerli değildir.

Sheet ÜRÜNLER
A1: Ürün No | B1: Ürün Adı | C1: Ürün Linki | D1: Ürün Grubu | E1: Marka
A2: 50PUS8009/62 | B2: Philips 50" 4K Ambilight LED TV (Titan OS) (50PUS8009/62) | C2: https://www.philips.com.tr/c-p/50PUS8009_62/led-50pus8009-4k-ambilight-tv | D2: Televizyon | E2: Philips
A3: 55PUS8349/62 | B3: Philips 55" 4K Ambilight LED TV (Titan OS) (55PUS8349/62) | C3: https://www.philips.com.tr/c-p/55PUS8349_62/led-55pus8349-4k-ambilight-tv | D3: Televizyon | E3: Philips
A4: AS09IVW32N | B4: Siemens Ev Tipi Klima İç Ünite, 9.000BTU, Beyaz | C4: https://www.siemens-home.bsh-group.com/tr/tr/product/klimalar/AS09XVW32N | D4: Klima | E4: Siemens
A5: AS09OVW32N | B5: Siemens Ev Tipi Klima Dış Ünite, 9.000BTU, Beyaz | C5: https://www.siemens-home.bsh-group.com/tr/tr/product/klimalar/AS09XVW32N | D5: Klima | E5: Siemens
A6: AS12IVW30N | B6: Siemens Ev Tipi Klima İç Ünite, 12.000BTU, Beyaz | C6: https://www.siemens-home.bsh-group.com/tr/tr/product/klimalar/AS12XVW32N | D6: Klima | E6: Siemens
A7: AS12IVW32N | B7: Siemens Ev Tipi Klima İç Ünite, 12.000BTU, Beyaz | C7: https://www.siemens-home.bsh-group.com/tr/tr/product/klimalar/AS12XVW32N | D7: Klima | E7: Siemens
A8: AS12IXB32N | B8: Siemens Ev Tipi Klima İç Ünite, 12.000BTU, Siyah | C8: https://www.siemens-home.bsh-group.com/tr/tr/product/klimalar/AS12XXB32N | D8: Klima | E8: Siemens
A9: AS12OVW30N | B9: Siemens Ev Tipi Klima Dış Ünite, 12.000BTU, Beyaz | C9: https://www.siemens-home.bsh-group.com/tr/tr/product/klimalar/AS12XVW32N | D9: Klima | E9: Siemens
A10: AS12OVW32N | B10: Siemens Ev Tipi Klima Dış Ünite, 12.000BTU, Beyaz | C10: https://www.siemens-home.bsh-group.com/tr/tr/product/klimalar/AS12XVW32N | D10: Klima | E10: Siemens
A11: AS12OXB32N | B11: Siemens Ev Tipi Klima Dış Ünite, 12.000BTU, Beyaz | C11: https://www.siemens-home.bsh-group.com/tr/tr/product/klimalar/AS12XXB32N | D11: Klima | E11: Siemens
A12: AS18IVW30N | B12: Siemens Ev Tipi Klima İç Ünite, 18.000BTU, Beyaz | C12: https://www.siemens-home.bsh-group.com/tr/tr/product/klimalar/AS18XVW32N | D12: Klima | E12: Siemens
... A633: EP6A2PI40O | B633: iQ500 Gazlı Ocak, 60cm, Sert Cam, Beyaz, Döküm | C633: https://www.siemens-home.bsh-group.com/tr/tr/product/pisirme-grubu/ocaklar/gazli-ocaklar/EP6A2PI40O | D633: Ocak | E633: Siemens
A634: TP605EM3 | B634: EQ600 iAroma Tam Otomatik Kahve Makinesi, Siyah/Inox | D634: Kahve Makinesi | E634: Siemens
A635: TP607ET5 | B635: EQ600 iAroma Tam Otomatik Kahve Makinesi, Siyah/Dark Inox | C635: https://www.siemens-home.bsh-group.com/tr/tr/product/kahve-makineleri/tam-otomatik-kahve-makineleri/coffeemachinesautomatedfreestandingeq600/TP607ET5 | D635: Kahve Makinesi | E635: Siemens
A636: TP601E01 | B636: EQ600 iAroma Tam Otomatik Kahve Makinesi, Sabah Sisi Grisi | C636: https://www.siemens-home.bsh-group.com/tr/tr/product/kahve-makineleri/tam-otomatik-kahve-makineleri/coffeemachinesautomatedfreestandingeq600/TP601E01 | D636: Kahve Makinesi | E636: Siemens
