Workbook

Sheet Sayfa1
A1: STOK KODU | B1: AÇIKLAMA | C1: 30 Mart HOROZ | D1: 30 MART Studioline HOROZ | E1: 19 MART YILDIZ DEPO | F1: CAM OFİS | G1: İNTERNET DEPO | H1: STUDIO LINE CEPA | I1: ANKAMALL | J1: CEPA | K1: ONE TOWER | L1: PANORA | M1: VEGA | N1: TOPLAM STOK | O1: 13 MART BEKLEYEN | P1: PRİM HARİÇ ÜRÜN | Q1: MART TOPTAN | R1: HAVALE FİYATI | S1: TEK ÇEKİM FİYATI | T1: MART BİP | U1: Phase out ürünler 30.04.2026 montaj ZORUNLU | V1: Hakedişler LİSTE FİYATINDAN SATILIRSA geçerli olacak | W1: PREMİUM 4 LÜ ÜRÜN ALIMINDA 27.000 TL İNDİRİM | X1: ONLINE FİYAT
A2: KA93NVL30N | B2: =IFERROR(HYPERLINK(VLOOKUP(A2,ÜRÜNLER!A:C,3,FALSE),VLOOKUP(A2,ÜRÜNLER!A:B,2,FALSE)),"") -> iQ300 Gardırop Tipi Buzdolabı, 90.8cm, Inox | J2: 1 | K2: 1 | N2: =SUM(C2:M2) -> 2 | Q2: devamı yok | R2: 70000 | S2: 72800 | V2: 250
A3: KF96RSBEA | B3: =IFERROR(HYPERLINK(VLOOKUP(A3,ÜRÜNLER!A:C,3,FALSE),VLOOKUP(A3,ÜRÜNLER!A:B,2,FALSE)),"") -> iQ700 Gardırop Tipi Buzdolabı, Cam Kapı, Alkol Çekmeceli, 90.5cm, Siyah | C3: 6 | J3: 1 | L3: 1 | N3: =SUM(C3:M3) -> 8 | O3: 1 | Q3: 210521.14 | R3: 199995.08 | S3: 207994.89 | W3: PREMIUM 4 LÜ SET
A4: KF96NAXEA | B4: =IFERROR(HYPERLINK(VLOOKUP(A4,ÜRÜNLER!A:C,3,FALSE),VLOOKUP(A4,ÜRÜNLER!A:B,2,FALSE)),"") -> iQ300 Gardırop Tipi Buzdolabı, 90.5cm, BlackSteel | C4: 7 | I4: 1 | J4: 1 | K4: 2 | L4: 1 | N4: =SUM(C4:M4) -> 12 | O4: 35 | Q4: 128387.15 | R4: 124535.53 | S4: 129516.96 | T4: 34502.89 | W4: PREMIUM 4 LÜ SET
A5: KF96NVPEA | B5: =IFERROR(HYPERLINK(VLOOKUP(A5,ÜRÜNLER!A:C,3,FALSE),VLOOKUP(A5,ÜRÜNLER!A:B,2,FALSE)),"") -> iQ300 Gardırop Tipi Buzdolabı, 90.5cm, Inox | C5: 5 | I5: 1 | K5: 2 | N5: =SUM(C5:M5) -> 8 | O5: 16 | Q5: 113545.45 | R5: 110139.09 | S5: 114544.65 | T5: 20657.079 | W5: PREMIUM 4 LÜ SET
A6: KD43NNWE0N | B6: =IFERROR(HYPERLINK(VLOOKUP(A6,ÜRÜNLER!A:C,3,FALSE),VLOOKUP(A6,ÜRÜNLER!A:B,2,FALSE)),"") -> iQ100 Üstten Donduruculu Kulpsuz Buzdolabı, 70cm, Beyaz | C6: 3 | N6: =SUM(C6:M6) -> 3 | P6: PRİM HARİÇ | Q6: 30401.26 | R6: 30401.26 | S6: 31617.311
A7: KD55NNWE0N | B7: =IFERROR(HYPERLINK(VLOOKUP(A7,ÜRÜNLER!A:C,3,FALSE),VLOOKUP(A7,ÜRÜNLER!A:B,2,FALSE)),"") -> iQ300 Üstten Donduruculu Kulpsuz Buzdolabı, 70cm, Beyaz | C7: 5 | N7: =SUM(C7:M7) -> 5 | O7: 2 | Q7: 34025.498 | R7: 33004.733 | S7: 34324.922 | T7: 1491.7772
A8: KD55NNLE0N | B8: =IFERROR(HYPERLINK(VLOOKUP(A8,ÜRÜNLER!A:C,3,FALSE),VLOOKUP(A8,ÜRÜNLER!A:B,2,FALSE)),"") -> iQ300 Üstten Donduruculu Kulpsuz Buzdolabı, 70cm, Inox Görünümlü | N8: =SUM(C8:M8) -> 0 | O8: 5 | Q8: 39960.567 | R8: 38761.75 | S8: 40312.22 | T8: 4171.0322
A9: KD56NXWF1N | B9: =IFERROR(HYPERLINK(VLOOKUP(A9,ÜRÜNLER!A:C,3,FALSE),VLOOKUP(A9,ÜRÜNLER!A:B,2,FALSE)),"") -> iQ300 Üstten Donduruculu Kulpsuz Buzdolabı, 70cm, Beyaz | K9: 1 | N9: =SUM(C9:M9) -> 1 | Q9: devamı yok | R9: 40000 | S9: 41600 | V9: 250
A10: KD76NAIE0N | B10: =IFERROR(HYPERLINK(VLOOKUP(A10,ÜRÜNLER!A:C,3,FALSE),VLOOKUP(A10,ÜRÜNLER!A:B,2,FALSE)),"") -> iQ500 Üstten Donduruculu Kulplu Buzdolabı, 75cm, Inox | I10: 1 | K10: 1 | N10: =SUM(C10:M10) -> 2 | Q10: devamı yok | R10: 64999 | S10: 67598.96 | U10: 18233.94 | V10: 250
A11: KD76NAIE1N | B11: =IFERROR(HYPERLINK(VLOOKUP(A11,ÜRÜNLER!A:C,3,FALSE),VLOOKUP(A11,ÜRÜNLER!A:B,2,FALSE)),"") -> iQ500 Üstten Donduruculu Kulplu Buzdolabı, 75cm, Inox | C11: 4 | N11: =SUM(C11:M11) -> 4 | O11: 6 | Q11: 82878.063 | R11: 80391.722 | S11: 83607.39 | T11: 20757.133
A12: KD76NHID1N | B12: =IFERROR(HYPERLINK(VLOOKUP(A12,ÜRÜNLER!A:C,3,FALSE),VLOOKUP(A12,ÜRÜNLER!A:B,2,FALSE)),"") -> iQ500 Üstten Donduruculu Kulplu Buzdolabı, 75cm, Inox | C12: 2 | N12: =SUM(C12:M12) -> 2 | Q12: devamı yok | R12: 60000 | S12: 62400
A13: KD76NXIE1N | B13: =IFERROR(HYPERLINK(VLOOKUP(A13,ÜRÜNLER!A:C,3,FALSE),VLOOKUP(A13,ÜRÜNLER!A:B,2,FALSE)),"") -> iQ500 Üstten Donduruculu Kulpsuz Buzdolabı, 75cm, Inox | C13: 2 | N13: =SUM(C13:M13) -> 2 | O13: 8 | Q13: 66166.491 | R13: 64181.497 | S13: 66748.757 | T13: 13096.724
A14: KD76NXWE1N | B14: =IFERROR(HYPERLINK(VLOOKUP(A14,ÜRÜNLER!A:C,3,FALSE),VLOOKUP(A14,ÜRÜNLER!A:B,2,FALSE)),"") -> iQ300 Üstten Donduruculu, Kulpsuz Buzdolabı, 75cm, Beyaz | C14: 6 | I14: 1 | J14: 1 | L14: 1 | N14: =SUM(C14:M14) -> 9 | O14: 14 | Q14: 61265.27 | R14: 59427.312 | S14: 61804.404 | T14: 9839.6885
A15: KD76NXWE0N | B15: =IFERROR(HYPERLINK(VLOOKUP(A15,ÜRÜNLER!A:C,3,FALSE),VLOOKUP(A15,ÜRÜNLER!A:B,2,FALSE)),"") -> iQ300 Üstten Donduruculu Kulpsuz Buzdolabı, 75cm, Beyaz | K15: 1 | N15: =SUM(C15:M15) -> 1 | Q15: devamı yok | R15: 50000 | S15: 52000 | T15: 1783.7897 | V15: 250
A16: KD86NAID1N | B16: =IFERROR(HYPERLINK(VLOOKUP(A16,ÜRÜNLER!A:C,3,FALSE),VLOOKUP(A16,ÜRÜNLER!A:B,2,FALSE)),"") -> iQ500 Üstten Donduruculu Kulplu Buzdolabı, 86cm, Inox | C16: 4 | E16: 1 | I16: 1 | J16: 1 | N16: =SUM(C16:M16) -> 7 | O16: 6 | Q16: 95662.202 | R16: 92792.336 | S16: 96504.03 | T16: 23277.319 | W16: PREMIUM 4 LÜ SET
A17: KD86NAIE0N | B17: =IFERROR(HYPERLINK(VLOOKUP(A17,ÜRÜNLER!A:C,3,FALSE),VLOOKUP(A17,ÜRÜNLER!A:B,2,FALSE)),"") -> iQ500 Üstten Donduruculu Kulplu Buzdolabı, 86cm, Inox | N17: =SUM(C17:M17) -> 0 | R17: 0 | U17: 18538.14 | V17: 250 | W17: KD86NAIE0N
A18: KD86NAWE1N | B18: =IFERROR(HYPERLINK(VLOOKUP(A18,ÜRÜNLER!A:C,3,FALSE),VLOOKUP(A18,ÜRÜNLER!A:B,2,FALSE)),"") -> iQ500 Üstten Donduruculu Kulplu Buzdolabı, 86cm, Beyaz | C18: 6 | N18: =SUM(C18:M18) -> 6 | O18: 6 | Q18: 83239.542 | R18: 80742.356 | S18: 83972.05 | T18: 17244.193 | W18: PREMIUM 4 LÜ SET
A19: KD86NHID1N | B19: =IFERROR(HYPERLINK(VLOOKUP(A19,ÜRÜNLER!A:C,3,FALSE),VLOOKUP(A19,ÜRÜNLER!A:B,2,FALSE)),"") -> iQ500 Üstten Donduruculu Kulplu Buzdolabı, 86cm, Inox | K19: 1 | N19: =SUM(C19:M19) -> 1 | Q19: devamı yok | R19: 55000 | S19: 57200 | V19: 250
A20: KG36NNLE0N | B20: =IFERROR(HYPERLINK(VLOOKUP(A20,ÜRÜNLER!A:C,3,FALSE),VLOOKUP(A20,ÜRÜNLER!A:B,2,FALSE)),"") -> iQ100 Alttan Donduruculu Kulpsuz Buzdolabı, 60cm, Inox | K20: 1 | N20: =SUM(C20:M20) -> 1 | Q20: devamı yok | R20: 36999 | S20: 38478.96 | V20: 250
A21: KG55NCIE0N | B21: =IFERROR(HYPERLINK(VLOOKUP(A21,ÜRÜNLER!A:C,3,FALSE),VLOOKUP(A21,ÜRÜNLER!A:B,2,FALSE)),"") -> iQ300 Alttan Donduruculu Kulpsuz Buzdolabı, 70cm, Inox | C21: 65 | E21: 4 | I21: 1 | J21: 1 | K21: 1 | L21: 1 | N21: =SUM(C21:M21) -> 73 | O21: 40 | Q21: 63469.622 | R21: 61565.534 | S21: 64028.155 | T21: 14388.227
A22: KG55NCWE0N | B22: =IFERROR(HYPERLINK(VLOOKUP(A22,ÜRÜNLER!A:C,3,FALSE),VLOOKUP(A22,ÜRÜNLER!A:B,2,FALSE)),"") -> iQ300 Alttan Donduruculu Kulpsuz Buzdolabı, 70cm, Beyaz | C22: 91 | I22: 1 | K22: 2 | N22: =SUM(C22:M22) -> 94 | Q22: 57039.061 | R22: 55327.889 | S22: 57541.005 | T22: 10228.596
A23: KG55NVIE0N | B23: =IFERROR(HYPERLINK(VLOOKUP(A23,ÜRÜNLER!A:C,3,FALSE),VLOOKUP(A23,ÜRÜNLER!A:B,2,FALSE)),"") -> iQ300 Alttan Donduruculu Kulpsuz Buzdolabı, 70cm, Inox | C23: 9 | E23: 1 | K23: 1 | N23: =SUM(C23:M23) -> 11 | Q23: 51274.363 | R23: 49736.132 | S23: 51725.577 | T23: 6515.0603
A24: KG55NVWE0N | B24: =IFERROR(HYPERLINK(VLOOKUP(A24,ÜRÜNLER!A:C,3,FALSE),VLOOKUP(A24,ÜRÜNLER!A:B,2,FALSE)),"") -> iQ300 Alttan Donduruculu Kulpsuz Buzdolabı, 70cm, Beyaz | C24: 8 | E24: 1 | I24: 1 | K24: 1 | N24: =SUM(C24:M24) -> 11 | Q24: 46796.713 | R24: 45392.811 | S24: 47208.524 | T24: 6164.1546
A25: KG56NLBE0N | B25: =IFERROR(HYPERLINK(VLOOKUP(A25,ÜRÜNLER!A:C,3,FALSE),VLOOKUP(A25,ÜRÜNLER!A:B,2,FALSE)),"") -> iQ500 Alttan Donduruculu Kulpsuz Buzdolabı, 70cm, Parlak Siyah | C25: 19 | I25: 2 | J25: 1 | L25: 2 | N25: =SUM(C25:M25) -> 24 | Q25: 58065.822 | R25: 55162.531 | S25: 57369.032
A26: KG56NQWF0N | B26: =IFERROR(HYPERLINK(VLOOKUP(A26,ÜRÜNLER!A:C,3,FALSE),VLOOKUP(A26,ÜRÜNLER!A:B,2,FALSE)),"") -> iQ500 Alttan Donduruculu Kulpsuz Buzdolabı, 70cm, Seramik Desen | J26: 1 | N26: =SUM(C26:M26) -> 1 | Q26: devamı yok | R26: 45000 | S26: 46800 | V26: 250
A27: KG56NTEE0N | B27: =IFERROR(HYPERLINK(VLOOKUP(A27,ÜRÜNLER!A:C,3,FALSE),VLOOKUP(A27,ÜRÜNLER!A:B,2,FALSE)),"") -> iQ500 Alttan Donduruculu Kulpsuz Buzdolabı, 70cm, Mat Siyah | F27: 1 | N27: =SUM(C27:M27) -> 1 | Q27: devamı yok | R27: 45000 | S27: 46800 | V27: 250
A28: KG56NTWE0N | B28: =IFERROR(HYPERLINK(VLOOKUP(A28,ÜRÜNLER!A:C,3,FALSE),VLOOKUP(A28,ÜRÜNLER!A:B,2,FALSE)),"") -> iQ500 Alttan Donduruculu Kulpsuz Buzdolabı, 70cm, Seramik Desen | I28: 1 | K28: 1 | N28: =SUM(C28:M28) -> 2 | Q28: devamı yok | R28: 45000 | S28: 46800 | V28: 250
A29: KG56NXWE0N | B29: =IFERROR(HYPERLINK(VLOOKUP(A29,ÜRÜNLER!A:C,3,FALSE),VLOOKUP(A29,ÜRÜNLER!A:B,2,FALSE)),"") -> iQ300 Alttan Donduruculu Kulpsuz Buzdolabı, 70cm, Beyaz | C29: 1 | N29: =SUM(C29:M29) -> 1 | Q29: devamı yok | R29: 45999 | S29: 47838.96
A30: KG76APIE0N | B30: =IFERROR(HYPERLINK(VLOOKUP(A30,ÜRÜNLER!A:C,3,FALSE),VLOOKUP(A30,ÜRÜNLER!A:B,2,FALSE)),"") -> iQ700 Alttan Donduruculu Kulplu Buzdolabı, 75cm, Inox | C30: 16 | N30: =SUM(C30:M30) -> 16 | Q30: 72088.36 | R30: 67042.175 | S30: 69723.862 | T30: 273.24406
A31: KG76NCIE0N | B31: =IFERROR(HYPERLINK(VLOOKUP(A31,ÜRÜNLER!A:C,3,FALSE),VLOOKUP(A31,ÜRÜNLER!A:B,2,FALSE)),"") -> iQ500 Alttan Donduruculu Kulplu Buzdolabı, 75cm, Inox | C31: 16 | I31: 1 | J31: 1 | K31: 3 | L31: 1 | N31: =SUM(C31:M31) -> 22 | O31: 70 | Q31: 84280.726 | R31: 81752.304 | S31: 85022.396 | T31: 21679.563
A32: KG76NCWE0N | B32: =IFERROR(HYPERLINK(VLOOKUP(A32,ÜRÜNLER!A:C,3,FALSE),VLOOKUP(A32,ÜRÜNLER!A:B,2,FALSE)),"") -> iQ500 Alttan Donduruculu Kulplu Buzdolabı, 75cm, Beyaz | C32: 9 | I32: 1 | K32: 1 | N32: =SUM(C32:M32) -> 11 | O32: 53 | Q32: 77045.044 | R32: 74733.692 | S32: 77723.04 | T32: 17219.462
A33: KG76NCXE0N | B33: =IFERROR(HYPERLINK(VLOOKUP(A33,ÜRÜNLER!A:C,3,FALSE),VLOOKUP(A33,ÜRÜNLER!A:B,2,FALSE)),"") -> iQ500 Alttan Donduruculu Kulpsuz Buzdolabı, 75cm, darkSteel | I33: 1 | J33: 1 | L33: 1 | N33: =SUM(C33:M33) -> 3 | O33: 80 | Q33: 95152.057 | R33: 92297.496 | S33: 95989.395 | T33: 29995.081 | W33: PREMIUM 4 LÜ SET
A34: KG76NVIE0N | B34: =IFERROR(HYPERLINK(VLOOKUP(A34,ÜRÜNLER!A:C,3,FALSE),VLOOKUP(A34,ÜRÜNLER!A:B,2,FALSE)),"") -> iQ300 Alttan Donduruculu Kulpsuz Buzdolabı, 75cm, Inox | C34: 28 | F34: 1 | I34: 1 | K34: 2 | N34: =SUM(C34:M34) -> 32 | O34: 30 | Q34: 76173.043 | R34: 73887.852 | S34: 76843.366 | T34: 19676.532
A35: KG76NVWE0N | B35: =IFERROR(HYPERLINK(VLOOKUP(A35,ÜRÜNLER!A:C,3,FALSE),VLOOKUP(A35,ÜRÜNLER!A:B,2,FALSE)),"") -> iQ300 Alttan Donduruculu Kulpsuz Buzdolabı, 75cm, Beyaz | C35: 24 | I35: 1 | J35: 1 | L35: 1 | N35: =SUM(C35:M35) -> 27 | O35: 30 | Q35: 68727.331 | R35: 66665.511 | S35: 69332.132 | T35: 13712.215
A36: KG76PAIC0N | B36: =IFERROR(HYPERLINK(VLOOKUP(A36,ÜRÜNLER!A:C,3,FALSE),VLOOKUP(A36,ÜRÜNLER!A:B,2,FALSE)),"") -> iQ700 Alttan Donduruculu Kulplu Buzdolabı, 75cm, Inox | C36: 39 | E36: 2 | F36: 1 | I36: 1 | J36: 1 | L36: 1 | N36: =SUM(C36:M36) -> 45 | O36: 30 | Q36: 89108.337 | R36: 86435.087 | S36: 89892.491 | T36: 17382.756
A37: KG76PAWC0N | B37: =IFERROR(HYPERLINK(VLOOKUP(A37,ÜRÜNLER!A:C,3,FALSE),VLOOKUP(A37,ÜRÜNLER!A:B,2,FALSE)),"") -> iQ700 Alttan Donduruculu Kulplu Buzdolabı, 75cm, Beyaz | C37: 18 | E37: 1 | I37: 1 | K37: 3 | N37: =SUM(C37:M37) -> 23 | O37: 12 | Q37: 82556.235 | R37: 80079.548 | S37: 83282.73 | T37: 17041.118
A38: KG86NAID2N | B38: =IFERROR(HYPERLINK(VLOOKUP(A38,ÜRÜNLER!A:C,3,FALSE),VLOOKUP(A38,ÜRÜNLER!A:B,2,FALSE)),"") -> iQ500 Alttan Donduruculu Kulplu Buzdolabı, 86cm, Inox | C38: 66 | E38: 1 | F38: 1 | I38: 1 | J38: 1 | K38: 1 | L38: 1 | M38: 1 | N38: =SUM(C38:M38) -> 73 | O38: 154 | Q38: 97945.234 | R38: 95006.877 | S38: 98807.152 | T38: 27326.629
A39: KG86NCWE0N | B39: =IFERROR(HYPERLINK(VLOOKUP(A39,ÜRÜNLER!A:C,3,FALSE),VLOOKUP(A39,ÜRÜNLER!A:B,2,FALSE)),"") -> iQ500 Alttan Donduruculu Kulplu Buzdolabı, 86cm, Beyaz | C39: 11 | F39: 1 | I39: 1 | N39: =SUM(C39:M39) -> 13 | O39: 24 | Q39: 84927.533 | R39: 82379.707 | S39: 85674.895 | T39: 19908.928
A40: KG86NVWE0N | B40: =IFERROR(HYPERLINK(VLOOKUP(A40,ÜRÜNLER!A:C,3,FALSE),VLOOKUP(A40,ÜRÜNLER!A:B,2,FALSE)),"") -> iQ500 Alttan Donduruculu Kulpsuz Buzdolabı, 86cm, Beyaz | C40: 13 | F40: 1 | J40: 1 | N40: =SUM(C40:M40) -> 15 | O40: 12 | Q40: 75297.093 | R40: 73038.18 | S40: 75959.707 | T40: 13599.418
...

Sheet HESAPLAYICI
A1: =Sayfa1!A1 -> STOK KODU | B1: =Sayfa1!B1 -> AÇIKLAMA | C1: =Sayfa1!C1 -> 30 Mart HOROZ | D1: =Sayfa1!Q1 -> MART TOPTAN | E1: =Sayfa1!R1 -> HAVALE FİYATI | F1: =Sayfa1!S1 -> TEK ÇEKİM FİYATI | G1: =Sayfa1!T1 -> MART BİP | H1: =Sayfa1!U1 -> Phase out ürünler 30.04.2026 montaj ZORUNLU | I1: Toplam Bundle İndirim Tutarını Aşağıya Yaz | J1: =Sayfa1!V1 -> Hakedişler LİSTE FİYATINDAN SATILIRSA geçerli olacak | K1: =Sayfa1!W1 -> PREMİUM 4 LÜ ÜRÜN ALIMINDA 27.000 TL İNDİRİM | L1: =Sayfa1!X1 -> ONLINE FİYAT
A2: BF922L1B1 | B2: =IFERROR(VLOOKUP(A2,Sayfa1!A:B,2,FALSE),"?") -> iQ700 studioLine Ankastre Mikrodalga, 21L, Siyah | C2: =IFERROR(VLOOKUP(A2,Sayfa1!A:C,3,FALSE),"?") -> 0 | D2: =IFERROR(VLOOKUP(A2,Sayfa1!A:Q,17,FALSE),"?") -> 48975.731 | E2: =IFERROR(VLOOKUP(A2,Sayfa1!A:R,18,FALSE),"?") -> 45547.43 | F2: =IFERROR(VLOOKUP(A2,Sayfa1!A:S,19,FALSE),"?") -> 47369.327 | G2: =IFERROR(VLOOKUP(A2,Sayfa1!A:T,20,FALSE),"?") -> 0 | H2: =IFERROR(VLOOKUP(A2,Sayfa1!A:U,21,FALSE),"?") -> 0 | I2: 0 | J2: =IFERROR(VLOOKUP(A2,Sayfa1!A:V,22,FALSE),"?") -> 500 | K2: =IFERROR(VLOOKUP(A2,Sayfa1!A:W,23,FALSE),"?") -> 0 | L2: =IFERROR(VLOOKUP(A2,Sayfa1!A:X,24,FALSE),"?") -> 0
A3: HN978GQB1 | B3: =IFERROR(VLOOKUP(A3,Sayfa1!A:B,2,FALSE),"?") -> iQ700 studioLine Buhar ve Mikrodalga Fonksiyonlu Ankastre Fırın, Komple Kendini Temizler, Siyah | C3: =IFERROR(VLOOKUP(A3,Sayfa1!A:C,3,FALSE),"?") -> 0 | D3: =IFERROR(VLOOKUP(A3,Sayfa1!A:Q,17,FALSE),"?") -> 214828.55 | E3: =IFERROR(VLOOKUP(A3,Sayfa1!A:R,18,FALSE),"?") -> 199790.55 | F3: =IFERROR(VLOOKUP(A3,Sayfa1!A:S,19,FALSE),"?") -> 207782.18 | G3: =IFERROR(VLOOKUP(A3,Sayfa1!A:S,19,FALSE),"?") -> 207782.18 | H3: =IFERROR(VLOOKUP(A3,Sayfa1!A:U,21,FALSE),"?") -> 0 | J3: =IFERROR(VLOOKUP(A3,Sayfa1!A:V,22,FALSE),"?") -> 500 | K3: =IFERROR(VLOOKUP(A3,Sayfa1!A:W,23,FALSE),"?") -> 0 | L3: =IFERROR(VLOOKUP(A3,Sayfa1!A:X,24,FALSE),"?") -> 0
A4: LC91KLT65 | B4: =IFERROR(VLOOKUP(A4,Sayfa1!A:B,2,FALSE),"?") -> iQ700 studioLine Eğimli Davlumbaz, 90cm, 441m3, Siyah Cam | C4: =IFERROR(VLOOKUP(A4,Sayfa1!A:C,3,FALSE),"?") -> 0 | D4: =IFERROR(VLOOKUP(A4,Sayfa1!A:Q,17,FALSE),"?") -> 79664.143 | E4: =IFERROR(VLOOKUP(A4,Sayfa1!A:R,18,FALSE),"?") -> 74087.653 | F4: =IFERROR(VLOOKUP(A4,Sayfa1!A:S,19,FALSE),"?") -> 77051.16 | G4: =IFERROR(VLOOKUP(A4,Sayfa1!A:S,19,FALSE),"?") -> 77051.16 | H4: =IFERROR(VLOOKUP(A4,Sayfa1!A:U,21,FALSE),"?") -> 0 | J4: =IFERROR(VLOOKUP(A4,Sayfa1!A:V,22,FALSE),"?") -> 500 | K4: =IFERROR(VLOOKUP(A4,Sayfa1!A:W,23,FALSE),"?") -> 0 | L4: =IFERROR(VLOOKUP(A4,Sayfa1!A:X,24,FALSE),"?") -> 0
A5: EZ877KZY1E | B5: =IFERROR(VLOOKUP(A5,Sayfa1!A:B,2,FALSE),"?") -> iQ700 studioLine İndüksiyonlu Ocak, 80cm, Çerçeveli, Siyah | C5: =IFERROR(VLOOKUP(A5,Sayfa1!A:C,3,FALSE),"?") -> 0 | D5: =IFERROR(VLOOKUP(A5,Sayfa1!A:Q,17,FALSE),"?") -> 174205 | E5: =IFERROR(VLOOKUP(A5,Sayfa1!A:R,18,FALSE),"?") -> 162010.65 | F5: =IFERROR(VLOOKUP(A5,Sayfa1!A:S,19,FALSE),"?") -> 168491.08 | G5: =IFERROR(VLOOKUP(A5,Sayfa1!A:S,19,FALSE),"?") -> 168491.08 | H5: =IFERROR(VLOOKUP(A5,Sayfa1!A:U,21,FALSE),"?") -> 0 | J5: =IFERROR(VLOOKUP(A5,Sayfa1!A:V,22,FALSE),"?") -> 500 | K5: =IFERROR(VLOOKUP(A5,Sayfa1!A:W,23,FALSE),"?") -> 0 | L5: =IFERROR(VLOOKUP(A5,Sayfa1!A:X,24,FALSE),"?") -> 0
A6: CI24WP03 | B6: =IFERROR(VLOOKUP(A6,Sayfa1!A:B,2,FALSE),"?") -> iQ700 studioLine Ankastre Şarap Soğutucu, 212.5x60.3cm | C6: =IFERROR(VLOOKUP(A6,Sayfa1!A:C,3,FALSE),"?") -> 0 | D6: =IFERROR(VLOOKUP(A6,Sayfa1!A:Q,17,FALSE),"?") -> 311386.85 | E6: =IFERROR(VLOOKUP(A6,Sayfa1!A:R,18,FALSE),"?") -> 289589.77 | F6: =IFERROR(VLOOKUP(A6,Sayfa1!A:S,19,FALSE),"?") -> 301173.36 | G6: =IFERROR(VLOOKUP(A6,Sayfa1!A:S,19,FALSE),"?") -> 301173.36 | H6: =IFERROR(VLOOKUP(A6,Sayfa1!A:U,21,FALSE),"?") -> 0 | J6: =IFERROR(VLOOKUP(A6,Sayfa1!A:V,22,FALSE),"?") -> 500 | K6: =IFERROR(VLOOKUP(A6,Sayfa1!A:W,23,FALSE),"?") -> 0 | L6: =IFERROR(VLOOKUP(A6,Sayfa1!A:X,24,FALSE),"?") -> 0
A7: BI910C1B1 | B7: =IFERROR(VLOOKUP(A7,Sayfa1!A:B,2,FALSE),"?") -> ? | C7: =IFERROR(VLOOKUP(A7,Sayfa1!A:C,3,FALSE),"?") -> ? | D7: =IFERROR(VLOOKUP(A7,Sayfa1!A:Q,17,FALSE),"?") -> ? | E7: =IFERROR(VLOOKUP(A7,Sayfa1!A:R,18,FALSE),"?") -> ? | F7: =IFERROR(VLOOKUP(A7,Sayfa1!A:S,19,FALSE),"?") -> ? | G7: =IFERROR(VLOOKUP(A7,Sayfa1!A:S,19,FALSE),"?") -> ? | H7: =IFERROR(VLOOKUP(A7,Sayfa1!A:U,21,FALSE),"?") -> ? | J7: =IFERROR(VLOOKUP(A7,Sayfa1!A:V,22,FALSE),"?") -> ? | K7: =IFERROR(VLOOKUP(A7,Sayfa1!A:W,23,FALSE),"?") -> ? | L7: =IFERROR(VLOOKUP(A7,Sayfa1!A:X,24,FALSE),"?") -> ?
B8: =IFERROR(VLOOKUP(A8,Sayfa1!A:B,2,FALSE),"?") -> ? | C8: =IFERROR(VLOOKUP(A8,Sayfa1!A:C,3,FALSE),"?") -> ? | D8: =IFERROR(VLOOKUP(A8,Sayfa1!A:Q,17,FALSE),"?") -> ? | E8: =IFERROR(VLOOKUP(A8,Sayfa1!A:R,18,FALSE),"?") -> ? | F8: =IFERROR(VLOOKUP(A8,Sayfa1!A:S,19,FALSE),"?") -> ? | G8: =IFERROR(VLOOKUP(A8,Sayfa1!A:S,19,FALSE),"?") -> ? | H8: =IFERROR(VLOOKUP(A8,Sayfa1!A:U,21,FALSE),"?") -> ? | J8: =IFERROR(VLOOKUP(A8,Sayfa1!A:V,22,FALSE),"?") -> ? | K8: =IFERROR(VLOOKUP(A8,Sayfa1!A:W,23,FALSE),"?") -> ? | L8: =IFERROR(VLOOKUP(A8,Sayfa1!A:X,24,FALSE),"?") -> ?
B9: =IFERROR(VLOOKUP(A9,Sayfa1!A:B,2,FALSE),"?") -> ? | C9: =IFERROR(VLOOKUP(A9,Sayfa1!A:C,3,FALSE),"?") -> ? | D9: =IFERROR(VLOOKUP(A9,Sayfa1!A:Q,17,FALSE),"?") -> ? | E9: =IFERROR(VLOOKUP(A9,Sayfa1!A:R,18,FALSE),"?") -> ? | F9: =IFERROR(VLOOKUP(A9,Sayfa1!A:S,19,FALSE),"?") -> ? | G9: =IFERROR(VLOOKUP(A9,Sayfa1!A:S,19,FALSE),"?") -> ? | H9: =IFERROR(VLOOKUP(A9,Sayfa1!A:U,21,FALSE),"?") -> ? | J9: =IFERROR(VLOOKUP(A9,Sayfa1!A:V,22,FALSE),"?") -> ? | K9: =IFERROR(VLOOKUP(A9,Sayfa1!A:W,23,FALSE),"?") -> ? | L9: =IFERROR(VLOOKUP(A9,Sayfa1!A:X,24,FALSE),"?") -> ?
B10: =IFERROR(VLOOKUP(A10,Sayfa1!A:B,2,FALSE),"?") -> ? | C10: =IFERROR(VLOOKUP(A10,Sayfa1!A:C,3,FALSE),"?") -> ? | D10: =IFERROR(VLOOKUP(A10,Sayfa1!A:Q,17,FALSE),"?") -> ? | E10: =IFERROR(VLOOKUP(A10,Sayfa1!A:R,18,FALSE),"?") -> ? | F10: =IFERROR(VLOOKUP(A10,Sayfa1!A:S,19,FALSE),"?") -> ? | G10: =IFERROR(VLOOKUP(A10,Sayfa1!A:S,19,FALSE),"?") -> ? | H10: =IFERROR(VLOOKUP(A10,Sayfa1!A:U,21,FALSE),"?") -> ? | J10: =IFERROR(VLOOKUP(A10,Sayfa1!A:V,22,FALSE),"?") -> ? | K10: =IFERROR(VLOOKUP(A10,Sayfa1!A:W,23,FALSE),"?") -> ? | L10: =IFERROR(VLOOKUP(A10,Sayfa1!A:X,24,FALSE),"?") -> ?
B11: =IFERROR(VLOOKUP(A11,Sayfa1!A:B,2,FALSE),"?") -> ? | C11: =IFERROR(VLOOKUP(A11,Sayfa1!A:C,3,FALSE),"?") -> ? | D11: =IFERROR(VLOOKUP(A11,Sayfa1!A:Q,17,FALSE),"?") -> ? | E11: =IFERROR(VLOOKUP(A11,Sayfa1!A:R,18,FALSE),"?") -> ? | F11: =IFERROR(VLOOKUP(A11,Sayfa1!A:S,19,FALSE),"?") -> ? | G11: =IFERROR(VLOOKUP(A11,Sayfa1!A:S,19,FALSE),"?") -> ? | H11: =IFERROR(VLOOKUP(A11,Sayfa1!A:U,21,FALSE),"?") -> ? | J11: =IFERROR(VLOOKUP(A11,Sayfa1!A:V,22,FALSE),"?") -> ? | K11: =IFERROR(VLOOKUP(A11,Sayfa1!A:W,23,FALSE),"?") -> ? | L11: =IFERROR(VLOOKUP(A11,Sayfa1!A:X,24,FALSE),"?") -> ?
A12: Toplam Satış Fiyatı | E12: =SUM(E2:E11) -> 771026.06 | F12: =SUM(F2:F11) -> 801867.1
A13: BİP İndirimi | E13: =SUM(G:G)*-1 -> -754497.78 | F13: =SUM(G:G)*-1 -> -754497.78
A14: PhaseOut İndirimi | E14: =SUM(H:H)*-1 -> 0 | F14: =SUM(H:H)*-1 -> 0
A15: Toplam Bundle İndirimi | E15: =I2*-1 -> 0 | F15: =I2*-1 -> 0
A16: Satılabilir Minimum Fiyat | E16: =SUM(E12:E15) -> 16528.284 | F16: =SUM(F12:F15) -> 47369.327
A17: Satılabilir Minimum Taksitli Fiyat | E17: =E16*1.08 -> 17850.547

Sheet Bundle Kampanya
C1: YENİ
C2: 2’li LDA alımında perakende de 5.000 ₺ indirim fırsatı! | D2: 2’li LDA alımında (Buzdolabı - Çamaşır - Bulaşık - Derin Dondurucu) perakende de 5.000 ₺ indirim uygulanır. “diğer kampanyalar ile birleşemez” 4.000 ₺ kdv dahil fiyat farkı hak edişi ödenecektir.
K9: Seçili Ankastre fırın ile set alana perakende de 6.000 ₺ indirim! | L9: Geçerli Ankastre Fırınlar
C11: 2’li LDA alımında Kurutma Makinelerinde perakende de 10.000 ₺ indirim fırsatı! | D11: 2’li LDA alımında (Buzdolabı - Çamaşır - Bulaşık - Derin Dondurucu) + KURUTMA perakende de 10.000 ₺ indirim uygulanır. “diğer kampanyalar ile birleşemez” 8.000 ₺ kdv dahil fiyat farkı hak edişi ödenecektir. | L11: (HB214FBS1T, HB012FBB1T, HB214FBW1T, HB012FBW1T, HB514FBH0T, HB514FBH2T, HB012FBH1T, HB514FBR1T, HB514FBR1T) Ankastre fırınlarda geçerlidir.
L15: Uygulama koşulları : Seçili ankastre fırınlar ile set (fırın+ocak+dav.) set alana perakende de 6.000 ₺ indirim uygulanır. Diğer fırınlarda geçerli değildir. KDV dahil 4.500 ₺ hak ediş ödenir.
C21: 4'lü çeyiz seti alana perakende de 15.000 ₺ İndirim! | D21: 4'lü çeyiz seti alana perakende de 15.000 ₺ indirim! (Buzdolabı-Derin Dondurucu-Çamaşır-Kurutma-Bulaşık)
K27: Seçili Ankastre set alana perakende de 8.000 ₺ indirim! | L27: Geçerli Ankastre Setler
D29: Uygulama koşulları : Seçili ürün gruplarından 4'lü LDA alan tüketicilere perakende de 15.000 ₺ indirim! KDV dahil 12.200 ₺ hakediş ödenir. (Buzdolab-Derin Dondurucu-Çamaşır-Kurutma-Bulaşık) | L29: Giriş setler hariçtir.
L33: Uygulama koşulları : Seçili ankastre set (fırın+ocak+dav.) alımlarında perakende de 8.000 ₺ net indirim uygulanır. Giriş setlerde geçerli değildir. KDV dahil 6.200 ₺ hak ediş ödenir.
C36: Seçili Premium Ürünlerden 3'lü LDA Alımına Ek Kurutma alana WQ42J200TR Kurutma Makinesi perakende de 9.999 ₺! | D36: Kampanya Kapsamındaki Ürünler
D38: Buzdolabı (KD86NAWE1N, KD86NAID1N, KD86NAIE0N, KG86PAXB0N, KG76NCXE0N, KG86PFIC0N, KG86PFWC0N, KF96NAXEA, KF96RSBEA, KF96NVPEA) Bulaşık Makinesi (SN15EC00NT, SN15EI00KT, SN15EW00KT, SN23IC62MT, SN25EI63KT, SN25EI70MT, SN27YI82DT, SN25EI82AT, SN25EI83CT, SN57ZS82DT, SN55ES82KT, SN75EX11CE, SN63HX62MT, SX95EX12CE) Çamaşır Makinesi (WG42K2Z0TR, WG42K2ZXTR, WG52K2Z0TR, WG52K2ZXTR, WG54A2Z0TR, WG54B2ASTR, WG54B2A1TR, WG44B2A0TR, WG44A2ZRTR, WG64K2F0TR, WG64K2Z0TR, WG64K2ZRTR) Kurutma Makinesi (WQ42J200TR, WQ43J2C0TR, WQ42G20RTR, WQ44G2C1TR, WQ52K200TR, WQ45B2A0TR, WQ45B2AXTR, WQ52J20RTR)
K40: "HB557" Ankastre fırın segmenti ve üzeri Set alımlarına “SN616X00DT” kodlu tam ankastre bulaşık makinesi perakende de %50 indirimli! | L40: Geçerli Ankastre Fırınlar
L42: "HB557" Ankastre fırın segmenti ve daha üst segment fırınlar dahildir.
D44: Uygulama koşulları : Seçili premium ürünlerden 3'lü alımına ek kurutma alan tüketicilere WQ42J200TR Kurutma Makinesi perakende de 9.999 ₺! Diğer seçili kurutmalarda perakende de 35.271 ₺ indirim uygulanmalıdır. KDV dahil 27.000 ₺ hak ediş ödenir. (Buzdolabı+Çamaşır+Bulaşık+Kurutma)
L46: Uygulama koşulları : Seçili ankastre set (fırın+ocak+dav.) alımlarında “SN616X00DT” kodlu tam ankastre bulaşık makinesine perakende de %50 indirim uygulanır. Diğer ankastre bulaşık makinlerinde perakende de 18.315 ₺ indirim uygulanır. Giriş setlerde geçerli değildir. KDV dahil 12.000 ₺ hak ediş ödenir.
C51: XL veya XXL Buzdolabı Alana perakende de VSC3A210 Toz Torbalı Süpürge Hediye! veya VSM120B IQ500 Şarjlı Süpürge perakende de 7.450 TL “Diğer kampanyalar ile birleşemez” | D51: XL veya XXL Buzdolabı alana VSC3A210 Toz Torbalı Süpürge perakende de Hediye verilir veya VSM120B IQ500 Şarjlı Süpürge perakende de 7.450 ₺! "Diğer Süpürgelerde perakende de 9.750 ₺ indirim uygulanır" 7.500 ₺ kdv dahil fiyat farkı hak edişi ödenecektir. “Diğer kampanyalar ile birleşemez” (Süpürge almak istemeyen tüketiciler için Buzdolaplarında indirim yapılabilir.)
K57: YENİ
K58: "HB557" Ankastre fırın segmenti ve üzeri Set alımlarına “BF623LMS3” kodlu ankastre mikrodalga perakende de 1.990₺! | L58: Geçerli Ankastre Fırınlar
L60: "HB557" Ankastre fırın segmenti ve daha üst segment fırınlar dahildir.
L64: Uygulama koşulları : Seçili ankastre set (fırın+ocak+dav.) alımlarında “BF623LMS3” kodlu ankastre mikrodalga perakende de 1.990₺. Diğer ankastre mikrodalgalarda da perakende de 14.790 ₺ indirim uygulanır. Giriş setlerde geçerli değildir. KDV dahil 12.000 ₺ hak ediş ödenir.

Sheet ÜRÜNLER
A1: Ürün No | B1: Ürün Adı | C1: Ürün Linki
A2: AS09IVW32N | B2: Siemens Ev Tipi Klima İç Ünite, 9.000BTU, Beyaz | C2: https://www.siemens-home.bsh-group.com/tr/tr/product/klimalar/AS09XVW32N
A3: AS09OVW32N | B3: Siemens Ev Tipi Klima Dış Ünite, 9.000BTU, Beyaz | C3: https://www.siemens-home.bsh-group.com/tr/tr/product/klimalar/AS09XVW32N
A4: AS12IVW30N | B4: Siemens Ev Tipi Klima İç Ünite, 12.000BTU, Beyaz | C4: https://www.siemens-home.bsh-group.com/tr/tr/product/klimalar/AS12XVW32N
A5: AS12IVW32N | B5: Siemens Ev Tipi Klima İç Ünite, 12.000BTU, Beyaz | C5: https://www.siemens-home.bsh-group.com/tr/tr/product/klimalar/AS12XVW32N
A6: AS12IXB32N | B6: Siemens Ev Tipi Klima İç Ünite, 12.000BTU, Siyah | C6: https://www.siemens-home.bsh-group.com/tr/tr/product/klimalar/AS12XXB32N
A7: AS12OVW30N | B7: Siemens Ev Tipi Klima Dış Ünite, 12.000BTU, Beyaz | C7: https://www.siemens-home.bsh-group.com/tr/tr/product/klimalar/AS12XVW32N
A8: AS12OVW32N | B8: Siemens Ev Tipi Klima Dış Ünite, 12.000BTU, Beyaz | C8: https://www.siemens-home.bsh-group.com/tr/tr/product/klimalar/AS12XVW32N
A9: AS12OXB32N | B9: Siemens Ev Tipi Klima Dış Ünite, 12.000BTU, Beyaz | C9: https://www.siemens-home.bsh-group.com/tr/tr/product/klimalar/AS12XXB32N
A10: AS18IVW30N | B10: Siemens Ev Tipi Klima İç Ünite, 18.000BTU, Beyaz | C10: https://www.siemens-home.bsh-group.com/tr/tr/product/klimalar/AS18XVW32N
A11: AS18IXB32N | B11: Siemens Ev Tipi Klima İç Ünite, 18.000BTU, Siyah | C11: https://www.siemens-home.bsh-group.com/tr/tr/product/klimalar/AS18XXB32N
A12: AS18OVW30N | B12: Siemens Ev Tipi Klima Dış Ünite, 18.000BTU, Beyaz | C12: https://www.siemens-home.bsh-group.com/tr/tr/product/klimalar/AS18XVW32N
... A469: WG52A202TR | B469: iQ300 Çamaşır Makinesi, 10kg/1200devir, Beyaz | C469: https://www.siemens-home.bsh-group.com/tr/tr/product/yikama-ve-utuleme-grubu/camasir-makineleri/solo-camasir-makineleri/WG52A202TR
A470: WG52A203TR | B470: iQ300 Çamaşır Makinesi, 10kg/1200devir, Beyaz
A471: WG52A2A0TR | B471: iQ500 Çamaşır Makinesi, 10kg/1200devir, i-dos, Beyaz | C471: https://www.siemens-home.bsh-group.com/tr/tr/product/prsiemenswm/WG52A2A0TR
A472: WG52A2F0TR | B472: iQ500 Çamaşır Makinesi, 10kg/1200devir, i-dos, Beyaz | C472: https://www.siemens-home.bsh-group.com/tr/tr/product/yikama-ve-utuleme-grubu/camasir-makineleri/solo-camasir-makineleri/WG52A2F0TR
A473: WG52A2XVTR | B473: iQ300 Çamaşır Makinesi, 10kg/1200devir, Gümüş | C473: https://www.siemens-home.bsh-group.com/tr/tr/product/evlilik-kampanyasi-camasir-makineleri/WG52A2XVTR
A474: WG52A2Z0TR | B474: iQ500 Çamaşır Makinesi, 10kg/1200devir, Beyaz | C474: https://www.siemens-home.bsh-group.com/tr/tr/product/yikama-ve-utuleme-grubu/camasir-makineleri/iq300-camasir-makineleri/WG52A2Z0TR
A475: WG52A2ZXTR | B475: iQ300 Çamaşır Makinesi, 10kg/1200devir, Gümüş | C475: https://www.siemens-home.bsh-group.com/tr/tr/product/yikama-ve-utuleme-grubu/camasir-makineleri/solo-camasir-makineleri/WG52A2ZXTR
A476: WG52K2Z0TR | B476: iQ500 Çamaşır Makinesi, 10kg/1200devir, Beyaz | C476: https://www.siemens-home.bsh-group.com/tr/tr/product/yikama-ve-utuleme-grubu/camasir-makineleri/solo-camasir-makineleri/WG52K2Z0TR
A477: WG52K2Z1TR | B477: iQ500 Çamaşır Makinesi, 10kg/1200devir, Beyaz
A478: WG52K2ZXTR | B478: iQ500 Çamaşır Makinesi, 10kg/1200devir, Gümüş | C478: https://www.siemens-home.bsh-group.com/tr/tr/product/yikama-ve-utuleme-grubu/camasir-makineleri/solo-camasir-makineleri/WG52K2ZXTR
A479: WG54A200TR | B479: iQ300 Çamaşır Makinesi, 10kg/1400devir, Beyaz | C479: https://www.siemens-home.bsh-group.com/tr/tr/product/prsiemenswm/WG54A200TR
A480: WG54A2Z0TR | B480: iQ300 Çamaşır Makinesi, 10kg/1400devir, Beyaz | C480: https://www.siemens-home.bsh-group.com/tr/tr/product/yikama-ve-utuleme-grubu/camasir-makineleri/solo-camasir-makineleri/WG54A2Z0TR
A481: WG54B2A0TR | B481: iQ700 Çamaşır Makinesi, 10kg/1400devir, i-dos, Beyaz | C481: https://www.siemens-home.bsh-group.com/tr/tr/product/yikama-ve-utuleme-grubu/camasir-makineleri/iq700-camasir-makineleri/WG54B2A0TR
A482: WG54B2A1TR | B482: iQ700 Çamaşır Makinesi, 10kg/1400devir, i-dos, Beyaz | C482: https://www.siemens-home.bsh-group.com/tr/tr/product/yikama-ve-utuleme-grubu/camasir-makineleri/solo-camasir-makineleri/WG54B2A1TR
A483: WG54B2ASTR | B483: iQ700 Çamaşır Makinesi, 10kg/1400devir, i-dos, Gümüş | C483: https://www.siemens-home.bsh-group.com/tr/tr/product/yikama-ve-utuleme-grubu/camasir-makineleri/solo-camasir-makineleri/WG54B2ASTR
A484: WG54B2AXTR | B484: iQ700 Çamaşır Makinesi, 10kg/1400devir, i-dos, Gümüş | C484: https://www.siemens-home.bsh-group.com/tr/tr/product/yikama-ve-utuleme-grubu/camasir-makineleri/iq700-camasir-makineleri/WG54B2AXTR
A485: WG54K2Y0TR | B485: iQ500 Çamaşır Makinesi, 10kg/1400devir, i-dos, Beyaz | C485: https://www.siemens-home.bsh-group.com/tr/tr/product/yikama-ve-utuleme-grubu/camasir-makineleri/solo-camasir-makineleri/WG54K2Y0TR
A486: WG64K2Y0TR | B486: iQ500 Çamaşır Makinesi, 11kg/1400devir, i-dos, Beyaz | C486: https://www.siemens-home.bsh-group.com/tr/tr/product/yikama-ve-utuleme-grubu/camasir-makineleri/solo-camasir-makineleri/WG64K2Y0TR
A487: WG64K2F0TR | B487: iQ500 Çamaşır Makinesi, 11kg/1400devir, i-dos, Beyaz | C487: https://www.siemens-home.bsh-group.com/tr/tr/product/yikama-ve-utuleme-grubu/camasir-makineleri/solo-camasir-makineleri/WG64K2F0TR
A488: WG64K2Z0TR | B488: iQ500 Çamaşır Makinesi, 11kg/1400devir, Beyaz | C488: https://www.siemens-home.bsh-group.com/tr/tr/product/yikama-ve-utuleme-grubu/camasir-makineleri/solo-camasir-makineleri/WG64K2Z0TR
A489: WG64K2ZRTR | B489: iQ500 Çamaşır Makinesi, 11kg/1400devir, Antrasit/Dark | C489: https://www.siemens-home.bsh-group.com/tr/tr/product/yikama-ve-utuleme-grubu/camasir-makineleri/solo-camasir-makineleri/WG64K2ZRTR
... A517: SZ36RB04 | B517: Siemens Bulaşık Makinesi 3. Tepsi | C517: https://www.siemens-home.bsh-group.com/tr/tr/productservice/SZ36RB04(00)
